{
  "version": 8,
  "blockIdVersion": 11,
  "anchorX": 0,
  "anchorY": 0,
  "anchorZ": 0,
  "blocks": [
    {
      "x": -8,
      "y": 0,
      "z": -8,
      "name": "Wood_Deadwood_Planks"
    },
    {
      "x": -8,
      "y": 0,
      "z": -7,
      "name": "Wood_Deadwood_Planks"
    },
    {
      "x": -8,
      "y": 0,
      "z": -6,
      "name": "Wood_Deadwood_Planks"
    },
    {
      "x": -8,
      "y": 1,
      "z": -6,
      "name": "Wood_Deadwood_Planks"
    },
    {
      "x": -8,
      "y": 2,
      "z": -6,
      "name": "Wood_Deadwood_Planks"
    },
    {
      "x": -8,
      "y": 3,
      "z": -6,
      "name": "Wood_Deadwood_Planks"
    },
    {
      "x": -8,
      "y": 4,
      "z": -6,
      "name": "Wood_Deadwood_Planks"
    },
    {
      "x": -8,
      "y": 0,
      "z": -5,
      "name": "Wood_Deadwood_Planks"
    },
    {
      "x": -8,
      "y": 1,
      "z": -5,
      "name": "Wood_Deadwood_Planks"
    },
    {
      "x": -8,
      "y": 2,
      "z": -5,
      "name": "Wood_Deadwood_Planks"
    },
    {
      "x": -8,
      "y": 3,
      "z": -5,
      "name": "Wood_Deadwood_Planks"
    },
    {
      "x": -8,
      "y": 4,
      "z": -5,
      "name": "Wood_Deadwood_Planks"
    },
    {
      "x": -8,
      "y": 5,
      "z": -5,
      "name": "Wood_Deadwood_Planks"
    },
    {
      "x": -8,
      "y": 0,
      "z": -4,
      "name": "Wood_Deadwood_Planks"
    },
    {
      "x": -8,
      "y": 1,
      "z": -4,
      "name": "Wood_Deadwood_Planks"
    },
    {
      "x": -8,
      "y": 2,
      "z": -4,
      "name": "Wood_Deadwood_Planks"
    },
    {
      "x": -8,
      "y": 3,
      "z": -4,
      "name": "Wood_Deadwood_Planks"
    },
    {
      "x": -8,
      "y": 4,
      "z": -4,
      "name": "Wood_Deadwood_Planks"
    },
    {
      "x": -8,
      "y": 5,
      "z": -4,
      "name": "Wood_Deadwood_Planks"
    },
    {
      "x": -8,
      "y": 6,
      "z": -4,
      "name": "Wood_Deadwood_Planks"
    },
    {
      "x": -8,
      "y": 0,
      "z": -3,
      "name": "Wood_Deadwood_Planks"
    },
    {
      "x": -8,
      "y": 1,
      "z": -3,
      "name": "Wood_Deadwood_Planks"
    },
    {
      "x": -8,
      "y": 2,
      "z": -3,
      "name": "Wood_Deadwood_Planks"
    },
    {
      "x": -8,
      "y": 3,
      "z": -3,
      "name": "Wood_Deadwood_Planks"
    },
    {
      "x": -8,
      "y": 4,
      "z": -3,
      "name": "Wood_Deadwood_Planks"
    },
    {
      "x": -8,
      "y": 5,
      "z": -3,
      "name": "Wood_Deadwood_Planks"
    },
    {
      "x": -8,
      "y": 6,
      "z": -3,
      "name": "Wood_Deadwood_Planks"
    },
    {
      "x": -8,
      "y": 0,
      "z": -2,
      "name": "Wood_Deadwood_Planks"
    },
    {
      "x": -8,
      "y": 1,
      "z": -2,
      "name": "Wood_Deadwood_Planks"
    },
    {
      "x": -8,
      "y": 2,
      "z": -2,
      "name": "Wood_Deadwood_Planks"
    },
    {
      "x": -8,
      "y": 3,
      "z": -2,
      "name": "Wood_Deadwood_Planks"
    },
    {
      "x": -8,
      "y": 4,
      "z": -2,
      "name": "Wood_Deadwood_Planks"
    },
    {
      "x": -8,
      "y": 5,
      "z": -2,
      "name": "Wood_Deadwood_Planks"
    },
    {
      "x": -8,
      "y": 0,
      "z": -1,
      "name": "Wood_Deadwood_Planks"
    },
    {
      "x": -8,
      "y": 0,
      "z": 0,
      "name": "Wood_Deadwood_Planks"
    },
    {
      "x": -8,
      "y": 0,
      "z": 1,
      "name": "Wood_Deadwood_Planks"
    },
    {
      "x": -8,
      "y": 0,
      "z": 2,
      "name": "Wood_Deadwood_Planks"
    },
    {
      "x": -8,
      "y": 0,
      "z": 3,
      "name": "Wood_Deadwood_Planks"
    },
    {
      "x": -8,
      "y": 0,
      "z": 4,
      "name": "Wood_Deadwood_Planks"
    },
    {
      "x": -8,
      "y": 0,
      "z": 5,
      "name": "Wood_Deadwood_Planks"
    },
    {
      "x": -8,
      "y": 0,
      "z": 6,
      "name": "Wood_Deadwood_Planks"
    },
    {
      "x": -8,
      "y": 0,
      "z": 7,
      "name": "Wood_Deadwood_Planks"
    },
    {
      "x": -8,
      "y": 0,
      "z": 8,
      "name": "Wood_Deadwood_Planks"
    },
    {
      "x": -7,
      "y": 0,
      "z": -8,
      "name": "Wood_Deadwood_Planks"
    },
    {
      "x": -7,
      "y": 0,
      "z": -7,
      "name": "Wood_Deadwood_Planks"
    },
    {
      "x": -7,
      "y": 3,
      "z": -7,
      "name": "Furniture_Ancient_Ladder",
      "rotation": 3
    },
    {
      "x": -7,
      "y": 4,
      "z": -7,
      "name": "Furniture_Ancient_Ladder",
      "rotation": 3
    },
    {
      "x": -7,
      "y": 0,
      "z": -6,
      "name": "Wood_Drywood_Planks",
      "rotation": 2
    },
    {
      "x": -7,
      "y": 1,
      "z": -6,
      "name": "D_Wood_Deadwood_Door"
    },
    {
      "x": -7,
      "y": 2,
      "z": -6,
      "name": "D_Wood_Deadwood_Door",
      "filler": 1024
    },
    {
      "x": -7,
      "y": 3,
      "z": -6,
      "name": "D_Wood_Deadwood_Plank_Corner"
    },
    {
      "x": -7,
      "y": 4,
      "z": -6,
      "name": "Wood_Deadwood_Ornate"
    },
    {
      "x": -7,
      "y": 0,
      "z": -5,
      "name": "Wood_Drywood_Planks",
      "rotation": 2
    },
    {
      "x": -7,
      "y": 1,
      "z": -5,
      "name": "Furniture_Human_Ruins_Stool",
      "rotation": 1
    },
    {
      "x": -7,
      "y": 4,
      "z": -5,
      "name": "Wood_Deadwood_Ornate"
    },
    {
      "x": -7,
      "y": 0,
      "z": -4,
      "name": "Wood_Drywood_Planks",
      "rotation": 2
    },
    {
      "x": -7,
      "y": 1,
      "z": -4,
      "name": "Furniture_Human_Ruins_Desk",
      "filler": 31
    },
    {
      "x": -7,
      "y": 2,
      "z": -4,
      "name": "Recipe_Book_Magic_Void"
    },
    {
      "x": -7,
      "y": 4,
      "z": -4,
      "name": "Wood_Deadwood_Ornate"
    },
    {
      "x": -7,
      "y": 0,
      "z": -3,
      "name": "Wood_Drywood_Planks",
      "rotation": 2
    },
    {
      "x": -7,
      "y": 1,
      "z": -3,
      "name": "Furniture_Human_Ruins_Stool",
      "rotation": 1
    },
    {
      "x": -7,
      "y": 4,
      "z": -3,
      "name": "Wood_Deadwood_Ornate"
    },
    {
      "x": -7,
      "y": 0,
      "z": -2,
      "name": "Wood_Drywood_Planks",
      "rotation": 2
    },
    {
      "x": -7,
      "y": 1,
      "z": -2,
      "name": "D_Wood_Deadwood_Door",
      "rotation": 2
    },
    {
      "x": -7,
      "y": 2,
      "z": -2,
      "name": "D_Wood_Deadwood_Door",
      "filler": 1024,
      "rotation": 2
    },
    {
      "x": -7,
      "y": 3,
      "z": -2,
      "name": "D_Wood_Deadwood_Plank_Corner",
      "rotation": 2
    },
    {
      "x": -7,
      "y": 4,
      "z": -2,
      "name": "Wood_Deadwood_Ornate"
    },
    {
      "x": -7,
      "y": 0,
      "z": -1,
      "name": "Wood_Deadwood_Planks"
    },
    {
      "x": -7,
      "y": 0,
      "z": 0,
      "name": "Wood_Deadwood_Planks"
    },
    {
      "x": -7,
      "y": 0,
      "z": 1,
      "name": "Wood_Deadwood_Planks"
    },
    {
      "x": -7,
      "y": 0,
      "z": 2,
      "name": "Wood_Deadwood_Planks"
    },
    {
      "x": -7,
      "y": 0,
      "z": 3,
      "name": "Wood_Deadwood_Planks"
    },
    {
      "x": -7,
      "y": 0,
      "z": 4,
      "name": "Wood_Deadwood_Planks"
    },
    {
      "x": -7,
      "y": 0,
      "z": 5,
      "name": "Wood_Deadwood_Planks"
    },
    {
      "x": -7,
      "y": 0,
      "z": 6,
      "name": "Wood_Deadwood_Planks"
    },
    {
      "x": -7,
      "y": 0,
      "z": 7,
      "name": "Wood_Deadwood_Planks"
    },
    {
      "x": -7,
      "y": 3,
      "z": 7,
      "name": "Furniture_Ancient_Ladder",
      "rotation": 3
    },
    {
      "x": -7,
      "y": 4,
      "z": 7,
      "name": "Furniture_Ancient_Ladder",
      "rotation": 3
    },
    {
      "x": -7,
      "y": 0,
      "z": 8,
      "name": "Wood_Deadwood_Planks"
    },
    {
      "x": -6,
      "y": 0,
      "z": -8,
      "name": "Wood_Deadwood_Planks"
    },
    {
      "x": -6,
      "y": 1,
      "z": -8,
      "name": "Wood_Deadwood_Planks"
    },
    {
      "x": -6,
      "y": 2,
      "z": -8,
      "name": "Wood_Deadwood_Planks"
    },
    {
      "x": -6,
      "y": 3,
      "z": -8,
      "name": "Wood_Deadwood_Planks"
    },
    {
      "x": -6,
      "y": 4,
      "z": -8,
      "name": "Wood_Deadwood_Planks"
    },
    {
      "x": -6,
      "y": 5,
      "z": -8,
      "name": "Wood_Deadwood_Beam"
    },
    {
      "x": -6,
      "y": 6,
      "z": -8,
      "name": "Wood_Deadwood_Beam"
    },
    {
      "x": -6,
      "y": 0,
      "z": -7,
      "name": "Wood_Drywood_Planks",
      "rotation": 2
    },
    {
      "x": -6,
      "y": 1,
      "z": -7,
      "name": "D_Wood_Deadwood_Plank_Corner",
      "rotation": 1
    },
    {
      "x": -6,
      "y": 2,
      "z": -7,
      "name": "D_Wood_Deadwood_Plank_Corner",
      "rotation": 1
    },
    {
      "x": -6,
      "y": 3,
      "z": -7,
      "name": "D_Wood_Deadwood_Plank_Corner",
      "rotation": 1
    },
    {
      "x": -6,
      "y": 4,
      "z": -7,
      "name": "Wood_Deadwood_Planks"
    },
    {
      "x": -6,
      "y": 0,
      "z": -6,
      "name": "Wood_Drywood_Planks",
      "rotation": 2
    },
    {
      "x": -6,
      "y": 1,
      "z": -6,
      "name": "D_Wood_Deadwood_Plank_Corner",
      "rotation": 1
    },
    {
      "x": -6,
      "y": 2,
      "z": -6,
      "name": "D_Wood_Deadwood_Plank_Corner",
      "rotation": 1
    },
    {
      "x": -6,
      "y": 3,
      "z": -6,
      "name": "D_Wood_Deadwood_Plank_Corner",
      "rotation": 1
    },
    {
      "x": -6,
      "y": 4,
      "z": -6,
      "name": "Wood_Deadwood_Planks"
    },
    {
      "x": -6,
      "y": 0,
      "z": -5,
      "name": "Wood_Drywood_Planks",
      "rotation": 2
    },
    {
      "x": -6,
      "y": 1,
      "z": -5,
      "name": "Furniture_Human_Ruins_Stool",
      "rotation": 1
    },
    {
      "x": -6,
      "y": 4,
      "z": -5,
      "name": "Wood_Deadwood_Ornate"
    },
    {
      "x": -6,
      "y": 0,
      "z": -4,
      "name": "Wood_Drywood_Planks",
      "rotation": 2
    },
    {
      "x": -6,
      "y": 1,
      "z": -4,
      "name": "Furniture_Human_Ruins_Desk"
    },
    {
      "x": -6,
      "y": 2,
      "z": -4,
      "name": "Recipe_Book_Magic_Air"
    },
    {
      "x": -6,
      "y": 4,
      "z": -4,
      "name": "Wood_Deadwood_Ornate"
    },
    {
      "x": -6,
      "y": 0,
      "z": -3,
      "name": "Wood_Drywood_Planks",
      "rotation": 2
    },
    {
      "x": -6,
      "y": 1,
      "z": -3,
      "name": "Furniture_Human_Ruins_Stool",
      "rotation": 1
    },
    {
      "x": -6,
      "y": 4,
      "z": -3,
      "name": "Wood_Deadwood_Ornate"
    },
    {
      "x": -6,
      "y": 0,
      "z": -2,
      "name": "Wood_Drywood_Planks",
      "rotation": 2
    },
    {
      "x": -6,
      "y": 1,
      "z": -2,
      "name": "D_Wood_Deadwood_Plank_Corner",
      "rotation": 2
    },
    {
      "x": -6,
      "y": 2,
      "z": -2,
      "name": "D_Wood_Deadwood_Plank_Corner",
      "rotation": 2
    },
    {
      "x": -6,
      "y": 3,
      "z": -2,
      "name": "D_Wood_Deadwood_Plank_Corner",
      "rotation": 2
    },
    {
      "x": -6,
      "y": 4,
      "z": -2,
      "name": "Wood_Deadwood_Planks"
    },
    {
      "x": -6,
      "y": 0,
      "z": -1,
      "name": "Wood_Drywood_Planks",
      "rotation": 2
    },
    {
      "x": -6,
      "y": 1,
      "z": -1,
      "name": "Wood_Deadwood_Planks"
    },
    {
      "x": -6,
      "y": 2,
      "z": -1,
      "name": "D_Wood_Deadwood_Plank_Corner",
      "rotation": 2
    },
    {
      "x": -6,
      "y": 3,
      "z": -1,
      "name": "Wood_Deadwood_Planks"
    },
    {
      "x": -6,
      "y": 4,
      "z": -1,
      "name": "Wood_Deadwood_Planks"
    },
    {
      "x": -6,
      "y": 0,
      "z": 0,
      "name": "Wood_Drywood_Planks",
      "rotation": 2
    },
    {
      "x": -6,
      "y": 1,
      "z": 0,
      "name": "D_Wood_Deadwood_Plank_Corner",
      "rotation": 1
    },
    {
      "x": -6,
      "y": 2,
      "z": 0,
      "name": "D_Wood_Deadwood_Plank_Corner",
      "rotation": 2
    },
    {
      "x": -6,
      "y": 3,
      "z": 0,
      "name": "Wood_Deadwood_Planks"
    },
    {
      "x": -6,
      "y": 4,
      "z": 0,
      "name": "Wood_Deadwood_Planks"
    },
    {
      "x": -6,
      "y": 5,
      "z": 0,
      "name": "Wood_Deadwood_Beam"
    },
    {
      "x": -6,
      "y": 6,
      "z": 0,
      "name": "Wood_Deadwood_Beam"
    },
    {
      "x": -6,
      "y": 0,
      "z": 1,
      "name": "Wood_Drywood_Planks",
      "rotation": 2
    },
    {
      "x": -6,
      "y": 1,
      "z": 1,
      "name": "Wood_Deadwood_Planks"
    },
    {
      "x": -6,
      "y": 2,
      "z": 1,
      "name": "D_Wood_Deadwood_Plank_Corner",
      "rotation": 2
    },
    {
      "x": -6,
      "y": 3,
      "z": 1,
      "name": "Wood_Deadwood_Planks"
    },
    {
      "x": -6,
      "y": 4,
      "z": 1,
      "name": "Wood_Deadwood_Planks"
    },
    {
      "x": -6,
      "y": 0,
      "z": 2,
      "name": "Wood_Drywood_Planks",
      "rotation": 2
    },
    {
      "x": -6,
      "y": 1,
      "z": 2,
      "name": "Wood_Deadwood_Planks"
    },
    {
      "x": -6,
      "y": 2,
      "z": 2,
      "name": "D_Wood_Deadwood_Plank_Corner",
      "rotation": 2
    },
    {
      "x": -6,
      "y": 3,
      "z": 2,
      "name": "D_Wood_Deadwood_Plank_Corner",
      "rotation": 1
    },
    {
      "x": -6,
      "y": 4,
      "z": 2,
      "name": "Wood_Deadwood_Planks"
    },
    {
      "x": -6,
      "y": 5,
      "z": 2,
      "name": "Wood_Deadwood_Beam"
    },
    {
      "x": -6,
      "y": 6,
      "z": 2,
      "name": "Wood_Deadwood_Beam"
    },
    {
      "x": -6,
      "y": 0,
      "z": 3,
      "name": "Wood_Drywood_Planks",
      "rotation": 2
    },
    {
      "x": -6,
      "y": 1,
      "z": 3,
      "name": "Wood_Deadwood_Planks"
    },
    {
      "x": -6,
      "y": 2,
      "z": 3,
      "name": "D_Wood_Deadwood_Plank_Corner",
      "rotation": 1
    },
    {
      "x": -6,
      "y": 3,
      "z": 3,
      "name": "Wood_Deadwood_Planks"
    },
    {
      "x": -6,
      "y": 4,
      "z": 3,
      "name": "Wood_Deadwood_Planks"
    },
    {
      "x": -6,
      "y": 0,
      "z": 4,
      "name": "Wood_Drywood_Planks",
      "rotation": 2
    },
    {
      "x": -6,
      "y": 1,
      "z": 4,
      "name": "Wood_Deadwood_Planks"
    },
    {
      "x": -6,
      "y": 2,
      "z": 4,
      "name": "D_Wood_Deadwood_Plank_Corner",
      "rotation": 1
    },
    {
      "x": -6,
      "y": 3,
      "z": 4,
      "name": "Wood_Deadwood_Planks"
    },
    {
      "x": -6,
      "y": 4,
      "z": 4,
      "name": "Wood_Deadwood_Planks"
    },
    {
      "x": -6,
      "y": 5,
      "z": 4,
      "name": "Wood_Deadwood_Planks"
    },
    {
      "x": -6,
      "y": 0,
      "z": 5,
      "name": "Wood_Drywood_Planks",
      "rotation": 2
    },
    {
      "x": -6,
      "y": 1,
      "z": 5,
      "name": "D_Wood_Deadwood_Door",
      "rotation": 1
    },
    {
      "x": -6,
      "y": 2,
      "z": 5,
      "name": "D_Wood_Deadwood_Door",
      "filler": 1024,
      "rotation": 1
    },
    {
      "x": -6,
      "y": 3,
      "z": 5,
      "name": "Wood_Deadwood_Planks"
    },
    {
      "x": -6,
      "y": 4,
      "z": 5,
      "name": "Wood_Deadwood_Planks"
    },
    {
      "x": -6,
      "y": 5,
      "z": 5,
      "name": "Wood_Deadwood_Planks"
    },
    {
      "x": -6,
      "y": 0,
      "z": 6,
      "name": "Wood_Drywood_Planks",
      "rotation": 2
    },
    {
      "x": -6,
      "y": 1,
      "z": 6,
      "name": "Wood_Deadwood_Planks"
    },
    {
      "x": -6,
      "y": 2,
      "z": 6,
      "name": "D_Wood_Deadwood_Plank_Corner",
      "rotation": 1
    },
    {
      "x": -6,
      "y": 3,
      "z": 6,
      "name": "Wood_Deadwood_Planks"
    },
    {
      "x": -6,
      "y": 4,
      "z": 6,
      "name": "Wood_Deadwood_Planks"
    },
    {
      "x": -6,
      "y": 5,
      "z": 6,
      "name": "Wood_Deadwood_Planks"
    },
    {
      "x": -6,
      "y": 6,
      "z": 6,
      "name": "Wood_Deadwood_Planks"
    },
    {
      "x": -6,
      "y": 0,
      "z": 7,
      "name": "Wood_Drywood_Planks",
      "rotation": 2
    },
    {
      "x": -6,
      "y": 1,
      "z": 7,
      "name": "D_Wood_Deadwood_Plank_Corner",
      "rotation": 1
    },
    {
      "x": -6,
      "y": 2,
      "z": 7,
      "name": "D_Wood_Deadwood_Plank_Corner",
      "rotation": 1
    },
    {
      "x": -6,
      "y": 3,
      "z": 7,
      "name": "Wood_Deadwood_Planks"
    },
    {
      "x": -6,
      "y": 4,
      "z": 7,
      "name": "Wood_Deadwood_Planks"
    },
    {
      "x": -6,
      "y": 0,
      "z": 8,
      "name": "Wood_Deadwood_Planks"
    },
    {
      "x": -6,
      "y": 1,
      "z": 8,
      "name": "Wood_Deadwood_Planks"
    },
    {
      "x": -6,
      "y": 2,
      "z": 8,
      "name": "Wood_Deadwood_Planks"
    },
    {
      "x": -6,
      "y": 3,
      "z": 8,
      "name": "Wood_Deadwood_Planks"
    },
    {
      "x": -6,
      "y": 4,
      "z": 8,
      "name": "Wood_Deadwood_Planks"
    },
    {
      "x": -6,
      "y": 5,
      "z": 8,
      "name": "Wood_Deadwood_Planks"
    },
    {
      "x": -5,
      "y": 0,
      "z": -8,
      "name": "Wood_Deadwood_Planks"
    },
    {
      "x": -5,
      "y": 1,
      "z": -8,
      "name": "Wood_Deadwood_Planks"
    },
    {
      "x": -5,
      "y": 2,
      "z": -8,
      "name": "Wood_Deadwood_Planks"
    },
    {
      "x": -5,
      "y": 3,
      "z": -8,
      "name": "Wood_Deadwood_Planks"
    },
    {
      "x": -5,
      "y": 4,
      "z": -8,
      "name": "Wood_Deadwood_Planks"
    },
    {
      "x": -5,
      "y": 0,
      "z": -7,
      "name": "Wood_Drywood_Planks",
      "rotation": 2
    },
    {
      "x": -5,
      "y": 1,
      "z": -7,
      "name": "Furniture_Ancient_Wardrobe",
      "filler": 31
    },
    {
      "x": -5,
      "y": 2,
      "z": -7,
      "name": "Furniture_Ancient_Wardrobe",
      "filler": 1055
    },
    {
      "x": -5,
      "y": 4,
      "z": -7,
      "name": "Wood_Deadwood_Ornate"
    },
    {
      "x": -5,
      "y": 0,
      "z": -6,
      "name": "Wood_Drywood_Planks",
      "rotation": 2
    },
    {
      "x": -5,
      "y": 2,
      "z": -6,
      "name": "Furniture_Ancient_Shelf",
      "rotation": 1
    },
    {
      "x": -5,
      "y": 4,
      "z": -6,
      "name": "Wood_Deadwood_Ornate"
    },
    {
      "x": -5,
      "y": 0,
      "z": -5,
      "name": "Wood_Drywood_Planks",
      "rotation": 2
    },
    {
      "x": -5,
      "y": 4,
      "z": -5,
      "name": "Wood_Deadwood_Ornate"
    },
    {
      "x": -5,
      "y": 0,
      "z": -4,
      "name": "Wood_Drywood_Planks",
      "rotation": 2
    },
    {
      "x": -5,
      "y": 4,
      "z": -4,
      "name": "Wood_Deadwood_Ornate"
    },
    {
      "x": -5,
      "y": 5,
      "z": -4,
      "name": "Wood_Deadwood_Planks_Half",
      "rotation": 7
    },
    {
      "x": -5,
      "y": 6,
      "z": -4,
      "name": "Wood_Deadwood_Stairs",
      "rotation": 9
    },
    {
      "x": -5,
      "y": 0,
      "z": -3,
      "name": "Wood_Drywood_Planks",
      "rotation": 2
    },
    {
      "x": -5,
      "y": 4,
      "z": -3,
      "name": "Wood_Deadwood_Ornate"
    },
    {
      "x": -5,
      "y": 0,
      "z": -2,
      "name": "Wood_Drywood_Planks",
      "rotation": 2
    },
    {
      "x": -5,
      "y": 4,
      "z": -2,
      "name": "Wood_Deadwood_Ornate"
    },
    {
      "x": -5,
      "y": 5,
      "z": -2,
      "name": "Wood_Deadwood_Beam"
    },
    {
      "x": -5,
      "y": 6,
      "z": -2,
      "name": "Wood_Deadwood_Beam"
    },
    {
      "x": -5,
      "y": 0,
      "z": -1,
      "name": "Wood_Drywood_Planks",
      "rotation": 2
    },
    {
      "x": -5,
      "y": 2,
      "z": -1,
      "name": "Furniture_Ancient_Shelf",
      "rotation": 1
    },
    {
      "x": -5,
      "y": 4,
      "z": -1,
      "name": "Wood_Deadwood_Ornate"
    },
    {
      "x": -5,
      "y": 0,
      "z": 0,
      "name": "Wood_Drywood_Planks",
      "rotation": 2
    },
    {
      "x": -5,
      "y": 2,
      "z": 0,
      "name": "Furniture_Ancient_Shelf",
      "rotation": 1
    },
    {
      "x": -5,
      "y": 4,
      "z": 0,
      "name": "Wood_Deadwood_Planks"
    },
    {
      "x": -5,
      "y": 5,
      "z": 0,
      "name": "Wood_Deadwood_Planks"
    },
    {
      "x": -5,
      "y": 6,
      "z": 0,
      "name": "Wood_Deadwood_Planks"
    },
    {
      "x": -5,
      "y": 0,
      "z": 1,
      "name": "Wood_Drywood_Planks",
      "rotation": 2
    },
    {
      "x": -5,
      "y": 1,
      "z": 1,
      "name": "Wood_Deadwood_Stairs",
      "rotation": 2
    },
    {
      "x": -5,
      "y": 2,
      "z": 1,
      "name": "Furniture_Ancient_Shelf",
      "rotation": 1
    },
    {
      "x": -5,
      "y": 4,
      "z": 1,
      "name": "Wood_Deadwood_Ornate"
    },
    {
      "x": -5,
      "y": 0,
      "z": 2,
      "name": "Wood_Drywood_Planks",
      "rotation": 2
    },
    {
      "x": -5,
      "y": 1,
      "z": 2,
      "name": "Block_Spawner_Block",
      "components": {
        "Components": {
          "PlacedByInteraction": {
            "WhoPlacedUuid": {
              "$binary": "IUbJQAVpTxOQHQmz7elhOA==",
              "$type": "04"
            }
          },
          "BlockSpawner": {
            "BlockSpawnerId": "Chests_Terror_Tower"
          }
        }
      },
      "rotation": 1
    },
    {
      "x": -5,
      "y": 4,
      "z": 2,
      "name": "Wood_Deadwood_Ornate"
    },
    {
      "x": -5,
      "y": 5,
      "z": 2,
      "name": "Wood_Deadwood_Planks_Half",
      "rotation": 7
    },
    {
      "x": -5,
      "y": 6,
      "z": 2,
      "name": "Wood_Deadwood_Stairs",
      "rotation": 9
    },
    {
      "x": -5,
      "y": 0,
      "z": 3,
      "name": "Wood_Drywood_Planks",
      "rotation": 2
    },
    {
      "x": -5,
      "y": 1,
      "z": 3,
      "name": "Block_Spawner_Block",
      "components": {
        "Components": {
          "PlacedByInteraction": {
            "WhoPlacedUuid": {
              "$binary": "IUbJQAVpTxOQHQmz7elhOA==",
              "$type": "04"
            }
          },
          "BlockSpawner": {
            "BlockSpawnerId": "Chests_Terror_Tower"
          }
        }
      },
      "rotation": 1
    },
    {
      "x": -5,
      "y": 4,
      "z": 3,
      "name": "Wood_Deadwood_Ornate"
    },
    {
      "x": -5,
      "y": 0,
      "z": 4,
      "name": "Wood_Drywood_Planks",
      "rotation": 2
    },
    {
      "x": -5,
      "y": 1,
      "z": 4,
      "name": "Wood_Deadwood_Stairs"
    },
    {
      "x": -5,
      "y": 2,
      "z": 4,
      "name": "Furniture_Ancient_Shelf",
      "rotation": 1
    },
    {
      "x": -5,
      "y": 4,
      "z": 4,
      "name": "Wood_Deadwood_Ornate"
    },
    {
      "x": -5,
      "y": 0,
      "z": 5,
      "name": "Wood_Drywood_Planks",
      "rotation": 2
    },
    {
      "x": -5,
      "y": 2,
      "z": 5,
      "name": "Furniture_Ancient_Shelf",
      "rotation": 1
    },
    {
      "x": -5,
      "y": 4,
      "z": 5,
      "name": "Wood_Deadwood_Ornate"
    },
    {
      "x": -5,
      "y": 0,
      "z": 6,
      "name": "Wood_Drywood_Planks",
      "rotation": 2
    },
    {
      "x": -5,
      "y": 2,
      "z": 6,
      "name": "Furniture_Ancient_Shelf",
      "rotation": 1
    },
    {
      "x": -5,
      "y": 4,
      "z": 6,
      "name": "Wood_Deadwood_Ornate"
    },
    {
      "x": -5,
      "y": 0,
      "z": 7,
      "name": "Wood_Drywood_Planks",
      "rotation": 2
    },
    {
      "x": -5,
      "y": 1,
      "z": 7,
      "name": "Furniture_Human_Ruins_Bookshelf",
      "rotation": 2
    },
    {
      "x": -5,
      "y": 2,
      "z": 7,
      "name": "Furniture_Human_Ruins_Bookshelf",
      "rotation": 2
    },
    {
      "x": -5,
      "y": 3,
      "z": 7,
      "name": "Furniture_Human_Ruins_Bookshelf",
      "rotation": 2
    },
    {
      "x": -5,
      "y": 4,
      "z": 7,
      "name": "Wood_Deadwood_Ornate"
    },
    {
      "x": -5,
      "y": 0,
      "z": 8,
      "name": "Wood_Deadwood_Planks"
    },
    {
      "x": -5,
      "y": 1,
      "z": 8,
      "name": "Wood_Deadwood_Planks"
    },
    {
      "x": -5,
      "y": 2,
      "z": 8,
      "name": "Wood_Deadwood_Planks"
    },
    {
      "x": -5,
      "y": 3,
      "z": 8,
      "name": "Wood_Deadwood_Planks"
    },
    {
      "x": -5,
      "y": 4,
      "z": 8,
      "name": "Wood_Deadwood_Planks"
    },
    {
      "x": -5,
      "y": 5,
      "z": 8,
      "name": "Wood_Deadwood_Planks"
    },
    {
      "x": -4,
      "y": 0,
      "z": -8,
      "name": "Wood_Deadwood_Planks"
    },
    {
      "x": -4,
      "y": 1,
      "z": -8,
      "name": "Wood_Deadwood_Planks"
    },
    {
      "x": -4,
      "y": 2,
      "z": -8,
      "name": "Wood_Deadwood_Planks"
    },
    {
      "x": -4,
      "y": 3,
      "z": -8,
      "name": "Wood_Deadwood_Planks"
    },
    {
      "x": -4,
      "y": 4,
      "z": -8,
      "name": "Wood_Deadwood_Planks"
    },
    {
      "x": -4,
      "y": 0,
      "z": -7,
      "name": "Wood_Drywood_Planks",
      "rotation": 2
    },
    {
      "x": -4,
      "y": 1,
      "z": -7,
      "name": "Furniture_Ancient_Wardrobe"
    },
    {
      "x": -4,
      "y": 2,
      "z": -7,
      "name": "Furniture_Ancient_Wardrobe",
      "filler": 1024
    },
    {
      "x": -4,
      "y": 4,
      "z": -7,
      "name": "Wood_Deadwood_Ornate"
    },
    {
      "x": -4,
      "y": 0,
      "z": -6,
      "name": "Wood_Drywood_Planks",
      "rotation": 2
    },
    {
      "x": -4,
      "y": 4,
      "z": -6,
      "name": "Wood_Deadwood_Ornate"
    },
    {
      "x": -4,
      "y": 5,
      "z": -6,
      "name": "Wood_Deadwood_Beam"
    },
    {
      "x": -4,
      "y": 6,
      "z": -6,
      "name": "Wood_Deadwood_Beam"
    },
    {
      "x": -4,
      "y": 0,
      "z": -5,
      "name": "Wood_Drywood_Planks",
      "rotation": 2
    },
    {
      "x": -4,
      "y": 4,
      "z": -5,
      "name": "Wood_Deadwood_Ornate"
    },
    {
      "x": -4,
      "y": 5,
      "z": -5,
      "name": "Wood_Deadwood_Planks_Half",
      "rotation": 6
    },
    {
      "x": -4,
      "y": 6,
      "z": -5,
      "name": "Wood_Deadwood_Stairs",
      "rotation": 8
    },
    {
      "x": -4,
      "y": 0,
      "z": -4,
      "name": "Wood_Drywood_Planks",
      "rotation": 2
    },
    {
      "x": -4,
      "y": 4,
      "z": -4,
      "name": "Wood_Deadwood_Ornate"
    },
    {
      "x": -4,
      "y": 5,
      "z": -4,
      "name": "Wood_Deadwood_Planks"
    },
    {
      "x": -4,
      "y": 6,
      "z": -4,
      "name": "Wood_Deadwood_Planks"
    },
    {
      "x": -4,
      "y": 0,
      "z": -3,
      "name": "Wood_Drywood_Planks",
      "rotation": 2
    },
    {
      "x": -4,
      "y": 4,
      "z": -3,
      "name": "Wood_Deadwood_Ornate"
    },
    {
      "x": -4,
      "y": 5,
      "z": -3,
      "name": "Wood_Deadwood_Planks_Half",
      "rotation": 4
    },
    {
      "x": -4,
      "y": 6,
      "z": -3,
      "name": "Wood_Deadwood_Stairs",
      "rotation": 10
    },
    {
      "x": -4,
      "y": 0,
      "z": -2,
      "name": "Wood_Drywood_Planks",
      "rotation": 2
    },
    {
      "x": -4,
      "y": 4,
      "z": -2,
      "name": "Wood_Deadwood_Ornate"
    },
    {
      "x": -4,
      "y": 0,
      "z": -1,
      "name": "Wood_Drywood_Planks",
      "rotation": 2
    },
    {
      "x": -4,
      "y": 4,
      "z": -1,
      "name": "Wood_Deadwood_Ornate"
    },
    {
      "x": -4,
      "y": 0,
      "z": 0,
      "name": "Wood_Drywood_Planks",
      "rotation": 2
    },
    {
      "x": -4,
      "y": 4,
      "z": 0,
      "name": "Wood_Deadwood_Planks"
    },
    {
      "x": -4,
      "y": 5,
      "z": 0,
      "name": "Wood_Deadwood_Planks"
    },
    {
      "x": -4,
      "y": 6,
      "z": 0,
      "name": "Wood_Deadwood_Planks"
    },
    {
      "x": -4,
      "y": 0,
      "z": 1,
      "name": "Wood_Drywood_Planks",
      "rotation": 2
    },
    {
      "x": -4,
      "y": 4,
      "z": 1,
      "name": "Wood_Deadwood_Ornate"
    },
    {
      "x": -4,
      "y": 5,
      "z": 1,
      "name": "Wood_Deadwood_Planks_Half",
      "rotation": 6
    },
    {
      "x": -4,
      "y": 6,
      "z": 1,
      "name": "Wood_Deadwood_Stairs",
      "rotation": 8
    },
    {
      "x": -4,
      "y": 0,
      "z": 2,
      "name": "Wood_Drywood_Planks",
      "rotation": 2
    },
    {
      "x": -4,
      "y": 4,
      "z": 2,
      "name": "Wood_Deadwood_Ornate"
    },
    {
      "x": -4,
      "y": 5,
      "z": 2,
      "name": "Wood_Deadwood_Planks"
    },
    {
      "x": -4,
      "y": 6,
      "z": 2,
      "name": "Wood_Deadwood_Planks"
    },
    {
      "x": -4,
      "y": 0,
      "z": 3,
      "name": "Wood_Drywood_Planks",
      "rotation": 2
    },
    {
      "x": -4,
      "y": 4,
      "z": 3,
      "name": "Wood_Deadwood_Ornate"
    },
    {
      "x": -4,
      "y": 5,
      "z": 3,
      "name": "Wood_Deadwood_Planks_Half",
      "rotation": 4
    },
    {
      "x": -4,
      "y": 6,
      "z": 3,
      "name": "Wood_Deadwood_Stairs",
      "rotation": 10
    },
    {
      "x": -4,
      "y": 0,
      "z": 4,
      "name": "Wood_Drywood_Planks",
      "rotation": 2
    },
    {
      "x": -4,
      "y": 4,
      "z": 4,
      "name": "Wood_Deadwood_Ornate"
    },
    {
      "x": -4,
      "y": 0,
      "z": 5,
      "name": "Wood_Drywood_Planks",
      "rotation": 2
    },
    {
      "x": -4,
      "y": 4,
      "z": 5,
      "name": "Wood_Deadwood_Ornate"
    },
    {
      "x": -4,
      "y": 0,
      "z": 6,
      "name": "Wood_Drywood_Planks",
      "rotation": 2
    },
    {
      "x": -4,
      "y": 4,
      "z": 6,
      "name": "Wood_Deadwood_Ornate"
    },
    {
      "x": -4,
      "y": 0,
      "z": 7,
      "name": "Wood_Drywood_Planks",
      "rotation": 2
    },
    {
      "x": -4,
      "y": 1,
      "z": 7,
      "name": "Furniture_Human_Ruins_Bookshelf",
      "rotation": 2
    },
    {
      "x": -4,
      "y": 2,
      "z": 7,
      "name": "Furniture_Human_Ruins_Bookshelf",
      "rotation": 2
    },
    {
      "x": -4,
      "y": 3,
      "z": 7,
      "name": "Furniture_Human_Ruins_Bookshelf",
      "rotation": 2
    },
    {
      "x": -4,
      "y": 4,
      "z": 7,
      "name": "Wood_Deadwood_Ornate"
    },
    {
      "x": -4,
      "y": 0,
      "z": 8,
      "name": "Wood_Deadwood_Planks"
    },
    {
      "x": -4,
      "y": 1,
      "z": 8,
      "name": "Wood_Deadwood_Planks"
    },
    {
      "x": -4,
      "y": 2,
      "z": 8,
      "name": "Wood_Deadwood_Planks"
    },
    {
      "x": -4,
      "y": 3,
      "z": 8,
      "name": "Wood_Deadwood_Planks"
    },
    {
      "x": -4,
      "y": 4,
      "z": 8,
      "name": "Wood_Deadwood_Planks"
    },
    {
      "x": -3,
      "y": 0,
      "z": -8,
      "name": "Wood_Deadwood_Planks"
    },
    {
      "x": -3,
      "y": 1,
      "z": -8,
      "name": "Wood_Deadwood_Planks"
    },
    {
      "x": -3,
      "y": 2,
      "z": -8,
      "name": "Wood_Deadwood_Planks"
    },
    {
      "x": -3,
      "y": 3,
      "z": -8,
      "name": "Wood_Deadwood_Planks"
    },
    {
      "x": -3,
      "y": 4,
      "z": -8,
      "name": "Wood_Deadwood_Planks"
    },
    {
      "x": -3,
      "y": 0,
      "z": -7,
      "name": "Wood_Drywood_Planks",
      "rotation": 2
    },
    {
      "x": -3,
      "y": 1,
      "z": -7,
      "name": "Furniture_Human_Ruins_Wardrobe",
      "filler": 31
    },
    {
      "x": -3,
      "y": 2,
      "z": -7,
      "name": "Furniture_Human_Ruins_Wardrobe",
      "filler": 1055
    },
    {
      "x": -3,
      "y": 4,
      "z": -7,
      "name": "Wood_Deadwood_Ornate"
    },
    {
      "x": -3,
      "y": 0,
      "z": -6,
      "name": "Wood_Drywood_Planks",
      "rotation": 2
    },
    {
      "x": -3,
      "y": 4,
      "z": -6,
      "name": "Wood_Deadwood_Ornate"
    },
    {
      "x": -3,
      "y": 0,
      "z": -5,
      "name": "Wood_Drywood_Planks",
      "rotation": 2
    },
    {
      "x": -3,
      "y": 4,
      "z": -5,
      "name": "Wood_Deadwood_Ornate"
    },
    {
      "x": -3,
      "y": 0,
      "z": -4,
      "name": "Wood_Drywood_Planks",
      "rotation": 2
    },
    {
      "x": -3,
      "y": 4,
      "z": -4,
      "name": "Wood_Deadwood_Ornate"
    },
    {
      "x": -3,
      "y": 5,
      "z": -4,
      "name": "Wood_Deadwood_Planks_Half",
      "rotation": 5
    },
    {
      "x": -3,
      "y": 6,
      "z": -4,
      "name": "Wood_Deadwood_Stairs",
      "rotation": 11
    },
    {
      "x": -3,
      "y": 0,
      "z": -3,
      "name": "Wood_Drywood_Planks",
      "rotation": 2
    },
    {
      "x": -3,
      "y": 4,
      "z": -3,
      "name": "Wood_Deadwood_Ornate"
    },
    {
      "x": -3,
      "y": 0,
      "z": -2,
      "name": "Wood_Drywood_Planks",
      "rotation": 2
    },
    {
      "x": -3,
      "y": 4,
      "z": -2,
      "name": "Wood_Deadwood_Ornate"
    },
    {
      "x": -3,
      "y": 0,
      "z": -1,
      "name": "Wood_Drywood_Planks",
      "rotation": 2
    },
    {
      "x": -3,
      "y": 4,
      "z": -1,
      "name": "Wood_Deadwood_Ornate"
    },
    {
      "x": -3,
      "y": 0,
      "z": 0,
      "name": "Wood_Drywood_Planks",
      "rotation": 2
    },
    {
      "x": -3,
      "y": 4,
      "z": 0,
      "name": "Wood_Deadwood_Planks"
    },
    {
      "x": -3,
      "y": 5,
      "z": 0,
      "name": "Wood_Deadwood_Planks"
    },
    {
      "x": -3,
      "y": 0,
      "z": 1,
      "name": "Wood_Drywood_Planks",
      "rotation": 2
    },
    {
      "x": -3,
      "y": 4,
      "z": 1,
      "name": "Wood_Deadwood_Ornate"
    },
    {
      "x": -3,
      "y": 0,
      "z": 2,
      "name": "Wood_Drywood_Planks",
      "rotation": 2
    },
    {
      "x": -3,
      "y": 4,
      "z": 2,
      "name": "Wood_Deadwood_Ornate"
    },
    {
      "x": -3,
      "y": 5,
      "z": 2,
      "name": "Wood_Deadwood_Planks_Half",
      "rotation": 5
    },
    {
      "x": -3,
      "y": 6,
      "z": 2,
      "name": "Wood_Deadwood_Stairs",
      "rotation": 11
    },
    {
      "x": -3,
      "y": 0,
      "z": 3,
      "name": "Wood_Drywood_Planks",
      "rotation": 2
    },
    {
      "x": -3,
      "y": 4,
      "z": 3,
      "name": "Wood_Deadwood_Ornate"
    },
    {
      "x": -3,
      "y": 0,
      "z": 4,
      "name": "Wood_Drywood_Planks",
      "rotation": 2
    },
    {
      "x": -3,
      "y": 4,
      "z": 4,
      "name": "Wood_Deadwood_Ornate"
    },
    {
      "x": -3,
      "y": 0,
      "z": 5,
      "name": "Wood_Drywood_Planks",
      "rotation": 2
    },
    {
      "x": -3,
      "y": 4,
      "z": 5,
      "name": "Wood_Deadwood_Ornate"
    },
    {
      "x": -3,
      "y": 5,
      "z": 5,
      "name": "Wood_Deadwood_Beam"
    },
    {
      "x": -3,
      "y": 6,
      "z": 5,
      "name": "Wood_Deadwood_Beam"
    },
    {
      "x": -3,
      "y": 0,
      "z": 6,
      "name": "Wood_Drywood_Planks",
      "rotation": 2
    },
    {
      "x": -3,
      "y": 4,
      "z": 6,
      "name": "Wood_Deadwood_Ornate"
    },
    {
      "x": -3,
      "y": 0,
      "z": 7,
      "name": "Wood_Drywood_Planks",
      "rotation": 2
    },
    {
      "x": -3,
      "y": 1,
      "z": 7,
      "name": "Furniture_Human_Ruins_Bookshelf",
      "rotation": 2
    },
    {
      "x": -3,
      "y": 2,
      "z": 7,
      "name": "Furniture_Human_Ruins_Bookshelf",
      "rotation": 2
    },
    {
      "x": -3,
      "y": 3,
      "z": 7,
      "name": "Furniture_Human_Ruins_Bookshelf",
      "rotation": 2
    },
    {
      "x": -3,
      "y": 4,
      "z": 7,
      "name": "Wood_Deadwood_Ornate"
    },
    {
      "x": -3,
      "y": 5,
      "z": 7,
      "name": "Wood_Deadwood_Beam"
    },
    {
      "x": -3,
      "y": 6,
      "z": 7,
      "name": "Wood_Deadwood_Beam"
    },
    {
      "x": -3,
      "y": 0,
      "z": 8,
      "name": "Wood_Deadwood_Planks"
    },
    {
      "x": -3,
      "y": 1,
      "z": 8,
      "name": "Wood_Deadwood_Planks"
    },
    {
      "x": -3,
      "y": 2,
      "z": 8,
      "name": "Wood_Deadwood_Planks"
    },
    {
      "x": -3,
      "y": 3,
      "z": 8,
      "name": "Wood_Deadwood_Planks"
    },
    {
      "x": -3,
      "y": 4,
      "z": 8,
      "name": "Wood_Deadwood_Planks"
    },
    {
      "x": -2,
      "y": 0,
      "z": -8,
      "name": "Wood_Deadwood_Planks"
    },
    {
      "x": -2,
      "y": 1,
      "z": -8,
      "name": "Wood_Deadwood_Planks"
    },
    {
      "x": -2,
      "y": 2,
      "z": -8,
      "name": "Wood_Deadwood_Planks"
    },
    {
      "x": -2,
      "y": 3,
      "z": -8,
      "name": "Wood_Deadwood_Planks"
    },
    {
      "x": -2,
      "y": 4,
      "z": -8,
      "name": "Wood_Deadwood_Planks"
    },
    {
      "x": -2,
      "y": 0,
      "z": -7,
      "name": "Wood_Drywood_Planks",
      "rotation": 2
    },
    {
      "x": -2,
      "y": 1,
      "z": -7,
      "name": "Furniture_Human_Ruins_Wardrobe"
    },
    {
      "x": -2,
      "y": 2,
      "z": -7,
      "name": "Furniture_Human_Ruins_Wardrobe",
      "filler": 1024
    },
    {
      "x": -2,
      "y": 4,
      "z": -7,
      "name": "Wood_Deadwood_Planks"
    },
    {
      "x": -2,
      "y": 5,
      "z": -7,
      "name": "Wood_Deadwood_Beam"
    },
    {
      "x": -2,
      "y": 6,
      "z": -7,
      "name": "Wood_Deadwood_Beam"
    },
    {
      "x": -2,
      "y": 0,
      "z": -6,
      "name": "Wood_Drywood_Planks",
      "rotation": 2
    },
    {
      "x": -2,
      "y": 4,
      "z": -6,
      "name": "Wood_Deadwood_Planks"
    },
    {
      "x": -2,
      "y": 0,
      "z": -5,
      "name": "Wood_Drywood_Planks",
      "rotation": 2
    },
    {
      "x": -2,
      "y": 4,
      "z": -5,
      "name": "Wood_Deadwood_Ornate"
    },
    {
      "x": -2,
      "y": 0,
      "z": -4,
      "name": "Wood_Drywood_Planks",
      "rotation": 2
    },
    {
      "x": -2,
      "y": 4,
      "z": -4,
      "name": "Wood_Deadwood_Ornate"
    },
    {
      "x": -2,
      "y": 0,
      "z": -3,
      "name": "Wood_Drywood_Planks",
      "rotation": 2
    },
    {
      "x": -2,
      "y": 4,
      "z": -3,
      "name": "Wood_Deadwood_Ornate"
    },
    {
      "x": -2,
      "y": 5,
      "z": -3,
      "name": "Wood_Deadwood_Beam"
    },
    {
      "x": -2,
      "y": 6,
      "z": -3,
      "name": "Wood_Deadwood_Beam"
    },
    {
      "x": -2,
      "y": 0,
      "z": -2,
      "name": "Wood_Drywood_Planks",
      "rotation": 2
    },
    {
      "x": -2,
      "y": 4,
      "z": -2,
      "name": "Wood_Deadwood_Planks"
    },
    {
      "x": -2,
      "y": 0,
      "z": -1,
      "name": "Wood_Drywood_Planks",
      "rotation": 2
    },
    {
      "x": -2,
      "y": 4,
      "z": -1,
      "name": "Wood_Deadwood_Planks"
    },
    {
      "x": -2,
      "y": 5,
      "z": -1,
      "name": "Wood_Deadwood_Beam"
    },
    {
      "x": -2,
      "y": 6,
      "z": -1,
      "name": "Wood_Deadwood_Beam"
    },
    {
      "x": -2,
      "y": 0,
      "z": 0,
      "name": "Wood_Drywood_Planks",
      "rotation": 2
    },
    {
      "x": -2,
      "y": 4,
      "z": 0,
      "name": "Wood_Deadwood_Planks"
    },
    {
      "x": -2,
      "y": 5,
      "z": 0,
      "name": "Wood_Deadwood_Planks"
    },
    {
      "x": -2,
      "y": 0,
      "z": 1,
      "name": "Wood_Drywood_Planks",
      "rotation": 2
    },
    {
      "x": -2,
      "y": 4,
      "z": 1,
      "name": "Wood_Deadwood_Ornate"
    },
    {
      "x": -2,
      "y": 0,
      "z": 2,
      "name": "Wood_Drywood_Planks",
      "rotation": 2
    },
    {
      "x": -2,
      "y": 4,
      "z": 2,
      "name": "Wood_Deadwood_Planks"
    },
    {
      "x": -2,
      "y": 5,
      "z": 2,
      "name": "Wood_Deadwood_Beam"
    },
    {
      "x": -2,
      "y": 6,
      "z": 2,
      "name": "Wood_Deadwood_Beam"
    },
    {
      "x": -2,
      "y": 0,
      "z": 3,
      "name": "Wood_Drywood_Planks",
      "rotation": 2
    },
    {
      "x": -2,
      "y": 4,
      "z": 3,
      "name": "Wood_Deadwood_Ornate"
    },
    {
      "x": -2,
      "y": 0,
      "z": 4,
      "name": "Wood_Drywood_Planks",
      "rotation": 2
    },
    {
      "x": -2,
      "y": 4,
      "z": 4,
      "name": "Wood_Deadwood_Ornate"
    },
    {
      "x": -2,
      "y": 0,
      "z": 5,
      "name": "Wood_Drywood_Planks",
      "rotation": 2
    },
    {
      "x": -2,
      "y": 4,
      "z": 5,
      "name": "Wood_Deadwood_Ornate"
    },
    {
      "x": -2,
      "y": 0,
      "z": 6,
      "name": "Wood_Drywood_Planks",
      "rotation": 2
    },
    {
      "x": -2,
      "y": 4,
      "z": 6,
      "name": "Wood_Deadwood_Ornate"
    },
    {
      "x": -2,
      "y": 0,
      "z": 7,
      "name": "Wood_Drywood_Planks",
      "rotation": 2
    },
    {
      "x": -2,
      "y": 1,
      "z": 7,
      "name": "Furniture_Human_Ruins_Bookshelf",
      "rotation": 2
    },
    {
      "x": -2,
      "y": 2,
      "z": 7,
      "name": "Furniture_Human_Ruins_Bookshelf",
      "rotation": 2
    },
    {
      "x": -2,
      "y": 3,
      "z": 7,
      "name": "Furniture_Human_Ruins_Bookshelf",
      "rotation": 2
    },
    {
      "x": -2,
      "y": 4,
      "z": 7,
      "name": "Wood_Deadwood_Ornate"
    },
    {
      "x": -2,
      "y": 0,
      "z": 8,
      "name": "Wood_Deadwood_Planks"
    },
    {
      "x": -2,
      "y": 1,
      "z": 8,
      "name": "Wood_Deadwood_Planks"
    },
    {
      "x": -2,
      "y": 2,
      "z": 8,
      "name": "Wood_Deadwood_Planks"
    },
    {
      "x": -2,
      "y": 3,
      "z": 8,
      "name": "Wood_Deadwood_Planks"
    },
    {
      "x": -2,
      "y": 4,
      "z": 8,
      "name": "Wood_Deadwood_Planks"
    },
    {
      "x": -2,
      "y": 5,
      "z": 8,
      "name": "Wood_Deadwood_Beam"
    },
    {
      "x": -2,
      "y": 6,
      "z": 8,
      "name": "Wood_Deadwood_Beam"
    },
    {
      "x": -1,
      "y": 0,
      "z": -8,
      "name": "Wood_Deadwood_Planks"
    },
    {
      "x": -1,
      "y": 1,
      "z": -8,
      "name": "Wood_Deadwood_Planks"
    },
    {
      "x": -1,
      "y": 2,
      "z": -8,
      "name": "Wood_Deadwood_Planks"
    },
    {
      "x": -1,
      "y": 3,
      "z": -8,
      "name": "Wood_Deadwood_Planks"
    },
    {
      "x": -1,
      "y": 4,
      "z": -8,
      "name": "Wood_Deadwood_Planks"
    },
    {
      "x": -1,
      "y": 0,
      "z": -7,
      "name": "Wood_Drywood_Planks",
      "rotation": 2
    },
    {
      "x": -1,
      "y": 1,
      "z": -7,
      "name": "Furniture_Ancient_Wardrobe",
      "filler": 31
    },
    {
      "x": -1,
      "y": 2,
      "z": -7,
      "name": "Furniture_Ancient_Wardrobe",
      "filler": 1055
    },
    {
      "x": -1,
      "y": 4,
      "z": -7,
      "name": "Wood_Deadwood_Planks"
    },
    {
      "x": -1,
      "y": 0,
      "z": -6,
      "name": "Wood_Drywood_Planks",
      "rotation": 2
    },
    {
      "x": -1,
      "y": 4,
      "z": -6,
      "name": "Wood_Deadwood_Planks"
    },
    {
      "x": -1,
      "y": 0,
      "z": -5,
      "name": "Wood_Drywood_Planks",
      "rotation": 2
    },
    {
      "x": -1,
      "y": 4,
      "z": -5,
      "name": "Wood_Deadwood_Ornate"
    },
    {
      "x": -1,
      "y": 0,
      "z": -4,
      "name": "Wood_Drywood_Planks",
      "rotation": 2
    },
    {
      "x": -1,
      "y": 1,
      "z": -4,
      "name": "Furniture_Human_Ruins_Stool",
      "rotation": 3
    },
    {
      "x": -1,
      "y": 4,
      "z": -4,
      "name": "Wood_Deadwood_Ornate"
    },
    {
      "x": -1,
      "y": 0,
      "z": -3,
      "name": "Wood_Drywood_Planks",
      "rotation": 2
    },
    {
      "x": -1,
      "y": 1,
      "z": -3,
      "name": "Furniture_Human_Ruins_Desk",
      "filler": 31
    },
    {
      "x": -1,
      "y": 4,
      "z": -3,
      "name": "Wood_Deadwood_Ornate"
    },
    {
      "x": -1,
      "y": 0,
      "z": -2,
      "name": "Wood_Drywood_Planks",
      "rotation": 2
    },
    {
      "x": -1,
      "y": 1,
      "z": -2,
      "name": "Furniture_Human_Ruins_Desk",
      "filler": 31
    },
    {
      "x": -1,
      "y": 4,
      "z": -2,
      "name": "Wood_Deadwood_Planks"
    },
    {
      "x": -1,
      "y": 0,
      "z": -1,
      "name": "Wood_Drywood_Planks",
      "rotation": 2
    },
    {
      "x": -1,
      "y": 1,
      "z": -1,
      "name": "Furniture_Human_Ruins_Stool",
      "rotation": 3
    },
    {
      "x": -1,
      "y": 4,
      "z": -1,
      "name": "Wood_Deadwood_Planks"
    },
    {
      "x": -1,
      "y": 0,
      "z": 0,
      "name": "Wood_Drywood_Planks",
      "rotation": 2
    },
    {
      "x": -1,
      "y": 4,
      "z": 0,
      "name": "Wood_Deadwood_Planks"
    },
    {
      "x": -1,
      "y": 0,
      "z": 1,
      "name": "Wood_Drywood_Planks",
      "rotation": 2
    },
    {
      "x": -1,
      "y": 1,
      "z": 1,
      "name": "Furniture_Human_Ruins_Stool",
      "rotation": 3
    },
    {
      "x": -1,
      "y": 4,
      "z": 1,
      "name": "Wood_Deadwood_Ornate"
    },
    {
      "x": -1,
      "y": 0,
      "z": 2,
      "name": "Wood_Drywood_Planks",
      "rotation": 2
    },
    {
      "x": -1,
      "y": 1,
      "z": 2,
      "name": "Furniture_Human_Ruins_Desk",
      "rotation": 2
    },
    {
      "x": -1,
      "y": 4,
      "z": 2,
      "name": "Wood_Deadwood_Ornate"
    },
    {
      "x": -1,
      "y": 5,
      "z": 2,
      "name": "Wood_Deadwood_Beam"
    },
    {
      "x": -1,
      "y": 6,
      "z": 2,
      "name": "Wood_Deadwood_Beam"
    },
    {
      "x": -1,
      "y": 0,
      "z": 3,
      "name": "Wood_Drywood_Planks",
      "rotation": 2
    },
    {
      "x": -1,
      "y": 1,
      "z": 3,
      "name": "Furniture_Human_Ruins_Desk",
      "filler": 31
    },
    {
      "x": -1,
      "y": 4,
      "z": 3,
      "name": "Wood_Deadwood_Ornate"
    },
    {
      "x": -1,
      "y": 0,
      "z": 4,
      "name": "Wood_Drywood_Planks",
      "rotation": 2
    },
    {
      "x": -1,
      "y": 1,
      "z": 4,
      "name": "Furniture_Human_Ruins_Stool",
      "rotation": 3
    },
    {
      "x": -1,
      "y": 4,
      "z": 4,
      "name": "Wood_Deadwood_Ornate"
    },
    {
      "x": -1,
      "y": 0,
      "z": 5,
      "name": "Wood_Drywood_Planks",
      "rotation": 2
    },
    {
      "x": -1,
      "y": 4,
      "z": 5,
      "name": "Wood_Deadwood_Ornate"
    },
    {
      "x": -1,
      "y": 0,
      "z": 6,
      "name": "Wood_Drywood_Planks",
      "rotation": 2
    },
    {
      "x": -1,
      "y": 4,
      "z": 6,
      "name": "Wood_Deadwood_Ornate"
    },
    {
      "x": -1,
      "y": 0,
      "z": 7,
      "name": "Wood_Drywood_Planks",
      "rotation": 2
    },
    {
      "x": -1,
      "y": 1,
      "z": 7,
      "name": "Furniture_Human_Ruins_Bookshelf",
      "rotation": 2
    },
    {
      "x": -1,
      "y": 2,
      "z": 7,
      "name": "Furniture_Human_Ruins_Bookshelf",
      "rotation": 2
    },
    {
      "x": -1,
      "y": 3,
      "z": 7,
      "name": "Furniture_Human_Ruins_Bookshelf",
      "rotation": 2
    },
    {
      "x": -1,
      "y": 4,
      "z": 7,
      "name": "Wood_Deadwood_Ornate"
    },
    {
      "x": -1,
      "y": 0,
      "z": 8,
      "name": "Wood_Deadwood_Planks"
    },
    {
      "x": -1,
      "y": 1,
      "z": 8,
      "name": "Wood_Deadwood_Planks"
    },
    {
      "x": -1,
      "y": 2,
      "z": 8,
      "name": "Wood_Deadwood_Planks"
    },
    {
      "x": -1,
      "y": 3,
      "z": 8,
      "name": "Wood_Deadwood_Planks"
    },
    {
      "x": -1,
      "y": 4,
      "z": 8,
      "name": "Wood_Deadwood_Planks"
    },
    {
      "x": -1,
      "y": 5,
      "z": 8,
      "name": "Wood_Deadwood_Planks"
    },
    {
      "x": 0,
      "y": 0,
      "z": -8,
      "name": "Wood_Deadwood_Planks",
      "rotation": 1
    },
    {
      "x": 0,
      "y": 1,
      "z": -8,
      "name": "Wood_Deadwood_Planks"
    },
    {
      "x": 0,
      "y": 2,
      "z": -8,
      "name": "Wood_Deadwood_Planks"
    },
    {
      "x": 0,
      "y": 3,
      "z": -8,
      "name": "Wood_Deadwood_Planks"
    },
    {
      "x": 0,
      "y": 4,
      "z": -8,
      "name": "Wood_Deadwood_Planks"
    },
    {
      "x": 0,
      "y": 0,
      "z": -7,
      "name": "Wood_Drywood_Planks"
    },
    {
      "x": 0,
      "y": 1,
      "z": -7,
      "name": "Furniture_Ancient_Wardrobe"
    },
    {
      "x": 0,
      "y": 2,
      "z": -7,
      "name": "Furniture_Ancient_Wardrobe",
      "filler": 1024
    },
    {
      "x": 0,
      "y": 4,
      "z": -7,
      "name": "Wood_Deadwood_Planks"
    },
    {
      "x": 0,
      "y": 0,
      "z": -6,
      "name": "Wood_Drywood_Planks"
    },
    {
      "x": 0,
      "y": 4,
      "z": -6,
      "name": "Wood_Deadwood_Planks"
    },
    {
      "x": 0,
      "y": 0,
      "z": -5,
      "name": "Wood_Drywood_Planks"
    },
    {
      "x": 0,
      "y": 4,
      "z": -5,
      "name": "Wood_Deadwood_Planks"
    },
    {
      "x": 0,
      "y": 5,
      "z": -5,
      "name": "Wood_Deadwood_Planks"
    },
    {
      "x": 0,
      "y": 0,
      "z": -4,
      "name": "Wood_Drywood_Planks"
    },
    {
      "x": 0,
      "y": 1,
      "z": -4,
      "name": "Furniture_Human_Ruins_Stool",
      "rotation": 3
    },
    {
      "x": 0,
      "y": 4,
      "z": -4,
      "name": "Wood_Deadwood_Planks",
      "rotation": 1
    },
    {
      "x": 0,
      "y": 5,
      "z": -4,
      "name": "Wood_Deadwood_Planks",
      "rotation": 1
    },
    {
      "x": 0,
      "y": 6,
      "z": -4,
      "name": "Wood_Deadwood_Planks"
    },
    {
      "x": 0,
      "y": 0,
      "z": -3,
      "name": "Wood_Drywood_Planks"
    },
    {
      "x": 0,
      "y": 1,
      "z": -3,
      "name": "Furniture_Human_Ruins_Desk"
    },
    {
      "x": 0,
      "y": 4,
      "z": -3,
      "name": "Wood_Deadwood_Planks",
      "rotation": 1
    },
    {
      "x": 0,
      "y": 0,
      "z": -2,
      "name": "Wood_Drywood_Planks"
    },
    {
      "x": 0,
      "y": 1,
      "z": -2,
      "name": "Furniture_Human_Ruins_Desk"
    },
    {
      "x": 0,
      "y": 4,
      "z": -2,
      "name": "Wood_Deadwood_Planks",
      "rotation": 1
    },
    {
      "x": 0,
      "y": 0,
      "z": -1,
      "name": "Wood_Drywood_Planks"
    },
    {
      "x": 0,
      "y": 1,
      "z": -1,
      "name": "Furniture_Human_Ruins_Stool",
      "rotation": 3
    },
    {
      "x": 0,
      "y": 4,
      "z": -1,
      "name": "Wood_Deadwood_Planks",
      "rotation": 1
    },
    {
      "x": 0,
      "y": 5,
      "z": -1,
      "name": "Wood_Deadwood_Planks",
      "rotation": 1
    },
    {
      "x": 0,
      "y": 0,
      "z": 0,
      "name": "Wood_Drywood_Planks"
    },
    {
      "x": 0,
      "y": 4,
      "z": 0,
      "name": "Wood_Deadwood_Planks"
    },
    {
      "x": 0,
      "y": 5,
      "z": 0,
      "name": "Wood_Deadwood_Planks",
      "rotation": 1
    },
    {
      "x": 0,
      "y": 6,
      "z": 0,
      "name": "Wood_Deadwood_Planks",
      "rotation": 1
    },
    {
      "x": 0,
      "y": 0,
      "z": 1,
      "name": "Wood_Drywood_Planks"
    },
    {
      "x": 0,
      "y": 1,
      "z": 1,
      "name": "Furniture_Human_Ruins_Stool",
      "rotation": 3
    },
    {
      "x": 0,
      "y": 4,
      "z": 1,
      "name": "Wood_Deadwood_Planks"
    },
    {
      "x": 0,
      "y": 0,
      "z": 2,
      "name": "Wood_Drywood_Planks"
    },
    {
      "x": 0,
      "y": 1,
      "z": 2,
      "name": "Furniture_Human_Ruins_Desk",
      "filler": 1,
      "rotation": 2
    },
    {
      "x": 0,
      "y": 4,
      "z": 2,
      "name": "Wood_Deadwood_Planks"
    },
    {
      "x": 0,
      "y": 0,
      "z": 3,
      "name": "Wood_Drywood_Planks"
    },
    {
      "x": 0,
      "y": 1,
      "z": 3,
      "name": "Furniture_Human_Ruins_Desk"
    },
    {
      "x": 0,
      "y": 4,
      "z": 3,
      "name": "Wood_Deadwood_Planks"
    },
    {
      "x": 0,
      "y": 5,
      "z": 3,
      "name": "Wood_Deadwood_Fence"
    },
    {
      "x": 0,
      "y": 6,
      "z": 3,
      "name": "Wood_Deadwood_Fence"
    },
    {
      "x": 0,
      "y": 0,
      "z": 4,
      "name": "Wood_Drywood_Planks"
    },
    {
      "x": 0,
      "y": 1,
      "z": 4,
      "name": "Furniture_Human_Ruins_Stool",
      "rotation": 3
    },
    {
      "x": 0,
      "y": 4,
      "z": 4,
      "name": "Wood_Deadwood_Planks"
    },
    {
      "x": 0,
      "y": 5,
      "z": 4,
      "name": "Wood_Deadwood_Beam"
    },
    {
      "x": 0,
      "y": 6,
      "z": 4,
      "name": "Wood_Deadwood_Beam"
    },
    {
      "x": 0,
      "y": 0,
      "z": 5,
      "name": "Wood_Drywood_Planks"
    },
    {
      "x": 0,
      "y": 4,
      "z": 5,
      "name": "Wood_Deadwood_Planks"
    },
    {
      "x": 0,
      "y": 0,
      "z": 6,
      "name": "Wood_Drywood_Planks"
    },
    {
      "x": 0,
      "y": 4,
      "z": 6,
      "name": "Wood_Deadwood_Planks"
    },
    {
      "x": 0,
      "y": 5,
      "z": 6,
      "name": "Wood_Deadwood_Planks"
    },
    {
      "x": 0,
      "y": 6,
      "z": 6,
      "name": "Wood_Deadwood_Planks"
    },
    {
      "x": 0,
      "y": 0,
      "z": 7,
      "name": "Wood_Drywood_Planks"
    },
    {
      "x": 0,
      "y": 1,
      "z": 7,
      "name": "Furniture_Human_Ruins_Bookshelf",
      "rotation": 2
    },
    {
      "x": 0,
      "y": 2,
      "z": 7,
      "name": "Furniture_Human_Ruins_Bookshelf",
      "rotation": 2
    },
    {
      "x": 0,
      "y": 3,
      "z": 7,
      "name": "Furniture_Human_Ruins_Bookshelf",
      "rotation": 2
    },
    {
      "x": 0,
      "y": 4,
      "z": 7,
      "name": "Wood_Deadwood_Planks"
    },
    {
      "x": 0,
      "y": 5,
      "z": 7,
      "name": "Wood_Deadwood_Planks"
    },
    {
      "x": 0,
      "y": 6,
      "z": 7,
      "name": "Wood_Deadwood_Planks"
    },
    {
      "x": 0,
      "y": 0,
      "z": 8,
      "name": "Wood_Deadwood_Planks"
    },
    {
      "x": 0,
      "y": 1,
      "z": 8,
      "name": "Wood_Deadwood_Planks"
    },
    {
      "x": 0,
      "y": 2,
      "z": 8,
      "name": "Wood_Deadwood_Planks"
    },
    {
      "x": 0,
      "y": 3,
      "z": 8,
      "name": "Wood_Deadwood_Planks"
    },
    {
      "x": 0,
      "y": 4,
      "z": 8,
      "name": "Wood_Deadwood_Planks"
    },
    {
      "x": 0,
      "y": 5,
      "z": 8,
      "name": "Wood_Deadwood_Planks"
    },
    {
      "x": 0,
      "y": 6,
      "z": 8,
      "name": "Wood_Deadwood_Planks"
    },
    {
      "x": 1,
      "y": 0,
      "z": -8,
      "name": "Wood_Deadwood_Planks",
      "rotation": 1
    },
    {
      "x": 1,
      "y": 1,
      "z": -8,
      "name": "Wood_Deadwood_Planks"
    },
    {
      "x": 1,
      "y": 2,
      "z": -8,
      "name": "Wood_Deadwood_Planks"
    },
    {
      "x": 1,
      "y": 3,
      "z": -8,
      "name": "Wood_Deadwood_Planks"
    },
    {
      "x": 1,
      "y": 4,
      "z": -8,
      "name": "Wood_Deadwood_Planks"
    },
    {
      "x": 1,
      "y": 0,
      "z": -7,
      "name": "Wood_Drywood_Planks"
    },
    {
      "x": 1,
      "y": 1,
      "z": -7,
      "name": "Furniture_Human_Ruins_Wardrobe",
      "filler": 31
    },
    {
      "x": 1,
      "y": 2,
      "z": -7,
      "name": "Furniture_Human_Ruins_Wardrobe",
      "filler": 1055
    },
    {
      "x": 1,
      "y": 4,
      "z": -7,
      "name": "Wood_Deadwood_Planks"
    },
    {
      "x": 1,
      "y": 0,
      "z": -6,
      "name": "Wood_Drywood_Planks"
    },
    {
      "x": 1,
      "y": 4,
      "z": -6,
      "name": "Wood_Deadwood_Planks"
    },
    {
      "x": 1,
      "y": 0,
      "z": -5,
      "name": "Wood_Drywood_Planks"
    },
    {
      "x": 1,
      "y": 4,
      "z": -5,
      "name": "Wood_Deadwood_Planks"
    },
    {
      "x": 1,
      "y": 0,
      "z": -4,
      "name": "Wood_Drywood_Planks"
    },
    {
      "x": 1,
      "y": 4,
      "z": -4,
      "name": "Wood_Deadwood_Planks",
      "rotation": 1
    },
    {
      "x": 1,
      "y": 5,
      "z": -4,
      "name": "Wood_Deadwood_Planks",
      "rotation": 1
    },
    {
      "x": 1,
      "y": 6,
      "z": -4,
      "name": "Wood_Deadwood_Planks",
      "rotation": 1
    },
    {
      "x": 1,
      "y": 0,
      "z": -3,
      "name": "Wood_Drywood_Planks"
    },
    {
      "x": 1,
      "y": 4,
      "z": -3,
      "name": "Wood_Deadwood_Ornate",
      "rotation": 1
    },
    {
      "x": 1,
      "y": 0,
      "z": -2,
      "name": "Wood_Drywood_Planks"
    },
    {
      "x": 1,
      "y": 4,
      "z": -2,
      "name": "Wood_Deadwood_Ornate",
      "rotation": 1
    },
    {
      "x": 1,
      "y": 5,
      "z": -2,
      "name": "Wood_Deadwood_Beam",
      "rotation": 1
    },
    {
      "x": 1,
      "y": 6,
      "z": -2,
      "name": "Wood_Deadwood_Beam",
      "rotation": 1
    },
    {
      "x": 1,
      "y": 0,
      "z": -1,
      "name": "Wood_Drywood_Planks"
    },
    {
      "x": 1,
      "y": 4,
      "z": -1,
      "name": "Wood_Deadwood_Ornate",
      "rotation": 1
    },
    {
      "x": 1,
      "y": 0,
      "z": 0,
      "name": "Wood_Drywood_Planks"
    },
    {
      "x": 1,
      "y": 4,
      "z": 0,
      "name": "Wood_Deadwood_Planks",
      "rotation": 1
    },
    {
      "x": 1,
      "y": 5,
      "z": 0,
      "name": "Wood_Deadwood_Planks",
      "rotation": 1
    },
    {
      "x": 1,
      "y": 6,
      "z": 0,
      "name": "Wood_Deadwood_Planks",
      "rotation": 1
    },
    {
      "x": 1,
      "y": 0,
      "z": 1,
      "name": "Wood_Drywood_Planks"
    },
    {
      "x": 1,
      "y": 4,
      "z": 1,
      "name": "Wood_Deadwood_Ornate"
    },
    {
      "x": 1,
      "y": 0,
      "z": 2,
      "name": "Wood_Drywood_Planks"
    },
    {
      "x": 1,
      "y": 4,
      "z": 2,
      "name": "Wood_Deadwood_Ornate"
    },
    {
      "x": 1,
      "y": 0,
      "z": 3,
      "name": "Wood_Drywood_Planks"
    },
    {
      "x": 1,
      "y": 4,
      "z": 3,
      "name": "Wood_Deadwood_Ornate"
    },
    {
      "x": 1,
      "y": 5,
      "z": 3,
      "name": "Wood_Deadwood_Fence"
    },
    {
      "x": 1,
      "y": 0,
      "z": 4,
      "name": "Wood_Drywood_Planks"
    },
    {
      "x": 1,
      "y": 4,
      "z": 4,
      "name": "Wood_Deadwood_Ornate"
    },
    {
      "x": 1,
      "y": 0,
      "z": 5,
      "name": "Wood_Drywood_Planks"
    },
    {
      "x": 1,
      "y": 4,
      "z": 5,
      "name": "Wood_Deadwood_Ornate"
    },
    {
      "x": 1,
      "y": 0,
      "z": 6,
      "name": "Wood_Drywood_Planks"
    },
    {
      "x": 1,
      "y": 4,
      "z": 6,
      "name": "Wood_Deadwood_Ornate"
    },
    {
      "x": 1,
      "y": 0,
      "z": 7,
      "name": "Wood_Drywood_Planks"
    },
    {
      "x": 1,
      "y": 1,
      "z": 7,
      "name": "Furniture_Human_Ruins_Bookshelf",
      "rotation": 2
    },
    {
      "x": 1,
      "y": 2,
      "z": 7,
      "name": "Furniture_Human_Ruins_Bookshelf",
      "rotation": 2
    },
    {
      "x": 1,
      "y": 3,
      "z": 7,
      "name": "Furniture_Human_Ruins_Bookshelf",
      "rotation": 2
    },
    {
      "x": 1,
      "y": 4,
      "z": 7,
      "name": "Wood_Deadwood_Ornate"
    },
    {
      "x": 1,
      "y": 5,
      "z": 7,
      "name": "Wood_Deadwood_Beam"
    },
    {
      "x": 1,
      "y": 6,
      "z": 7,
      "name": "Wood_Deadwood_Beam"
    },
    {
      "x": 1,
      "y": 0,
      "z": 8,
      "name": "Wood_Deadwood_Planks"
    },
    {
      "x": 1,
      "y": 1,
      "z": 8,
      "name": "Wood_Deadwood_Planks"
    },
    {
      "x": 1,
      "y": 2,
      "z": 8,
      "name": "Wood_Deadwood_Planks"
    },
    {
      "x": 1,
      "y": 3,
      "z": 8,
      "name": "Wood_Deadwood_Planks"
    },
    {
      "x": 1,
      "y": 4,
      "z": 8,
      "name": "Wood_Deadwood_Planks"
    },
    {
      "x": 2,
      "y": 0,
      "z": -8,
      "name": "Wood_Deadwood_Planks",
      "rotation": 1
    },
    {
      "x": 2,
      "y": 1,
      "z": -8,
      "name": "Wood_Deadwood_Planks",
      "rotation": 1
    },
    {
      "x": 2,
      "y": 2,
      "z": -8,
      "name": "Wood_Deadwood_Planks",
      "rotation": 1
    },
    {
      "x": 2,
      "y": 3,
      "z": -8,
      "name": "Wood_Deadwood_Planks",
      "rotation": 1
    },
    {
      "x": 2,
      "y": 4,
      "z": -8,
      "name": "Wood_Deadwood_Planks",
      "rotation": 1
    },
    {
      "x": 2,
      "y": 0,
      "z": -7,
      "name": "Wood_Drywood_Planks"
    },
    {
      "x": 2,
      "y": 1,
      "z": -7,
      "name": "Furniture_Human_Ruins_Wardrobe"
    },
    {
      "x": 2,
      "y": 2,
      "z": -7,
      "name": "Furniture_Human_Ruins_Wardrobe",
      "filler": 1024
    },
    {
      "x": 2,
      "y": 4,
      "z": -7,
      "name": "Wood_Deadwood_Planks",
      "rotation": 1
    },
    {
      "x": 2,
      "y": 0,
      "z": -6,
      "name": "Wood_Drywood_Planks"
    },
    {
      "x": 2,
      "y": 4,
      "z": -6,
      "name": "Wood_Deadwood_Planks",
      "rotation": 1
    },
    {
      "x": 2,
      "y": 0,
      "z": -5,
      "name": "Wood_Drywood_Planks"
    },
    {
      "x": 2,
      "y": 4,
      "z": -5,
      "name": "Wood_Deadwood_Planks",
      "rotation": 1
    },
    {
      "x": 2,
      "y": 5,
      "z": -5,
      "name": "Wood_Deadwood_Planks",
      "rotation": 1
    },
    {
      "x": 2,
      "y": 0,
      "z": -4,
      "name": "Wood_Drywood_Planks"
    },
    {
      "x": 2,
      "y": 4,
      "z": -4,
      "name": "Wood_Deadwood_Planks",
      "rotation": 1
    },
    {
      "x": 2,
      "y": 5,
      "z": -4,
      "name": "Wood_Deadwood_Planks",
      "rotation": 1
    },
    {
      "x": 2,
      "y": 6,
      "z": -4,
      "name": "Wood_Deadwood_Planks",
      "rotation": 1
    },
    {
      "x": 2,
      "y": 0,
      "z": -3,
      "name": "Wood_Drywood_Planks"
    },
    {
      "x": 2,
      "y": 4,
      "z": -3,
      "name": "Wood_Deadwood_Ornate",
      "rotation": 1
    },
    {
      "x": 2,
      "y": 0,
      "z": -2,
      "name": "Wood_Drywood_Planks"
    },
    {
      "x": 2,
      "y": 4,
      "z": -2,
      "name": "Wood_Deadwood_Ornate",
      "rotation": 1
    },
    {
      "x": 2,
      "y": 0,
      "z": -1,
      "name": "Wood_Drywood_Planks"
    },
    {
      "x": 2,
      "y": 1,
      "z": -1,
      "name": "Furniture_Human_Ruins_Stool"
    },
    {
      "x": 2,
      "y": 4,
      "z": -1,
      "name": "Wood_Deadwood_Ornate",
      "rotation": 1
    },
    {
      "x": 2,
      "y": 0,
      "z": 0,
      "name": "Wood_Drywood_Planks"
    },
    {
      "x": 2,
      "y": 1,
      "z": 0,
      "name": "Furniture_Human_Ruins_Stool"
    },
    {
      "x": 2,
      "y": 4,
      "z": 0,
      "name": "Wood_Deadwood_Planks",
      "rotation": 1
    },
    {
      "x": 2,
      "y": 5,
      "z": 0,
      "name": "Wood_Deadwood_Planks",
      "rotation": 1
    },
    {
      "x": 2,
      "y": 0,
      "z": 1,
      "name": "Wood_Drywood_Planks"
    },
    {
      "x": 2,
      "y": 4,
      "z": 1,
      "name": "Wood_Deadwood_Ornate"
    },
    {
      "x": 2,
      "y": 0,
      "z": 2,
      "name": "Wood_Drywood_Planks"
    },
    {
      "x": 2,
      "y": 4,
      "z": 2,
      "name": "Wood_Deadwood_Ornate"
    },
    {
      "x": 2,
      "y": 0,
      "z": 3,
      "name": "Wood_Drywood_Planks"
    },
    {
      "x": 2,
      "y": 4,
      "z": 3,
      "name": "Wood_Deadwood_Ornate"
    },
    {
      "x": 2,
      "y": 0,
      "z": 4,
      "name": "Wood_Drywood_Planks"
    },
    {
      "x": 2,
      "y": 4,
      "z": 4,
      "name": "Wood_Deadwood_Ornate"
    },
    {
      "x": 2,
      "y": 0,
      "z": 5,
      "name": "Wood_Drywood_Planks"
    },
    {
      "x": 2,
      "y": 4,
      "z": 5,
      "name": "Wood_Deadwood_Ornate"
    },
    {
      "x": 2,
      "y": 5,
      "z": 5,
      "name": "Wood_Deadwood_Beam"
    },
    {
      "x": 2,
      "y": 6,
      "z": 5,
      "name": "Wood_Deadwood_Beam"
    },
    {
      "x": 2,
      "y": 0,
      "z": 6,
      "name": "Wood_Drywood_Planks"
    },
    {
      "x": 2,
      "y": 4,
      "z": 6,
      "name": "Wood_Deadwood_Ornate"
    },
    {
      "x": 2,
      "y": 0,
      "z": 7,
      "name": "Wood_Drywood_Planks"
    },
    {
      "x": 2,
      "y": 1,
      "z": 7,
      "name": "Furniture_Human_Ruins_Bookshelf",
      "rotation": 2
    },
    {
      "x": 2,
      "y": 2,
      "z": 7,
      "name": "Furniture_Human_Ruins_Bookshelf",
      "rotation": 2
    },
    {
      "x": 2,
      "y": 3,
      "z": 7,
      "name": "Furniture_Human_Ruins_Bookshelf",
      "rotation": 2
    },
    {
      "x": 2,
      "y": 4,
      "z": 7,
      "name": "Wood_Deadwood_Ornate"
    },
    {
      "x": 2,
      "y": 0,
      "z": 8,
      "name": "Wood_Deadwood_Planks"
    },
    {
      "x": 2,
      "y": 1,
      "z": 8,
      "name": "Wood_Deadwood_Planks"
    },
    {
      "x": 2,
      "y": 2,
      "z": 8,
      "name": "Wood_Deadwood_Planks"
    },
    {
      "x": 2,
      "y": 3,
      "z": 8,
      "name": "Wood_Deadwood_Planks"
    },
    {
      "x": 2,
      "y": 4,
      "z": 8,
      "name": "Wood_Deadwood_Planks"
    },
    {
      "x": 3,
      "y": 0,
      "z": -8,
      "name": "Wood_Deadwood_Planks",
      "rotation": 1
    },
    {
      "x": 3,
      "y": 1,
      "z": -8,
      "name": "Wood_Deadwood_Planks",
      "rotation": 1
    },
    {
      "x": 3,
      "y": 2,
      "z": -8,
      "name": "Wood_Deadwood_Planks",
      "rotation": 1
    },
    {
      "x": 3,
      "y": 3,
      "z": -8,
      "name": "Wood_Deadwood_Planks",
      "rotation": 1
    },
    {
      "x": 3,
      "y": 4,
      "z": -8,
      "name": "Wood_Deadwood_Planks",
      "rotation": 1
    },
    {
      "x": 3,
      "y": 0,
      "z": -7,
      "name": "Wood_Drywood_Planks"
    },
    {
      "x": 3,
      "y": 4,
      "z": -7,
      "name": "Wood_Deadwood_Ornate",
      "rotation": 1
    },
    {
      "x": 3,
      "y": 5,
      "z": -7,
      "name": "Wood_Deadwood_Beam",
      "rotation": 1
    },
    {
      "x": 3,
      "y": 6,
      "z": -7,
      "name": "Wood_Deadwood_Beam",
      "rotation": 1
    },
    {
      "x": 3,
      "y": 0,
      "z": -6,
      "name": "Wood_Drywood_Planks"
    },
    {
      "x": 3,
      "y": 4,
      "z": -6,
      "name": "Wood_Deadwood_Ornate",
      "rotation": 1
    },
    {
      "x": 3,
      "y": 0,
      "z": -5,
      "name": "Wood_Drywood_Planks"
    },
    {
      "x": 3,
      "y": 4,
      "z": -5,
      "name": "Wood_Deadwood_Ornate",
      "rotation": 1
    },
    {
      "x": 3,
      "y": 0,
      "z": -4,
      "name": "Wood_Drywood_Planks"
    },
    {
      "x": 3,
      "y": 4,
      "z": -4,
      "name": "Wood_Deadwood_Ornate",
      "rotation": 1
    },
    {
      "x": 3,
      "y": 0,
      "z": -3,
      "name": "Wood_Drywood_Planks"
    },
    {
      "x": 3,
      "y": 4,
      "z": -3,
      "name": "Wood_Deadwood_Ornate",
      "rotation": 1
    },
    {
      "x": 3,
      "y": 0,
      "z": -2,
      "name": "Wood_Drywood_Planks"
    },
    {
      "x": 3,
      "y": 4,
      "z": -2,
      "name": "Wood_Deadwood_Ornate",
      "rotation": 1
    },
    {
      "x": 3,
      "y": 0,
      "z": -1,
      "name": "Wood_Drywood_Planks"
    },
    {
      "x": 3,
      "y": 1,
      "z": -1,
      "name": "Furniture_Human_Ruins_Desk",
      "filler": 992,
      "rotation": 3
    },
    {
      "x": 3,
      "y": 4,
      "z": -1,
      "name": "Wood_Deadwood_Ornate",
      "rotation": 1
    },
    {
      "x": 3,
      "y": 5,
      "z": -1,
      "name": "Wood_Deadwood_Beam",
      "rotation": 1
    },
    {
      "x": 3,
      "y": 6,
      "z": -1,
      "name": "Wood_Deadwood_Beam",
      "rotation": 1
    },
    {
      "x": 3,
      "y": 0,
      "z": 0,
      "name": "Wood_Drywood_Planks"
    },
    {
      "x": 3,
      "y": 1,
      "z": 0,
      "name": "Furniture_Human_Ruins_Desk",
      "rotation": 3
    },
    {
      "x": 3,
      "y": 4,
      "z": 0,
      "name": "Wood_Deadwood_Planks",
      "rotation": 1
    },
    {
      "x": 3,
      "y": 5,
      "z": 0,
      "name": "Wood_Deadwood_Planks",
      "rotation": 1
    },
    {
      "x": 3,
      "y": 0,
      "z": 1,
      "name": "Wood_Drywood_Planks"
    },
    {
      "x": 3,
      "y": 4,
      "z": 1,
      "name": "Wood_Deadwood_Ornate"
    },
    {
      "x": 3,
      "y": 5,
      "z": 1,
      "name": "*Wood_Deadwood_Fence_State_Definitions_Corner",
      "rotation": 1
    },
    {
      "x": 3,
      "y": 0,
      "z": 2,
      "name": "Wood_Drywood_Planks"
    },
    {
      "x": 3,
      "y": 4,
      "z": 2,
      "name": "Wood_Deadwood_Ornate"
    },
    {
      "x": 3,
      "y": 5,
      "z": 2,
      "name": "Wood_Deadwood_Fence",
      "rotation": 1
    },
    {
      "x": 3,
      "y": 0,
      "z": 3,
      "name": "Wood_Drywood_Planks"
    },
    {
      "x": 3,
      "y": 4,
      "z": 3,
      "name": "Wood_Deadwood_Ornate"
    },
    {
      "x": 3,
      "y": 0,
      "z": 4,
      "name": "Wood_Drywood_Planks"
    },
    {
      "x": 3,
      "y": 4,
      "z": 4,
      "name": "Wood_Deadwood_Planks"
    },
    {
      "x": 3,
      "y": 0,
      "z": 5,
      "name": "Wood_Drywood_Planks"
    },
    {
      "x": 3,
      "y": 4,
      "z": 5,
      "name": "Wood_Deadwood_Ornate"
    },
    {
      "x": 3,
      "y": 0,
      "z": 6,
      "name": "Wood_Drywood_Planks"
    },
    {
      "x": 3,
      "y": 4,
      "z": 6,
      "name": "Wood_Deadwood_Ornate"
    },
    {
      "x": 3,
      "y": 0,
      "z": 7,
      "name": "Wood_Drywood_Planks"
    },
    {
      "x": 3,
      "y": 1,
      "z": 7,
      "name": "Furniture_Human_Ruins_Bookshelf",
      "rotation": 2
    },
    {
      "x": 3,
      "y": 2,
      "z": 7,
      "name": "Furniture_Human_Ruins_Bookshelf",
      "rotation": 2
    },
    {
      "x": 3,
      "y": 3,
      "z": 7,
      "name": "Furniture_Human_Ruins_Bookshelf",
      "rotation": 2
    },
    {
      "x": 3,
      "y": 4,
      "z": 7,
      "name": "Wood_Deadwood_Ornate"
    },
    {
      "x": 3,
      "y": 0,
      "z": 8,
      "name": "Wood_Deadwood_Planks"
    },
    {
      "x": 3,
      "y": 1,
      "z": 8,
      "name": "Wood_Deadwood_Planks"
    },
    {
      "x": 3,
      "y": 2,
      "z": 8,
      "name": "Wood_Deadwood_Planks"
    },
    {
      "x": 3,
      "y": 3,
      "z": 8,
      "name": "Wood_Deadwood_Planks"
    },
    {
      "x": 3,
      "y": 4,
      "z": 8,
      "name": "Wood_Deadwood_Planks"
    },
    {
      "x": 4,
      "y": 0,
      "z": -8,
      "name": "Wood_Deadwood_Planks",
      "rotation": 1
    },
    {
      "x": 4,
      "y": 1,
      "z": -8,
      "name": "*Furniture_Ancient_Door_State_Definitions_CloseDoorIn"
    },
    {
      "x": 4,
      "y": 2,
      "z": -8,
      "name": "*Furniture_Ancient_Door_State_Definitions_CloseDoorIn",
      "filler": 1024
    },
    {
      "x": 4,
      "y": 3,
      "z": -8,
      "name": "Wood_Deadwood_Planks",
      "rotation": 1
    },
    {
      "x": 4,
      "y": 4,
      "z": -8,
      "name": "Wood_Deadwood_Planks",
      "rotation": 1
    },
    {
      "x": 4,
      "y": 0,
      "z": -7,
      "name": "Wood_Drywood_Planks"
    },
    {
      "x": 4,
      "y": 4,
      "z": -7,
      "name": "Wood_Deadwood_Ornate",
      "rotation": 1
    },
    {
      "x": 4,
      "y": 0,
      "z": -6,
      "name": "Wood_Drywood_Planks"
    },
    {
      "x": 4,
      "y": 4,
      "z": -6,
      "name": "Wood_Deadwood_Ornate",
      "rotation": 1
    },
    {
      "x": 4,
      "y": 0,
      "z": -5,
      "name": "Wood_Drywood_Planks"
    },
    {
      "x": 4,
      "y": 4,
      "z": -5,
      "name": "Wood_Deadwood_Ornate",
      "rotation": 1
    },
    {
      "x": 4,
      "y": 0,
      "z": -4,
      "name": "Wood_Drywood_Planks"
    },
    {
      "x": 4,
      "y": 4,
      "z": -4,
      "name": "Wood_Deadwood_Ornate",
      "rotation": 1
    },
    {
      "x": 4,
      "y": 0,
      "z": -3,
      "name": "Wood_Drywood_Planks"
    },
    {
      "x": 4,
      "y": 4,
      "z": -3,
      "name": "Wood_Deadwood_Ornate",
      "rotation": 1
    },
    {
      "x": 4,
      "y": 0,
      "z": -2,
      "name": "Wood_Drywood_Planks"
    },
    {
      "x": 4,
      "y": 4,
      "z": -2,
      "name": "Wood_Deadwood_Ornate",
      "rotation": 1
    },
    {
      "x": 4,
      "y": 0,
      "z": -1,
      "name": "Wood_Drywood_Planks"
    },
    {
      "x": 4,
      "y": 1,
      "z": -1,
      "name": "Furniture_Human_Ruins_Desk",
      "filler": 992,
      "rotation": 3
    },
    {
      "x": 4,
      "y": 4,
      "z": -1,
      "name": "Wood_Deadwood_Ornate",
      "rotation": 1
    },
    {
      "x": 4,
      "y": 0,
      "z": 0,
      "name": "Wood_Drywood_Planks"
    },
    {
      "x": 4,
      "y": 1,
      "z": 0,
      "name": "Furniture_Human_Ruins_Desk",
      "rotation": 3
    },
    {
      "x": 4,
      "y": 4,
      "z": 0,
      "name": "Wood_Deadwood_Planks",
      "rotation": 1
    },
    {
      "x": 4,
      "y": 0,
      "z": 1,
      "name": "Wood_Drywood_Planks"
    },
    {
      "x": 4,
      "y": 4,
      "z": 1,
      "name": "Wood_Deadwood_Ornate"
    },
    {
      "x": 4,
      "y": 5,
      "z": 1,
      "name": "Wood_Deadwood_Fence"
    },
    {
      "x": 4,
      "y": 6,
      "z": 1,
      "name": "Wood_Deadwood_Fence"
    },
    {
      "x": 4,
      "y": 0,
      "z": 2,
      "name": "Wood_Drywood_Planks"
    },
    {
      "x": 4,
      "y": 4,
      "z": 2,
      "name": "Wood_Deadwood_Ornate"
    },
    {
      "x": 4,
      "y": 0,
      "z": 3,
      "name": "Wood_Drywood_Planks"
    },
    {
      "x": 4,
      "y": 4,
      "z": 3,
      "name": "Wood_Deadwood_Ornate"
    },
    {
      "x": 4,
      "y": 0,
      "z": 4,
      "name": "Wood_Drywood_Planks"
    },
    {
      "x": 4,
      "y": 4,
      "z": 4,
      "name": "Wood_Deadwood_Ornate"
    },
    {
      "x": 4,
      "y": 0,
      "z": 5,
      "name": "Wood_Drywood_Planks"
    },
    {
      "x": 4,
      "y": 4,
      "z": 5,
      "name": "Wood_Deadwood_Ornate"
    },
    {
      "x": 4,
      "y": 0,
      "z": 6,
      "name": "Wood_Drywood_Planks"
    },
    {
      "x": 4,
      "y": 1,
      "z": 6,
      "name": "Wood_Deadwood_Planks"
    },
    {
      "x": 4,
      "y": 2,
      "z": 6,
      "name": "D_Wood_Deadwood_Plank_Corner",
      "rotation": 3
    },
    {
      "x": 4,
      "y": 3,
      "z": 6,
      "name": "D_Wood_Deadwood_Plank_Corner",
      "rotation": 3
    },
    {
      "x": 4,
      "y": 4,
      "z": 6,
      "name": "Wood_Deadwood_Planks"
    },
    {
      "x": 4,
      "y": 5,
      "z": 6,
      "name": "Wood_Deadwood_Beam"
    },
    {
      "x": 4,
      "y": 6,
      "z": 6,
      "name": "Wood_Deadwood_Beam"
    },
    {
      "x": 4,
      "y": 0,
      "z": 7,
      "name": "Wood_Drywood_Planks"
    },
    {
      "x": 4,
      "y": 1,
      "z": 7,
      "name": "D_Wood_Deadwood_Door",
      "rotation": 3
    },
    {
      "x": 4,
      "y": 2,
      "z": 7,
      "name": "D_Wood_Deadwood_Door",
      "filler": 1024,
      "rotation": 3
    },
    {
      "x": 4,
      "y": 3,
      "z": 7,
      "name": "Wood_Deadwood_Planks"
    },
    {
      "x": 4,
      "y": 4,
      "z": 7,
      "name": "Wood_Deadwood_Planks"
    },
    {
      "x": 4,
      "y": 0,
      "z": 8,
      "name": "Wood_Deadwood_Planks"
    },
    {
      "x": 4,
      "y": 1,
      "z": 8,
      "name": "Wood_Deadwood_Planks"
    },
    {
      "x": 4,
      "y": 2,
      "z": 8,
      "name": "Wood_Deadwood_Planks"
    },
    {
      "x": 4,
      "y": 3,
      "z": 8,
      "name": "Wood_Deadwood_Planks"
    },
    {
      "x": 4,
      "y": 4,
      "z": 8,
      "name": "Wood_Deadwood_Planks"
    },
    {
      "x": 5,
      "y": 0,
      "z": -8,
      "name": "Wood_Deadwood_Planks",
      "rotation": 1
    },
    {
      "x": 5,
      "y": 1,
      "z": -8,
      "name": "Wood_Deadwood_Planks",
      "rotation": 1
    },
    {
      "x": 5,
      "y": 2,
      "z": -8,
      "name": "Wood_Deadwood_Planks",
      "rotation": 1
    },
    {
      "x": 5,
      "y": 3,
      "z": -8,
      "name": "Wood_Deadwood_Planks",
      "rotation": 1
    },
    {
      "x": 5,
      "y": 4,
      "z": -8,
      "name": "Wood_Deadwood_Planks",
      "rotation": 1
    },
    {
      "x": 5,
      "y": 5,
      "z": -8,
      "name": "Wood_Deadwood_Planks",
      "rotation": 1
    },
    {
      "x": 5,
      "y": 6,
      "z": -8,
      "name": "Wood_Deadwood_Planks",
      "rotation": 1
    },
    {
      "x": 5,
      "y": 0,
      "z": -7,
      "name": "Wood_Drywood_Planks"
    },
    {
      "x": 5,
      "y": 4,
      "z": -7,
      "name": "Wood_Deadwood_Ornate",
      "rotation": 1
    },
    {
      "x": 5,
      "y": 0,
      "z": -6,
      "name": "Wood_Drywood_Planks"
    },
    {
      "x": 5,
      "y": 4,
      "z": -6,
      "name": "Wood_Deadwood_Ornate",
      "rotation": 1
    },
    {
      "x": 5,
      "y": 0,
      "z": -5,
      "name": "Wood_Drywood_Planks"
    },
    {
      "x": 5,
      "y": 4,
      "z": -5,
      "name": "Wood_Deadwood_Ornate",
      "rotation": 1
    },
    {
      "x": 5,
      "y": 5,
      "z": -5,
      "name": "Wood_Deadwood_Beam",
      "rotation": 1
    },
    {
      "x": 5,
      "y": 6,
      "z": -5,
      "name": "Wood_Deadwood_Beam",
      "rotation": 1
    },
    {
      "x": 5,
      "y": 0,
      "z": -4,
      "name": "Wood_Drywood_Planks"
    },
    {
      "x": 5,
      "y": 4,
      "z": -4,
      "name": "Wood_Deadwood_Ornate",
      "rotation": 1
    },
    {
      "x": 5,
      "y": 0,
      "z": -3,
      "name": "Wood_Drywood_Planks"
    },
    {
      "x": 5,
      "y": 4,
      "z": -3,
      "name": "Wood_Deadwood_Ornate",
      "rotation": 1
    },
    {
      "x": 5,
      "y": 0,
      "z": -2,
      "name": "Wood_Drywood_Planks"
    },
    {
      "x": 5,
      "y": 4,
      "z": -2,
      "name": "Wood_Deadwood_Ornate",
      "rotation": 1
    },
    {
      "x": 5,
      "y": 0,
      "z": -1,
      "name": "Wood_Drywood_Planks"
    },
    {
      "x": 5,
      "y": 1,
      "z": -1,
      "name": "Furniture_Human_Ruins_Stool"
    },
    {
      "x": 5,
      "y": 4,
      "z": -1,
      "name": "Wood_Deadwood_Ornate",
      "rotation": 1
    },
    {
      "x": 5,
      "y": 0,
      "z": 0,
      "name": "Wood_Drywood_Planks"
    },
    {
      "x": 5,
      "y": 1,
      "z": 0,
      "name": "Furniture_Human_Ruins_Stool"
    },
    {
      "x": 5,
      "y": 4,
      "z": 0,
      "name": "Wood_Deadwood_Planks",
      "rotation": 1
    },
    {
      "x": 5,
      "y": 0,
      "z": 1,
      "name": "Wood_Drywood_Planks"
    },
    {
      "x": 5,
      "y": 4,
      "z": 1,
      "name": "Wood_Deadwood_Ornate"
    },
    {
      "x": 5,
      "y": 0,
      "z": 2,
      "name": "Wood_Drywood_Planks"
    },
    {
      "x": 5,
      "y": 4,
      "z": 2,
      "name": "Wood_Deadwood_Ornate"
    },
    {
      "x": 5,
      "y": 5,
      "z": 2,
      "name": "Wood_Deadwood_Beam"
    },
    {
      "x": 5,
      "y": 6,
      "z": 2,
      "name": "Wood_Deadwood_Beam"
    },
    {
      "x": 5,
      "y": 0,
      "z": 3,
      "name": "Wood_Drywood_Planks"
    },
    {
      "x": 5,
      "y": 4,
      "z": 3,
      "name": "Wood_Deadwood_Ornate"
    },
    {
      "x": 5,
      "y": 0,
      "z": 4,
      "name": "Wood_Drywood_Planks"
    },
    {
      "x": 5,
      "y": 4,
      "z": 4,
      "name": "Wood_Deadwood_Ornate"
    },
    {
      "x": 5,
      "y": 0,
      "z": 5,
      "name": "Wood_Drywood_Planks"
    },
    {
      "x": 5,
      "y": 2,
      "z": 5,
      "name": "Furniture_Ancient_Shelf",
      "rotation": 2
    },
    {
      "x": 5,
      "y": 4,
      "z": 5,
      "name": "Wood_Deadwood_Ornate"
    },
    {
      "x": 5,
      "y": 0,
      "z": 6,
      "name": "Wood_Drywood_Planks"
    },
    {
      "x": 5,
      "y": 1,
      "z": 6,
      "name": "D_Wood_Deadwood_Plank_Corner",
      "rotation": 3
    },
    {
      "x": 5,
      "y": 2,
      "z": 6,
      "name": "D_Wood_Deadwood_Plank_Corner",
      "rotation": 3
    },
    {
      "x": 5,
      "y": 3,
      "z": 6,
      "name": "Wood_Deadwood_Planks"
    },
    {
      "x": 5,
      "y": 4,
      "z": 6,
      "name": "Wood_Deadwood_Planks"
    },
    {
      "x": 5,
      "y": 0,
      "z": 7,
      "name": "Wood_Deadwood_Planks"
    },
    {
      "x": 5,
      "y": 0,
      "z": 8,
      "name": "Wood_Deadwood_Planks"
    },
    {
      "x": 6,
      "y": 0,
      "z": -8,
      "name": "Wood_Deadwood_Planks",
      "rotation": 1
    },
    {
      "x": 6,
      "y": 1,
      "z": -8,
      "name": "Wood_Deadwood_Planks",
      "rotation": 1
    },
    {
      "x": 6,
      "y": 2,
      "z": -8,
      "name": "Wood_Deadwood_Planks",
      "rotation": 1
    },
    {
      "x": 6,
      "y": 3,
      "z": -8,
      "name": "Wood_Deadwood_Planks",
      "rotation": 1
    },
    {
      "x": 6,
      "y": 4,
      "z": -8,
      "name": "Wood_Deadwood_Planks",
      "rotation": 1
    },
    {
      "x": 6,
      "y": 5,
      "z": -8,
      "name": "Wood_Deadwood_Planks",
      "rotation": 1
    },
    {
      "x": 6,
      "y": 0,
      "z": -7,
      "name": "Wood_Drywood_Planks"
    },
    {
      "x": 6,
      "y": 1,
      "z": -7,
      "name": "Furniture_Ancient_Wardrobe",
      "filler": 31
    },
    {
      "x": 6,
      "y": 2,
      "z": -7,
      "name": "Furniture_Ancient_Wardrobe",
      "filler": 1055
    },
    {
      "x": 6,
      "y": 4,
      "z": -7,
      "name": "Wood_Deadwood_Ornate",
      "rotation": 1
    },
    {
      "x": 6,
      "y": 0,
      "z": -6,
      "name": "Wood_Drywood_Planks"
    },
    {
      "x": 6,
      "y": 4,
      "z": -6,
      "name": "Wood_Deadwood_Ornate",
      "rotation": 1
    },
    {
      "x": 6,
      "y": 0,
      "z": -5,
      "name": "Wood_Drywood_Planks"
    },
    {
      "x": 6,
      "y": 4,
      "z": -5,
      "name": "Wood_Deadwood_Ornate",
      "rotation": 1
    },
    {
      "x": 6,
      "y": 0,
      "z": -4,
      "name": "Wood_Drywood_Planks"
    },
    {
      "x": 6,
      "y": 4,
      "z": -4,
      "name": "Wood_Deadwood_Ornate",
      "rotation": 1
    },
    {
      "x": 6,
      "y": 0,
      "z": -3,
      "name": "Wood_Drywood_Planks"
    },
    {
      "x": 6,
      "y": 4,
      "z": -3,
      "name": "Wood_Deadwood_Ornate",
      "rotation": 1
    },
    {
      "x": 6,
      "y": 0,
      "z": -2,
      "name": "Wood_Drywood_Planks"
    },
    {
      "x": 6,
      "y": 4,
      "z": -2,
      "name": "Wood_Deadwood_Planks",
      "rotation": 1
    },
    {
      "x": 6,
      "y": 5,
      "z": -2,
      "name": "Wood_Deadwood_Planks",
      "rotation": 1
    },
    {
      "x": 6,
      "y": 0,
      "z": -1,
      "name": "Wood_Drywood_Planks"
    },
    {
      "x": 6,
      "y": 4,
      "z": -1,
      "name": "Wood_Deadwood_Planks",
      "rotation": 1
    },
    {
      "x": 6,
      "y": 5,
      "z": -1,
      "name": "Wood_Deadwood_Planks",
      "rotation": 1
    },
    {
      "x": 6,
      "y": 0,
      "z": 0,
      "name": "Wood_Drywood_Planks"
    },
    {
      "x": 6,
      "y": 4,
      "z": 0,
      "name": "Wood_Deadwood_Planks",
      "rotation": 1
    },
    {
      "x": 6,
      "y": 0,
      "z": 1,
      "name": "Wood_Drywood_Planks"
    },
    {
      "x": 6,
      "y": 4,
      "z": 1,
      "name": "Wood_Deadwood_Ornate"
    },
    {
      "x": 6,
      "y": 0,
      "z": 2,
      "name": "Wood_Drywood_Planks"
    },
    {
      "x": 6,
      "y": 4,
      "z": 2,
      "name": "Wood_Deadwood_Ornate"
    },
    {
      "x": 6,
      "y": 0,
      "z": 3,
      "name": "Wood_Drywood_Planks"
    },
    {
      "x": 6,
      "y": 4,
      "z": 3,
      "name": "Wood_Deadwood_Ornate"
    },
    {
      "x": 6,
      "y": 5,
      "z": 3,
      "name": "Wood_Deadwood_Planks_Half",
      "rotation": 7
    },
    {
      "x": 6,
      "y": 6,
      "z": 3,
      "name": "Wood_Deadwood_Stairs",
      "rotation": 9
    },
    {
      "x": 6,
      "y": 0,
      "z": 4,
      "name": "Wood_Drywood_Planks"
    },
    {
      "x": 6,
      "y": 4,
      "z": 4,
      "name": "Wood_Deadwood_Ornate"
    },
    {
      "x": 6,
      "y": 0,
      "z": 5,
      "name": "Wood_Drywood_Planks"
    },
    {
      "x": 6,
      "y": 2,
      "z": 5,
      "name": "Furniture_Ancient_Shelf",
      "rotation": 2
    },
    {
      "x": 6,
      "y": 4,
      "z": 5,
      "name": "Wood_Deadwood_Ornate"
    },
    {
      "x": 6,
      "y": 5,
      "z": 5,
      "name": "Wood_Deadwood_Beam"
    },
    {
      "x": 6,
      "y": 6,
      "z": 5,
      "name": "Wood_Deadwood_Beam"
    },
    {
      "x": 6,
      "y": 0,
      "z": 6,
      "name": "Wood_Drywood_Planks"
    },
    {
      "x": 6,
      "y": 1,
      "z": 6,
      "name": "Wood_Deadwood_Planks"
    },
    {
      "x": 6,
      "y": 2,
      "z": 6,
      "name": "D_Wood_Deadwood_Plank_Corner",
      "rotation": 3
    },
    {
      "x": 6,
      "y": 3,
      "z": 6,
      "name": "Wood_Deadwood_Planks"
    },
    {
      "x": 6,
      "y": 4,
      "z": 6,
      "name": "Wood_Deadwood_Planks"
    },
    {
      "x": 6,
      "y": 0,
      "z": 7,
      "name": "Wood_Deadwood_Planks"
    },
    {
      "x": 6,
      "y": 0,
      "z": 8,
      "name": "Wood_Deadwood_Planks"
    },
    {
      "x": 7,
      "y": 0,
      "z": -8,
      "name": "Wood_Deadwood_Planks",
      "rotation": 1
    },
    {
      "x": 7,
      "y": 1,
      "z": -8,
      "name": "Wood_Deadwood_Planks",
      "rotation": 1
    },
    {
      "x": 7,
      "y": 2,
      "z": -8,
      "name": "Wood_Deadwood_Planks",
      "rotation": 1
    },
    {
      "x": 7,
      "y": 3,
      "z": -8,
      "name": "Wood_Deadwood_Planks",
      "rotation": 1
    },
    {
      "x": 7,
      "y": 4,
      "z": -8,
      "name": "Wood_Deadwood_Planks",
      "rotation": 1
    },
    {
      "x": 7,
      "y": 5,
      "z": -8,
      "name": "Wood_Deadwood_Planks",
      "rotation": 1
    },
    {
      "x": 7,
      "y": 0,
      "z": -7,
      "name": "Wood_Drywood_Planks"
    },
    {
      "x": 7,
      "y": 1,
      "z": -7,
      "name": "Furniture_Ancient_Wardrobe"
    },
    {
      "x": 7,
      "y": 2,
      "z": -7,
      "name": "Furniture_Ancient_Wardrobe",
      "filler": 1024
    },
    {
      "x": 7,
      "y": 4,
      "z": -7,
      "name": "Wood_Deadwood_Ornate",
      "rotation": 1
    },
    {
      "x": 7,
      "y": 0,
      "z": -6,
      "name": "Wood_Drywood_Planks"
    },
    {
      "x": 7,
      "y": 4,
      "z": -6,
      "name": "Wood_Deadwood_Ornate",
      "rotation": 1
    },
    {
      "x": 7,
      "y": 0,
      "z": -5,
      "name": "Wood_Drywood_Planks"
    },
    {
      "x": 7,
      "y": 2,
      "z": -5,
      "name": "Furniture_Ancient_Shelf",
      "rotation": 3
    },
    {
      "x": 7,
      "y": 4,
      "z": -5,
      "name": "Wood_Deadwood_Ornate",
      "rotation": 1
    },
    {
      "x": 7,
      "y": 0,
      "z": -4,
      "name": "Wood_Drywood_Planks"
    },
    {
      "x": 7,
      "y": 2,
      "z": -4,
      "name": "Furniture_Ancient_Shelf",
      "rotation": 3
    },
    {
      "x": 7,
      "y": 4,
      "z": -4,
      "name": "Wood_Deadwood_Ornate",
      "rotation": 1
    },
    {
      "x": 7,
      "y": 5,
      "z": -4,
      "name": "Wood_Deadwood_Beam",
      "rotation": 1
    },
    {
      "x": 7,
      "y": 6,
      "z": -4,
      "name": "Wood_Deadwood_Beam",
      "rotation": 1
    },
    {
      "x": 7,
      "y": 0,
      "z": -3,
      "name": "Wood_Drywood_Planks"
    },
    {
      "x": 7,
      "y": 2,
      "z": -3,
      "name": "Furniture_Ancient_Shelf",
      "rotation": 3
    },
    {
      "x": 7,
      "y": 4,
      "z": -3,
      "name": "Wood_Deadwood_Ornate",
      "rotation": 1
    },
    {
      "x": 7,
      "y": 0,
      "z": -2,
      "name": "Wood_Drywood_Planks"
    },
    {
      "x": 7,
      "y": 4,
      "z": -2,
      "name": "Wood_Deadwood_Planks",
      "rotation": 1
    },
    {
      "x": 7,
      "y": 5,
      "z": -2,
      "name": "Wood_Deadwood_Planks",
      "rotation": 1
    },
    {
      "x": 7,
      "y": 0,
      "z": -1,
      "name": "Wood_Drywood_Planks"
    },
    {
      "x": 7,
      "y": 4,
      "z": -1,
      "name": "Wood_Deadwood_Planks"
    },
    {
      "x": 7,
      "y": 0,
      "z": 0,
      "name": "Wood_Drywood_Planks"
    },
    {
      "x": 7,
      "y": 2,
      "z": 0,
      "name": "Furniture_Ancient_Shelf",
      "rotation": 3
    },
    {
      "x": 7,
      "y": 4,
      "z": 0,
      "name": "Wood_Deadwood_Planks"
    },
    {
      "x": 7,
      "y": 0,
      "z": 1,
      "name": "Wood_Drywood_Planks"
    },
    {
      "x": 7,
      "y": 2,
      "z": 1,
      "name": "Furniture_Ancient_Shelf",
      "rotation": 3
    },
    {
      "x": 7,
      "y": 4,
      "z": 1,
      "name": "Wood_Deadwood_Ornate"
    },
    {
      "x": 7,
      "y": 0,
      "z": 2,
      "name": "Wood_Drywood_Planks"
    },
    {
      "x": 7,
      "y": 2,
      "z": 2,
      "name": "Furniture_Ancient_Shelf",
      "rotation": 3
    },
    {
      "x": 7,
      "y": 4,
      "z": 2,
      "name": "Wood_Deadwood_Ornate"
    },
    {
      "x": 7,
      "y": 5,
      "z": 2,
      "name": "Wood_Deadwood_Planks_Half",
      "rotation": 6
    },
    {
      "x": 7,
      "y": 6,
      "z": 2,
      "name": "Wood_Deadwood_Stairs",
      "rotation": 8
    },
    {
      "x": 7,
      "y": 0,
      "z": 3,
      "name": "Wood_Drywood_Planks"
    },
    {
      "x": 7,
      "y": 4,
      "z": 3,
      "name": "Wood_Deadwood_Ornate"
    },
    {
      "x": 7,
      "y": 5,
      "z": 3,
      "name": "Wood_Deadwood_Planks"
    },
    {
      "x": 7,
      "y": 6,
      "z": 3,
      "name": "Wood_Deadwood_Planks"
    },
    {
      "x": 7,
      "y": 0,
      "z": 4,
      "name": "Wood_Drywood_Planks"
    },
    {
      "x": 7,
      "y": 4,
      "z": 4,
      "name": "Wood_Deadwood_Ornate"
    },
    {
      "x": 7,
      "y": 5,
      "z": 4,
      "name": "Wood_Deadwood_Planks_Half",
      "rotation": 4
    },
    {
      "x": 7,
      "y": 6,
      "z": 4,
      "name": "Wood_Deadwood_Stairs",
      "rotation": 10
    },
    {
      "x": 7,
      "y": 0,
      "z": 5,
      "name": "Wood_Drywood_Planks"
    },
    {
      "x": 7,
      "y": 4,
      "z": 5,
      "name": "Wood_Deadwood_Ornate"
    },
    {
      "x": 7,
      "y": 0,
      "z": 6,
      "name": "Wood_Drywood_Planks"
    },
    {
      "x": 7,
      "y": 1,
      "z": 6,
      "name": "Wood_Deadwood_Planks"
    },
    {
      "x": 7,
      "y": 2,
      "z": 6,
      "name": "D_Wood_Deadwood_Plank_Corner",
      "rotation": 2
    },
    {
      "x": 7,
      "y": 3,
      "z": 6,
      "name": "Wood_Deadwood_Planks"
    },
    {
      "x": 7,
      "y": 4,
      "z": 6,
      "name": "Wood_Deadwood_Planks"
    },
    {
      "x": 7,
      "y": 0,
      "z": 7,
      "name": "Wood_Deadwood_Planks"
    },
    {
      "x": 7,
      "y": 0,
      "z": 8,
      "name": "Wood_Deadwood_Planks"
    },
    {
      "x": 8,
      "y": 0,
      "z": -8,
      "name": "Wood_Deadwood_Planks",
      "rotation": 1
    },
    {
      "x": 8,
      "y": 1,
      "z": -8,
      "name": "Wood_Deadwood_Planks",
      "rotation": 1
    },
    {
      "x": 8,
      "y": 2,
      "z": -8,
      "name": "Wood_Deadwood_Planks",
      "rotation": 1
    },
    {
      "x": 8,
      "y": 3,
      "z": -8,
      "name": "Wood_Deadwood_Planks",
      "rotation": 1
    },
    {
      "x": 8,
      "y": 4,
      "z": -8,
      "name": "Wood_Deadwood_Planks",
      "rotation": 1
    },
    {
      "x": 8,
      "y": 0,
      "z": -7,
      "name": "Wood_Deadwood_Planks",
      "rotation": 1
    },
    {
      "x": 8,
      "y": 1,
      "z": -7,
      "name": "Wood_Deadwood_Planks",
      "rotation": 1
    },
    {
      "x": 8,
      "y": 2,
      "z": -7,
      "name": "Wood_Deadwood_Planks",
      "rotation": 1
    },
    {
      "x": 8,
      "y": 3,
      "z": -7,
      "name": "Wood_Deadwood_Planks",
      "rotation": 1
    },
    {
      "x": 8,
      "y": 4,
      "z": -7,
      "name": "Wood_Deadwood_Planks",
      "rotation": 1
    },
    {
      "x": 8,
      "y": 0,
      "z": -6,
      "name": "Wood_Deadwood_Planks",
      "rotation": 1
    },
    {
      "x": 8,
      "y": 1,
      "z": -6,
      "name": "Wood_Deadwood_Planks",
      "rotation": 1
    },
    {
      "x": 8,
      "y": 2,
      "z": -6,
      "name": "Wood_Deadwood_Planks",
      "rotation": 1
    },
    {
      "x": 8,
      "y": 3,
      "z": -6,
      "name": "Wood_Deadwood_Planks",
      "rotation": 1
    },
    {
      "x": 8,
      "y": 4,
      "z": -6,
      "name": "Wood_Deadwood_Planks",
      "rotation": 1
    },
    {
      "x": 8,
      "y": 0,
      "z": -5,
      "name": "Wood_Deadwood_Planks",
      "rotation": 1
    },
    {
      "x": 8,
      "y": 1,
      "z": -5,
      "name": "Wood_Deadwood_Planks",
      "rotation": 1
    },
    {
      "x": 8,
      "y": 2,
      "z": -5,
      "name": "Wood_Deadwood_Planks",
      "rotation": 1
    },
    {
      "x": 8,
      "y": 3,
      "z": -5,
      "name": "Wood_Deadwood_Planks",
      "rotation": 1
    },
    {
      "x": 8,
      "y": 4,
      "z": -5,
      "name": "Wood_Deadwood_Planks",
      "rotation": 1
    },
    {
      "x": 8,
      "y": 0,
      "z": -4,
      "name": "Wood_Deadwood_Planks",
      "rotation": 1
    },
    {
      "x": 8,
      "y": 1,
      "z": -4,
      "name": "Wood_Deadwood_Planks",
      "rotation": 1
    },
    {
      "x": 8,
      "y": 2,
      "z": -4,
      "name": "Wood_Deadwood_Planks",
      "rotation": 1
    },
    {
      "x": 8,
      "y": 3,
      "z": -4,
      "name": "Wood_Deadwood_Planks",
      "rotation": 1
    },
    {
      "x": 8,
      "y": 4,
      "z": -4,
      "name": "Wood_Deadwood_Planks",
      "rotation": 1
    },
    {
      "x": 8,
      "y": 0,
      "z": -3,
      "name": "Wood_Deadwood_Planks",
      "rotation": 1
    },
    {
      "x": 8,
      "y": 1,
      "z": -3,
      "name": "Wood_Deadwood_Planks",
      "rotation": 1
    },
    {
      "x": 8,
      "y": 2,
      "z": -3,
      "name": "Wood_Deadwood_Planks",
      "rotation": 1
    },
    {
      "x": 8,
      "y": 3,
      "z": -3,
      "name": "Wood_Deadwood_Planks",
      "rotation": 1
    },
    {
      "x": 8,
      "y": 4,
      "z": -3,
      "name": "Wood_Deadwood_Planks",
      "rotation": 1
    },
    {
      "x": 8,
      "y": 0,
      "z": -2,
      "name": "Wood_Deadwood_Planks",
      "rotation": 1
    },
    {
      "x": 8,
      "y": 1,
      "z": -2,
      "name": "Wood_Deadwood_Planks",
      "rotation": 1
    },
    {
      "x": 8,
      "y": 2,
      "z": -2,
      "name": "Wood_Deadwood_Planks",
      "rotation": 1
    },
    {
      "x": 8,
      "y": 3,
      "z": -2,
      "name": "Wood_Deadwood_Planks",
      "rotation": 1
    },
    {
      "x": 8,
      "y": 4,
      "z": -2,
      "name": "Wood_Deadwood_Planks",
      "rotation": 1
    },
    {
      "x": 8,
      "y": 0,
      "z": -1,
      "name": "Wood_Deadwood_Planks",
      "rotation": 1
    },
    {
      "x": 8,
      "y": 1,
      "z": -1,
      "name": "Wood_Deadwood_Planks"
    },
    {
      "x": 8,
      "y": 2,
      "z": -1,
      "name": "Wood_Deadwood_Planks"
    },
    {
      "x": 8,
      "y": 3,
      "z": -1,
      "name": "Wood_Deadwood_Planks"
    },
    {
      "x": 8,
      "y": 4,
      "z": -1,
      "name": "Wood_Deadwood_Planks"
    },
    {
      "x": 8,
      "y": 0,
      "z": 0,
      "name": "Wood_Deadwood_Planks",
      "rotation": 1
    },
    {
      "x": 8,
      "y": 1,
      "z": 0,
      "name": "Wood_Deadwood_Planks"
    },
    {
      "x": 8,
      "y": 2,
      "z": 0,
      "name": "Wood_Deadwood_Planks"
    },
    {
      "x": 8,
      "y": 3,
      "z": 0,
      "name": "Wood_Deadwood_Planks"
    },
    {
      "x": 8,
      "y": 4,
      "z": 0,
      "name": "Wood_Deadwood_Planks"
    },
    {
      "x": 8,
      "y": 0,
      "z": 1,
      "name": "Wood_Deadwood_Planks"
    },
    {
      "x": 8,
      "y": 1,
      "z": 1,
      "name": "Wood_Deadwood_Planks"
    },
    {
      "x": 8,
      "y": 2,
      "z": 1,
      "name": "Wood_Deadwood_Planks"
    },
    {
      "x": 8,
      "y": 3,
      "z": 1,
      "name": "Wood_Deadwood_Planks"
    },
    {
      "x": 8,
      "y": 4,
      "z": 1,
      "name": "Wood_Deadwood_Planks"
    },
    {
      "x": 8,
      "y": 0,
      "z": 2,
      "name": "Wood_Deadwood_Planks"
    },
    {
      "x": 8,
      "y": 1,
      "z": 2,
      "name": "Wood_Deadwood_Planks"
    },
    {
      "x": 8,
      "y": 2,
      "z": 2,
      "name": "Wood_Deadwood_Planks"
    },
    {
      "x": 8,
      "y": 3,
      "z": 2,
      "name": "Wood_Deadwood_Planks"
    },
    {
      "x": 8,
      "y": 4,
      "z": 2,
      "name": "Wood_Deadwood_Planks"
    },
    {
      "x": 8,
      "y": 0,
      "z": 3,
      "name": "Wood_Deadwood_Planks"
    },
    {
      "x": 8,
      "y": 1,
      "z": 3,
      "name": "Wood_Deadwood_Planks"
    },
    {
      "x": 8,
      "y": 2,
      "z": 3,
      "name": "Wood_Deadwood_Planks"
    },
    {
      "x": 8,
      "y": 3,
      "z": 3,
      "name": "Wood_Deadwood_Planks"
    },
    {
      "x": 8,
      "y": 4,
      "z": 3,
      "name": "Wood_Deadwood_Planks"
    },
    {
      "x": 8,
      "y": 5,
      "z": 3,
      "name": "Wood_Deadwood_Planks_Half",
      "rotation": 5
    },
    {
      "x": 8,
      "y": 6,
      "z": 3,
      "name": "Wood_Deadwood_Stairs",
      "rotation": 11
    },
    {
      "x": 8,
      "y": 0,
      "z": 4,
      "name": "Wood_Deadwood_Planks"
    },
    {
      "x": 8,
      "y": 1,
      "z": 4,
      "name": "*Furniture_Ancient_Door_State_Definitions_CloseDoorOut",
      "rotation": 3
    },
    {
      "x": 8,
      "y": 2,
      "z": 4,
      "name": "*Furniture_Ancient_Door_State_Definitions_CloseDoorOut",
      "filler": 1024,
      "rotation": 3
    },
    {
      "x": 8,
      "y": 3,
      "z": 4,
      "name": "Wood_Deadwood_Planks"
    },
    {
      "x": 8,
      "y": 4,
      "z": 4,
      "name": "Wood_Deadwood_Planks"
    },
    {
      "x": 8,
      "y": 0,
      "z": 5,
      "name": "Wood_Deadwood_Planks"
    },
    {
      "x": 8,
      "y": 1,
      "z": 5,
      "name": "Wood_Deadwood_Planks"
    },
    {
      "x": 8,
      "y": 2,
      "z": 5,
      "name": "Wood_Deadwood_Planks"
    },
    {
      "x": 8,
      "y": 3,
      "z": 5,
      "name": "Wood_Deadwood_Planks"
    },
    {
      "x": 8,
      "y": 4,
      "z": 5,
      "name": "Wood_Deadwood_Planks"
    },
    {
      "x": 8,
      "y": 0,
      "z": 6,
      "name": "Wood_Deadwood_Planks"
    },
    {
      "x": 8,
      "y": 1,
      "z": 6,
      "name": "Wood_Deadwood_Planks"
    },
    {
      "x": 8,
