{
  "version": 8,
  "blockIdVersion": 11,
  "anchorX": 0,
  "anchorY": 0,
  "anchorZ": 0,
  "blocks": [
    {
      "x": -27,
      "y": 0,
      "z": -25,
      "name": "Rock_Basalt_Brick_Smooth"
    },
    {
      "x": -27,
      "y": 1,
      "z": -25,
      "name": "Rock_Basalt_Brick_Smooth"
    },
    {
      "x": -27,
      "y": 2,
      "z": -25,
      "name": "Rock_Basalt_Brick_Smooth"
    },
    {
      "x": -27,
      "y": 3,
      "z": -25,
      "name": "Rock_Basalt_Brick_Smooth"
    },
    {
      "x": -27,
      "y": 4,
      "z": -25,
      "name": "Rock_Basalt_Brick_Decorative"
    },
    {
      "x": -27,
      "y": 5,
      "z": -25,
      "name": "Rock_Basalt_Brick_Smooth"
    },
    {
      "x": -27,
      "y": 6,
      "z": -25,
      "name": "Rock_Basalt_Brick_Smooth"
    },
    {
      "x": -27,
      "y": 0,
      "z": -24,
      "name": "Rock_Basalt_Brick_Smooth"
    },
    {
      "x": -27,
      "y": 1,
      "z": -24,
      "name": "Rock_Basalt_Brick_Smooth"
    },
    {
      "x": -27,
      "y": 2,
      "z": -24,
      "name": "Rock_Basalt_Brick_Smooth"
    },
    {
      "x": -27,
      "y": 3,
      "z": -24,
      "name": "Rock_Basalt_Brick_Smooth"
    },
    {
      "x": -27,
      "y": 4,
      "z": -24,
      "name": "Rock_Basalt_Brick_Ornate"
    },
    {
      "x": -27,
      "y": 5,
      "z": -24,
      "name": "Rock_Basalt_Brick_Smooth"
    },
    {
      "x": -27,
      "y": 6,
      "z": -24,
      "name": "Rock_Basalt_Brick_Smooth"
    },
    {
      "x": -27,
      "y": 0,
      "z": -23,
      "name": "Rock_Basalt_Brick_Smooth"
    },
    {
      "x": -27,
      "y": 1,
      "z": -23,
      "name": "Rock_Basalt_Brick_Smooth"
    },
    {
      "x": -27,
      "y": 2,
      "z": -23,
      "name": "Rock_Basalt_Brick_Smooth"
    },
    {
      "x": -27,
      "y": 3,
      "z": -23,
      "name": "Rock_Basalt_Brick_Smooth"
    },
    {
      "x": -27,
      "y": 4,
      "z": -23,
      "name": "Rock_Basalt_Brick_Decorative"
    },
    {
      "x": -27,
      "y": 5,
      "z": -23,
      "name": "Rock_Basalt_Brick_Smooth"
    },
    {
      "x": -27,
      "y": 6,
      "z": -23,
      "name": "Rock_Basalt_Brick_Smooth"
    },
    {
      "x": -27,
      "y": 0,
      "z": -9,
      "name": "Rock_Basalt_Brick_Smooth"
    },
    {
      "x": -27,
      "y": 1,
      "z": -9,
      "name": "Rock_Basalt_Brick_Smooth"
    },
    {
      "x": -27,
      "y": 2,
      "z": -9,
      "name": "Rock_Basalt_Brick_Smooth"
    },
    {
      "x": -27,
      "y": 3,
      "z": -9,
      "name": "Rock_Basalt_Brick_Smooth"
    },
    {
      "x": -27,
      "y": 4,
      "z": -9,
      "name": "Rock_Basalt_Brick_Decorative"
    },
    {
      "x": -27,
      "y": 5,
      "z": -9,
      "name": "Rock_Basalt_Brick_Smooth"
    },
    {
      "x": -27,
      "y": 6,
      "z": -9,
      "name": "Rock_Basalt_Brick_Smooth"
    },
    {
      "x": -27,
      "y": 0,
      "z": -8,
      "name": "Rock_Basalt_Brick_Smooth"
    },
    {
      "x": -27,
      "y": 1,
      "z": -8,
      "name": "Rock_Basalt_Brick_Smooth"
    },
    {
      "x": -27,
      "y": 2,
      "z": -8,
      "name": "Rock_Basalt_Brick_Smooth"
    },
    {
      "x": -27,
      "y": 3,
      "z": -8,
      "name": "Rock_Basalt_Brick_Smooth"
    },
    {
      "x": -27,
      "y": 4,
      "z": -8,
      "name": "Rock_Basalt_Brick_Ornate"
    },
    {
      "x": -27,
      "y": 5,
      "z": -8,
      "name": "Rock_Basalt_Brick_Smooth"
    },
    {
      "x": -27,
      "y": 6,
      "z": -8,
      "name": "Rock_Basalt_Brick_Smooth"
    },
    {
      "x": -27,
      "y": 0,
      "z": -7,
      "name": "Rock_Basalt_Brick_Smooth"
    },
    {
      "x": -27,
      "y": 1,
      "z": -7,
      "name": "Rock_Basalt_Brick_Smooth"
    },
    {
      "x": -27,
      "y": 2,
      "z": -7,
      "name": "Rock_Basalt_Brick_Smooth"
    },
    {
      "x": -27,
      "y": 3,
      "z": -7,
      "name": "Rock_Basalt_Brick_Smooth"
    },
    {
      "x": -27,
      "y": 4,
      "z": -7,
      "name": "Rock_Basalt_Brick_Decorative"
    },
    {
      "x": -27,
      "y": 5,
      "z": -7,
      "name": "Rock_Basalt_Brick_Smooth"
    },
    {
      "x": -27,
      "y": 6,
      "z": -7,
      "name": "Rock_Basalt_Brick_Smooth"
    },
    {
      "x": -27,
      "y": 0,
      "z": 7,
      "name": "Rock_Basalt_Brick_Smooth"
    },
    {
      "x": -27,
      "y": 1,
      "z": 7,
      "name": "Rock_Basalt_Brick_Smooth"
    },
    {
      "x": -27,
      "y": 2,
      "z": 7,
      "name": "Rock_Basalt_Brick_Smooth"
    },
    {
      "x": -27,
      "y": 3,
      "z": 7,
      "name": "Rock_Basalt_Brick_Smooth"
    },
    {
      "x": -27,
      "y": 4,
      "z": 7,
      "name": "Rock_Basalt_Brick_Decorative"
    },
    {
      "x": -27,
      "y": 5,
      "z": 7,
      "name": "Rock_Basalt_Brick_Smooth"
    },
    {
      "x": -27,
      "y": 6,
      "z": 7,
      "name": "Rock_Basalt_Brick_Smooth"
    },
    {
      "x": -27,
      "y": 0,
      "z": 8,
      "name": "Rock_Basalt_Brick_Smooth"
    },
    {
      "x": -27,
      "y": 1,
      "z": 8,
      "name": "Rock_Basalt_Brick_Smooth"
    },
    {
      "x": -27,
      "y": 2,
      "z": 8,
      "name": "Rock_Basalt_Brick_Smooth"
    },
    {
      "x": -27,
      "y": 3,
      "z": 8,
      "name": "Rock_Basalt_Brick_Smooth"
    },
    {
      "x": -27,
      "y": 4,
      "z": 8,
      "name": "Rock_Basalt_Brick_Ornate"
    },
    {
      "x": -27,
      "y": 5,
      "z": 8,
      "name": "Rock_Basalt_Brick_Smooth"
    },
    {
      "x": -27,
      "y": 6,
      "z": 8,
      "name": "Rock_Basalt_Brick_Smooth"
    },
    {
      "x": -27,
      "y": 0,
      "z": 9,
      "name": "Rock_Basalt_Brick_Smooth"
    },
    {
      "x": -27,
      "y": 1,
      "z": 9,
      "name": "Rock_Basalt_Brick_Smooth"
    },
    {
      "x": -27,
      "y": 2,
      "z": 9,
      "name": "Rock_Basalt_Brick_Smooth"
    },
    {
      "x": -27,
      "y": 3,
      "z": 9,
      "name": "Rock_Basalt_Brick_Smooth"
    },
    {
      "x": -27,
      "y": 4,
      "z": 9,
      "name": "Rock_Basalt_Brick_Decorative"
    },
    {
      "x": -27,
      "y": 5,
      "z": 9,
      "name": "Rock_Basalt_Brick_Smooth"
    },
    {
      "x": -27,
      "y": 6,
      "z": 9,
      "name": "Rock_Basalt_Brick_Smooth"
    },
    {
      "x": -27,
      "y": 0,
      "z": 23,
      "name": "Rock_Basalt_Brick_Smooth"
    },
    {
      "x": -27,
      "y": 1,
      "z": 23,
      "name": "Rock_Basalt_Brick_Smooth"
    },
    {
      "x": -27,
      "y": 2,
      "z": 23,
      "name": "Rock_Basalt_Brick_Smooth"
    },
    {
      "x": -27,
      "y": 3,
      "z": 23,
      "name": "Rock_Basalt_Brick_Smooth"
    },
    {
      "x": -27,
      "y": 4,
      "z": 23,
      "name": "Rock_Basalt_Brick_Decorative"
    },
    {
      "x": -27,
      "y": 5,
      "z": 23,
      "name": "Rock_Basalt_Brick_Smooth"
    },
    {
      "x": -27,
      "y": 6,
      "z": 23,
      "name": "Rock_Basalt_Brick_Smooth"
    },
    {
      "x": -27,
      "y": 0,
      "z": 24,
      "name": "Rock_Basalt_Brick_Smooth"
    },
    {
      "x": -27,
      "y": 1,
      "z": 24,
      "name": "Rock_Basalt_Brick_Smooth"
    },
    {
      "x": -27,
      "y": 2,
      "z": 24,
      "name": "Rock_Basalt_Brick_Smooth"
    },
    {
      "x": -27,
      "y": 3,
      "z": 24,
      "name": "Rock_Basalt_Brick_Smooth"
    },
    {
      "x": -27,
      "y": 4,
      "z": 24,
      "name": "Rock_Basalt_Brick_Ornate"
    },
    {
      "x": -27,
      "y": 5,
      "z": 24,
      "name": "Rock_Basalt_Brick_Smooth"
    },
    {
      "x": -27,
      "y": 6,
      "z": 24,
      "name": "Rock_Basalt_Brick_Smooth"
    },
    {
      "x": -27,
      "y": 0,
      "z": 25,
      "name": "Rock_Basalt_Brick_Smooth"
    },
    {
      "x": -27,
      "y": 1,
      "z": 25,
      "name": "Rock_Basalt_Brick_Smooth"
    },
    {
      "x": -27,
      "y": 2,
      "z": 25,
      "name": "Rock_Basalt_Brick_Smooth"
    },
    {
      "x": -27,
      "y": 3,
      "z": 25,
      "name": "Rock_Basalt_Brick_Smooth"
    },
    {
      "x": -27,
      "y": 4,
      "z": 25,
      "name": "Rock_Basalt_Brick_Decorative"
    },
    {
      "x": -27,
      "y": 5,
      "z": 25,
      "name": "Rock_Basalt_Brick_Smooth"
    },
    {
      "x": -27,
      "y": 6,
      "z": 25,
      "name": "Rock_Basalt_Brick_Smooth"
    },
    {
      "x": -26,
      "y": 0,
      "z": -26,
      "name": "Rock_Basalt_Brick_Smooth"
    },
    {
      "x": -26,
      "y": 1,
      "z": -26,
      "name": "Rock_Basalt_Brick_Smooth"
    },
    {
      "x": -26,
      "y": 2,
      "z": -26,
      "name": "Rock_Basalt_Brick_Smooth"
    },
    {
      "x": -26,
      "y": 3,
      "z": -26,
      "name": "Rock_Basalt_Brick_Smooth"
    },
    {
      "x": -26,
      "y": 4,
      "z": -26,
      "name": "Rock_Basalt_Brick_Decorative"
    },
    {
      "x": -26,
      "y": 5,
      "z": -26,
      "name": "*Rock_Basalt_Brick_Roof_State_Definitions_Corner_Left",
      "rotation": 2
    },
    {
      "x": -26,
      "y": 0,
      "z": -25,
      "name": "Rock_Basalt_Brick",
      "rotation": 2
    },
    {
      "x": -26,
      "y": 1,
      "z": -25,
      "name": "Rock_Basalt_Brick",
      "rotation": 2
    },
    {
      "x": -26,
      "y": 2,
      "z": -25,
      "name": "Rock_Basalt_Brick",
      "rotation": 2
    },
    {
      "x": -26,
      "y": 3,
      "z": -25,
      "name": "Rock_Basalt_Brick",
      "rotation": 2
    },
    {
      "x": -26,
      "y": 4,
      "z": -25,
      "name": "Rock_Basalt_Brick",
      "rotation": 2
    },
    {
      "x": -26,
      "y": 5,
      "z": -25,
      "name": "Rock_Basalt_Brick_Roof",
      "rotation": 3
    },
    {
      "x": -26,
      "y": 6,
      "z": -25,
      "name": "Rock_Basalt_Brick",
      "rotation": 2
    },
    {
      "x": -26,
      "y": 0,
      "z": -24,
      "name": "Rock_Basalt_Brick",
      "rotation": 2
    },
    {
      "x": -26,
      "y": 1,
      "z": -24,
      "name": "Rock_Basalt_Brick",
      "rotation": 2
    },
    {
      "x": -26,
      "y": 2,
      "z": -24,
      "name": "Rock_Basalt_Brick",
      "rotation": 2
    },
    {
      "x": -26,
      "y": 3,
      "z": -24,
      "name": "Rock_Basalt_Brick",
      "rotation": 2
    },
    {
      "x": -26,
      "y": 4,
      "z": -24,
      "name": "Rock_Basalt_Brick",
      "rotation": 2
    },
    {
      "x": -26,
      "y": 5,
      "z": -24,
      "name": "Rock_Basalt_Brick",
      "rotation": 2
    },
    {
      "x": -26,
      "y": 6,
      "z": -24,
      "name": "Rock_Basalt_Brick",
      "rotation": 2
    },
    {
      "x": -26,
      "y": 0,
      "z": -23,
      "name": "Rock_Basalt_Brick",
      "rotation": 2
    },
    {
      "x": -26,
      "y": 1,
      "z": -23,
      "name": "Rock_Basalt_Brick",
      "rotation": 2
    },
    {
      "x": -26,
      "y": 2,
      "z": -23,
      "name": "Rock_Basalt_Brick",
      "rotation": 2
    },
    {
      "x": -26,
      "y": 3,
      "z": -23,
      "name": "Rock_Basalt_Brick",
      "rotation": 2
    },
    {
      "x": -26,
      "y": 4,
      "z": -23,
      "name": "Rock_Basalt_Brick",
      "rotation": 2
    },
    {
      "x": -26,
      "y": 5,
      "z": -23,
      "name": "Rock_Basalt_Brick",
      "rotation": 2
    },
    {
      "x": -26,
      "y": 6,
      "z": -23,
      "name": "Rock_Basalt_Brick",
      "rotation": 2
    },
    {
      "x": -26,
      "y": 0,
      "z": -22,
      "name": "Rock_Basalt_Brick",
      "rotation": 2
    },
    {
      "x": -26,
      "y": 1,
      "z": -22,
      "name": "Rock_Basalt_Brick",
      "rotation": 2
    },
    {
      "x": -26,
      "y": 2,
      "z": -22,
      "name": "Rock_Basalt_Brick",
      "rotation": 2
    },
    {
      "x": -26,
      "y": 3,
      "z": -22,
      "name": "Rock_Basalt_Brick",
      "rotation": 2
    },
    {
      "x": -26,
      "y": 4,
      "z": -22,
      "name": "Rock_Basalt_Brick",
      "rotation": 2
    },
    {
      "x": -26,
      "y": 5,
      "z": -22,
      "name": "Rock_Basalt_Brick",
      "rotation": 2
    },
    {
      "x": -26,
      "y": 6,
      "z": -22,
      "name": "Rock_Basalt_Brick",
      "rotation": 2
    },
    {
      "x": -26,
      "y": 0,
      "z": -21,
      "name": "Rock_Basalt_Brick",
      "rotation": 2
    },
    {
      "x": -26,
      "y": 1,
      "z": -21,
      "name": "Rock_Basalt_Brick",
      "rotation": 2
    },
    {
      "x": -26,
      "y": 2,
      "z": -21,
      "name": "Rock_Basalt_Brick",
      "rotation": 2
    },
    {
      "x": -26,
      "y": 3,
      "z": -21,
      "name": "Rock_Basalt_Brick",
      "rotation": 2
    },
    {
      "x": -26,
      "y": 4,
      "z": -21,
      "name": "Rock_Basalt_Brick",
      "rotation": 2
    },
    {
      "x": -26,
      "y": 5,
      "z": -21,
      "name": "Rock_Basalt_Brick",
      "rotation": 2
    },
    {
      "x": -26,
      "y": 6,
      "z": -21,
      "name": "Rock_Basalt_Brick",
      "rotation": 2
    },
    {
      "x": -26,
      "y": 0,
      "z": -20,
      "name": "Rock_Basalt_Brick",
      "rotation": 2
    },
    {
      "x": -26,
      "y": 1,
      "z": -20,
      "name": "Rock_Basalt_Brick",
      "rotation": 2
    },
    {
      "x": -26,
      "y": 2,
      "z": -20,
      "name": "Rock_Basalt_Brick",
      "rotation": 2
    },
    {
      "x": -26,
      "y": 3,
      "z": -20,
      "name": "Rock_Basalt_Brick",
      "rotation": 2
    },
    {
      "x": -26,
      "y": 4,
      "z": -20,
      "name": "Rock_Basalt_Brick",
      "rotation": 2
    },
    {
      "x": -26,
      "y": 5,
      "z": -20,
      "name": "Rock_Basalt_Brick",
      "rotation": 2
    },
    {
      "x": -26,
      "y": 6,
      "z": -20,
      "name": "Rock_Basalt_Brick",
      "rotation": 2
    },
    {
      "x": -26,
      "y": 0,
      "z": -19,
      "name": "Rock_Basalt_Brick",
      "rotation": 2
    },
    {
      "x": -26,
      "y": 1,
      "z": -19,
      "name": "Rock_Basalt_Brick",
      "rotation": 2
    },
    {
      "x": -26,
      "y": 2,
      "z": -19,
      "name": "Rock_Basalt_Brick",
      "rotation": 2
    },
    {
      "x": -26,
      "y": 3,
      "z": -19,
      "name": "Rock_Basalt_Brick",
      "rotation": 2
    },
    {
      "x": -26,
      "y": 4,
      "z": -19,
      "name": "Rock_Basalt_Brick",
      "rotation": 2
    },
    {
      "x": -26,
      "y": 5,
      "z": -19,
      "name": "Rock_Basalt_Brick",
      "rotation": 2
    },
    {
      "x": -26,
      "y": 6,
      "z": -19,
      "name": "Rock_Basalt_Brick",
      "rotation": 2
    },
    {
      "x": -26,
      "y": 0,
      "z": -18,
      "name": "Rock_Basalt_Brick",
      "rotation": 2
    },
    {
      "x": -26,
      "y": 1,
      "z": -18,
      "name": "Rock_Basalt_Brick",
      "rotation": 2
    },
    {
      "x": -26,
      "y": 2,
      "z": -18,
      "name": "Rock_Basalt_Brick",
      "rotation": 2
    },
    {
      "x": -26,
      "y": 3,
      "z": -18,
      "name": "Rock_Basalt_Brick",
      "rotation": 2
    },
    {
      "x": -26,
      "y": 4,
      "z": -18,
      "name": "Rock_Basalt_Brick",
      "rotation": 2
    },
    {
      "x": -26,
      "y": 5,
      "z": -18,
      "name": "Rock_Basalt_Brick",
      "rotation": 2
    },
    {
      "x": -26,
      "y": 6,
      "z": -18,
      "name": "Rock_Basalt_Brick",
      "rotation": 2
    },
    {
      "x": -26,
      "y": 0,
      "z": -17,
      "name": "Rock_Basalt_Brick",
      "rotation": 2
    },
    {
      "x": -26,
      "y": 1,
      "z": -17,
      "name": "Rock_Basalt_Brick",
      "rotation": 2
    },
    {
      "x": -26,
      "y": 2,
      "z": -17,
      "name": "Rock_Basalt_Brick",
      "rotation": 2
    },
    {
      "x": -26,
      "y": 3,
      "z": -17,
      "name": "Rock_Basalt_Brick",
      "rotation": 2
    },
    {
      "x": -26,
      "y": 4,
      "z": -17,
      "name": "Rock_Basalt_Brick",
      "rotation": 2
    },
    {
      "x": -26,
      "y": 5,
      "z": -17,
      "name": "Rock_Basalt_Brick",
      "rotation": 2
    },
    {
      "x": -26,
      "y": 6,
      "z": -17,
      "name": "Rock_Basalt_Brick",
      "rotation": 2
    },
    {
      "x": -26,
      "y": 0,
      "z": -16,
      "name": "Rock_Basalt_Brick",
      "rotation": 2
    },
    {
      "x": -26,
      "y": 1,
      "z": -16,
      "name": "Rock_Basalt_Brick",
      "rotation": 2
    },
    {
      "x": -26,
      "y": 2,
      "z": -16,
      "name": "Rock_Basalt_Brick",
      "rotation": 2
    },
    {
      "x": -26,
      "y": 3,
      "z": -16,
      "name": "Rock_Basalt_Brick",
      "rotation": 2
    },
    {
      "x": -26,
      "y": 4,
      "z": -16,
      "name": "Rock_Basalt_Brick",
      "rotation": 2
    },
    {
      "x": -26,
      "y": 5,
      "z": -16,
      "name": "Rock_Basalt_Brick",
      "rotation": 2
    },
    {
      "x": -26,
      "y": 6,
      "z": -16,
      "name": "Rock_Basalt_Brick",
      "rotation": 2
    },
    {
      "x": -26,
      "y": 0,
      "z": -15,
      "name": "Rock_Basalt_Brick",
      "rotation": 2
    },
    {
      "x": -26,
      "y": 1,
      "z": -15,
      "name": "Rock_Basalt_Brick",
      "rotation": 2
    },
    {
      "x": -26,
      "y": 2,
      "z": -15,
      "name": "Rock_Basalt_Brick",
      "rotation": 2
    },
    {
      "x": -26,
      "y": 3,
      "z": -15,
      "name": "Rock_Basalt_Brick",
      "rotation": 2
    },
    {
      "x": -26,
      "y": 4,
      "z": -15,
      "name": "Rock_Basalt_Brick",
      "rotation": 2
    },
    {
      "x": -26,
      "y": 5,
      "z": -15,
      "name": "Rock_Basalt_Brick",
      "rotation": 2
    },
    {
      "x": -26,
      "y": 6,
      "z": -15,
      "name": "Rock_Basalt_Brick",
      "rotation": 2
    },
    {
      "x": -26,
      "y": 0,
      "z": -14,
      "name": "Rock_Basalt_Brick",
      "rotation": 2
    },
    {
      "x": -26,
      "y": 1,
      "z": -14,
      "name": "Rock_Basalt_Brick",
      "rotation": 2
    },
    {
      "x": -26,
      "y": 2,
      "z": -14,
      "name": "Rock_Basalt_Brick",
      "rotation": 2
    },
    {
      "x": -26,
      "y": 3,
      "z": -14,
      "name": "Rock_Basalt_Brick",
      "rotation": 2
    },
    {
      "x": -26,
      "y": 4,
      "z": -14,
      "name": "Rock_Basalt_Brick",
      "rotation": 2
    },
    {
      "x": -26,
      "y": 5,
      "z": -14,
      "name": "Rock_Basalt_Brick",
      "rotation": 2
    },
    {
      "x": -26,
      "y": 6,
      "z": -14,
      "name": "Rock_Basalt_Brick",
      "rotation": 2
    },
    {
      "x": -26,
      "y": 0,
      "z": -13,
      "name": "Rock_Basalt_Brick",
      "rotation": 2
    },
    {
      "x": -26,
      "y": 1,
      "z": -13,
      "name": "Rock_Basalt_Brick",
      "rotation": 2
    },
    {
      "x": -26,
      "y": 2,
      "z": -13,
      "name": "Rock_Basalt_Brick",
      "rotation": 2
    },
    {
      "x": -26,
      "y": 3,
      "z": -13,
      "name": "Rock_Basalt_Brick",
      "rotation": 2
    },
    {
      "x": -26,
      "y": 4,
      "z": -13,
      "name": "Rock_Basalt_Brick",
      "rotation": 2
    },
    {
      "x": -26,
      "y": 5,
      "z": -13,
      "name": "Rock_Basalt_Brick",
      "rotation": 2
    },
    {
      "x": -26,
      "y": 6,
      "z": -13,
      "name": "Rock_Basalt_Brick",
      "rotation": 2
    },
    {
      "x": -26,
      "y": 0,
      "z": -12,
      "name": "Rock_Basalt_Brick",
      "rotation": 2
    },
    {
      "x": -26,
      "y": 1,
      "z": -12,
      "name": "Rock_Basalt_Brick",
      "rotation": 2
    },
    {
      "x": -26,
      "y": 2,
      "z": -12,
      "name": "Rock_Basalt_Brick",
      "rotation": 2
    },
    {
      "x": -26,
      "y": 3,
      "z": -12,
      "name": "Rock_Basalt_Brick",
      "rotation": 2
    },
    {
      "x": -26,
      "y": 4,
      "z": -12,
      "name": "Rock_Basalt_Brick",
      "rotation": 2
    },
    {
      "x": -26,
      "y": 5,
      "z": -12,
      "name": "Rock_Basalt_Brick",
      "rotation": 2
    },
    {
      "x": -26,
      "y": 6,
      "z": -12,
      "name": "Rock_Basalt_Brick",
      "rotation": 2
    },
    {
      "x": -26,
      "y": 0,
      "z": -11,
      "name": "Rock_Basalt_Brick",
      "rotation": 2
    },
    {
      "x": -26,
      "y": 1,
      "z": -11,
      "name": "Rock_Basalt_Brick",
      "rotation": 2
    },
    {
      "x": -26,
      "y": 2,
      "z": -11,
      "name": "Rock_Basalt_Brick",
      "rotation": 2
    },
    {
      "x": -26,
      "y": 3,
      "z": -11,
      "name": "Rock_Basalt_Brick",
      "rotation": 2
    },
    {
      "x": -26,
      "y": 4,
      "z": -11,
      "name": "Rock_Basalt_Brick",
      "rotation": 2
    },
    {
      "x": -26,
      "y": 5,
      "z": -11,
      "name": "Rock_Basalt_Brick",
      "rotation": 2
    },
    {
      "x": -26,
      "y": 6,
      "z": -11,
      "name": "Rock_Basalt_Brick",
      "rotation": 2
    },
    {
      "x": -26,
      "y": 0,
      "z": -10,
      "name": "Rock_Basalt_Brick",
      "rotation": 2
    },
    {
      "x": -26,
      "y": 1,
      "z": -10,
      "name": "Rock_Basalt_Brick",
      "rotation": 2
    },
    {
      "x": -26,
      "y": 2,
      "z": -10,
      "name": "Rock_Basalt_Brick",
      "rotation": 2
    },
    {
      "x": -26,
      "y": 3,
      "z": -10,
      "name": "Rock_Basalt_Brick",
      "rotation": 2
    },
    {
      "x": -26,
      "y": 4,
      "z": -10,
      "name": "Rock_Basalt_Brick",
      "rotation": 2
    },
    {
      "x": -26,
      "y": 5,
      "z": -10,
      "name": "Rock_Basalt_Brick",
      "rotation": 2
    },
    {
      "x": -26,
      "y": 6,
      "z": -10,
      "name": "Rock_Basalt_Brick",
      "rotation": 2
    },
    {
      "x": -26,
      "y": 0,
      "z": -9,
      "name": "Rock_Basalt_Brick",
      "rotation": 2
    },
    {
      "x": -26,
      "y": 1,
      "z": -9,
      "name": "Rock_Basalt_Brick",
      "rotation": 2
    },
    {
      "x": -26,
      "y": 2,
      "z": -9,
      "name": "Rock_Basalt_Brick",
      "rotation": 2
    },
    {
      "x": -26,
      "y": 3,
      "z": -9,
      "name": "Rock_Basalt_Brick",
      "rotation": 2
    },
    {
      "x": -26,
      "y": 4,
      "z": -9,
      "name": "Rock_Basalt_Brick",
      "rotation": 2
    },
    {
      "x": -26,
      "y": 5,
      "z": -9,
      "name": "Rock_Basalt_Brick",
      "rotation": 2
    },
    {
      "x": -26,
      "y": 6,
      "z": -9,
      "name": "Rock_Basalt_Brick",
      "rotation": 2
    },
    {
      "x": -26,
      "y": 0,
      "z": -8,
      "name": "Rock_Basalt_Brick",
      "rotation": 2
    },
    {
      "x": -26,
      "y": 1,
      "z": -8,
      "name": "Rock_Basalt_Brick",
      "rotation": 2
    },
    {
      "x": -26,
      "y": 2,
      "z": -8,
      "name": "Rock_Basalt_Brick",
      "rotation": 2
    },
    {
      "x": -26,
      "y": 3,
      "z": -8,
      "name": "Rock_Basalt_Brick",
      "rotation": 2
    },
    {
      "x": -26,
      "y": 4,
      "z": -8,
      "name": "Rock_Basalt_Brick",
      "rotation": 2
    },
    {
      "x": -26,
      "y": 5,
      "z": -8,
      "name": "Rock_Basalt_Brick",
      "rotation": 2
    },
    {
      "x": -26,
      "y": 6,
      "z": -8,
      "name": "Rock_Basalt_Brick",
      "rotation": 2
    },
    {
      "x": -26,
      "y": 0,
      "z": -7,
      "name": "Rock_Basalt_Brick",
      "rotation": 2
    },
    {
      "x": -26,
      "y": 1,
      "z": -7,
      "name": "Rock_Basalt_Brick",
      "rotation": 2
    },
    {
      "x": -26,
      "y": 2,
      "z": -7,
      "name": "Rock_Basalt_Brick",
      "rotation": 2
    },
    {
      "x": -26,
      "y": 3,
      "z": -7,
      "name": "Rock_Basalt_Brick",
      "rotation": 2
    },
    {
      "x": -26,
      "y": 4,
      "z": -7,
      "name": "Rock_Basalt_Brick",
      "rotation": 2
    },
    {
      "x": -26,
      "y": 5,
      "z": -7,
      "name": "Rock_Basalt_Brick",
      "rotation": 2
    },
    {
      "x": -26,
      "y": 6,
      "z": -7,
      "name": "Rock_Basalt_Brick",
      "rotation": 2
    },
    {
      "x": -26,
      "y": 0,
      "z": -6,
      "name": "Rock_Basalt_Brick",
      "rotation": 2
    },
    {
      "x": -26,
      "y": 1,
      "z": -6,
      "name": "Rock_Basalt_Brick",
      "rotation": 2
    },
    {
      "x": -26,
      "y": 2,
      "z": -6,
      "name": "Rock_Basalt_Brick",
      "rotation": 2
    },
    {
      "x": -26,
      "y": 3,
      "z": -6,
      "name": "Rock_Basalt_Brick",
      "rotation": 2
    },
    {
      "x": -26,
      "y": 4,
      "z": -6,
      "name": "Rock_Basalt_Brick",
      "rotation": 2
    },
    {
      "x": -26,
      "y": 5,
      "z": -6,
      "name": "Rock_Basalt_Brick",
      "rotation": 2
    },
    {
      "x": -26,
      "y": 6,
      "z": -6,
      "name": "Rock_Basalt_Brick",
      "rotation": 2
    },
    {
      "x": -26,
      "y": 0,
      "z": -5,
      "name": "Rock_Basalt_Brick",
      "rotation": 2
    },
    {
      "x": -26,
      "y": 1,
      "z": -5,
      "name": "Rock_Basalt_Brick",
      "rotation": 2
    },
    {
      "x": -26,
      "y": 2,
      "z": -5,
      "name": "Rock_Basalt_Brick",
      "rotation": 2
    },
    {
      "x": -26,
      "y": 3,
      "z": -5,
      "name": "Rock_Basalt_Brick",
      "rotation": 2
    },
    {
      "x": -26,
      "y": 4,
      "z": -5,
      "name": "Rock_Basalt_Brick",
      "rotation": 2
    },
    {
      "x": -26,
      "y": 5,
      "z": -5,
      "name": "Rock_Basalt_Brick",
      "rotation": 2
    },
    {
      "x": -26,
      "y": 6,
      "z": -5,
      "name": "Rock_Basalt_Brick",
      "rotation": 2
    },
    {
      "x": -26,
      "y": 0,
      "z": -4,
      "name": "Rock_Basalt_Brick",
      "rotation": 2
    },
    {
      "x": -26,
      "y": 1,
      "z": -4,
      "name": "Rock_Basalt_Brick",
      "rotation": 2
    },
    {
      "x": -26,
      "y": 2,
      "z": -4,
      "name": "Rock_Basalt_Brick",
      "rotation": 2
    },
    {
      "x": -26,
      "y": 3,
      "z": -4,
      "name": "Rock_Basalt_Brick",
      "rotation": 2
    },
    {
      "x": -26,
      "y": 4,
      "z": -4,
      "name": "Rock_Basalt_Brick",
      "rotation": 2
    },
    {
      "x": -26,
      "y": 5,
      "z": -4,
      "name": "Rock_Basalt_Brick",
      "rotation": 2
    },
    {
      "x": -26,
      "y": 6,
      "z": -4,
      "name": "Rock_Basalt_Brick",
      "rotation": 2
    },
    {
      "x": -26,
      "y": 0,
      "z": -3,
      "name": "Rock_Basalt_Brick",
      "rotation": 2
    },
    {
      "x": -26,
      "y": 1,
      "z": -3,
      "name": "Rock_Basalt_Brick",
      "rotation": 2
    },
    {
      "x": -26,
      "y": 2,
      "z": -3,
      "name": "Rock_Basalt_Brick",
      "rotation": 2
    },
    {
      "x": -26,
      "y": 3,
      "z": -3,
      "name": "Rock_Basalt_Brick",
      "rotation": 2
    },
    {
      "x": -26,
      "y": 4,
      "z": -3,
      "name": "Rock_Basalt_Brick",
      "rotation": 2
    },
    {
      "x": -26,
      "y": 5,
      "z": -3,
      "name": "Rock_Basalt_Brick",
      "rotation": 2
    },
    {
      "x": -26,
      "y": 6,
      "z": -3,
      "name": "Rock_Basalt_Brick",
      "rotation": 2
    },
    {
      "x": -26,
      "y": 0,
      "z": -2,
      "name": "Rock_Basalt_Brick",
      "rotation": 2
    },
    {
      "x": -26,
      "y": 1,
      "z": -2,
      "name": "Rock_Basalt_Brick",
      "rotation": 2
    },
    {
      "x": -26,
      "y": 2,
      "z": -2,
      "name": "Rock_Basalt_Brick",
      "rotation": 2
    },
    {
      "x": -26,
      "y": 3,
      "z": -2,
      "name": "Rock_Basalt_Brick",
      "rotation": 2
    },
    {
      "x": -26,
      "y": 4,
      "z": -2,
      "name": "Rock_Basalt_Brick",
      "rotation": 2
    },
    {
      "x": -26,
      "y": 5,
      "z": -2,
      "name": "Rock_Basalt_Brick",
      "rotation": 2
    },
    {
      "x": -26,
      "y": 6,
      "z": -2,
      "name": "Rock_Basalt_Brick",
      "rotation": 2
    },
    {
      "x": -26,
      "y": 0,
      "z": -1,
      "name": "Rock_Basalt_Brick",
      "rotation": 2
    },
    {
      "x": -26,
      "y": 1,
      "z": -1,
      "name": "Rock_Basalt_Brick",
      "rotation": 2
    },
    {
      "x": -26,
      "y": 2,
      "z": -1,
      "name": "Rock_Basalt_Brick",
      "rotation": 2
    },
    {
      "x": -26,
      "y": 3,
      "z": -1,
      "name": "Rock_Basalt_Brick",
      "rotation": 2
    },
    {
      "x": -26,
      "y": 4,
      "z": -1,
      "name": "Rock_Basalt_Brick",
      "rotation": 2
    },
    {
      "x": -26,
      "y": 5,
      "z": -1,
      "name": "Rock_Basalt_Brick",
      "rotation": 2
    },
    {
      "x": -26,
      "y": 6,
      "z": -1,
      "name": "Rock_Basalt_Brick",
      "rotation": 2
    },
    {
      "x": -26,
      "y": 0,
      "z": 0,
      "name": "Rock_Basalt_Brick",
      "rotation": 2
    },
    {
      "x": -26,
      "y": 1,
      "z": 0,
      "name": "Rock_Basalt_Brick",
      "rotation": 2
    },
    {
      "x": -26,
      "y": 2,
      "z": 0,
      "name": "Rock_Basalt_Brick",
      "rotation": 2
    },
    {
      "x": -26,
      "y": 3,
      "z": 0,
      "name": "Rock_Basalt_Brick",
      "rotation": 2
    },
    {
      "x": -26,
      "y": 4,
      "z": 0,
      "name": "Rock_Basalt_Brick",
      "rotation": 2
    },
    {
      "x": -26,
      "y": 5,
      "z": 0,
      "name": "Rock_Basalt_Brick",
      "rotation": 2
    },
    {
      "x": -26,
      "y": 6,
      "z": 0,
      "name": "Rock_Basalt_Brick",
      "rotation": 2
    },
    {
      "x": -26,
      "y": 0,
      "z": 1,
      "name": "Rock_Basalt_Brick",
      "rotation": 2
    },
    {
      "x": -26,
      "y": 1,
      "z": 1,
      "name": "Rock_Basalt_Brick",
      "rotation": 2
    },
    {
      "x": -26,
      "y": 2,
      "z": 1,
      "name": "Rock_Basalt_Brick",
      "rotation": 2
    },
    {
      "x": -26,
      "y": 3,
      "z": 1,
      "name": "Rock_Basalt_Brick",
      "rotation": 2
    },
    {
      "x": -26,
      "y": 4,
      "z": 1,
      "name": "Rock_Basalt_Brick",
      "rotation": 2
    },
    {
      "x": -26,
      "y": 5,
      "z": 1,
      "name": "Rock_Basalt_Brick",
      "rotation": 2
    },
    {
      "x": -26,
      "y": 6,
      "z": 1,
      "name": "Rock_Basalt_Brick",
      "rotation": 2
    },
    {
      "x": -26,
      "y": 0,
      "z": 2,
      "name": "Rock_Basalt_Brick",
      "rotation": 2
    },
    {
      "x": -26,
      "y": 1,
      "z": 2,
      "name": "Rock_Basalt_Brick",
      "rotation": 2
    },
    {
      "x": -26,
      "y": 2,
      "z": 2,
      "name": "Rock_Basalt_Brick",
      "rotation": 2
    },
    {
      "x": -26,
      "y": 3,
      "z": 2,
      "name": "Rock_Basalt_Brick",
      "rotation": 2
    },
    {
      "x": -26,
      "y": 4,
      "z": 2,
      "name": "Rock_Basalt_Brick",
      "rotation": 2
    },
    {
      "x": -26,
      "y": 5,
      "z": 2,
      "name": "Rock_Basalt_Brick",
      "rotation": 2
    },
    {
      "x": -26,
      "y": 6,
      "z": 2,
      "name": "Rock_Basalt_Brick",
      "rotation": 2
    },
    {
      "x": -26,
      "y": 0,
      "z": 3,
      "name": "Rock_Basalt_Brick",
      "rotation": 2
    },
    {
      "x": -26,
      "y": 1,
      "z": 3,
      "name": "Rock_Basalt_Brick",
      "rotation": 2
    },
    {
      "x": -26,
      "y": 2,
      "z": 3,
      "name": "Rock_Basalt_Brick",
      "rotation": 2
    },
    {
      "x": -26,
      "y": 3,
      "z": 3,
      "name": "Rock_Basalt_Brick",
      "rotation": 2
    },
    {
      "x": -26,
      "y": 4,
      "z": 3,
      "name": "Rock_Basalt_Brick",
      "rotation": 2
    },
    {
      "x": -26,
      "y": 5,
      "z": 3,
      "name": "Rock_Basalt_Brick",
      "rotation": 2
    },
    {
      "x": -26,
      "y": 6,
      "z": 3,
      "name": "Rock_Basalt_Brick",
      "rotation": 2
    },
    {
      "x": -26,
      "y": 0,
      "z": 4,
      "name": "Rock_Basalt_Brick",
      "rotation": 2
    },
    {
      "x": -26,
      "y": 1,
      "z": 4,
      "name": "Rock_Basalt_Brick",
      "rotation": 2
    },
    {
      "x": -26,
      "y": 2,
      "z": 4,
      "name": "Rock_Basalt_Brick",
      "rotation": 2
    },
    {
      "x": -26,
      "y": 3,
      "z": 4,
      "name": "Rock_Basalt_Brick",
      "rotation": 2
    },
    {
      "x": -26,
      "y": 4,
      "z": 4,
      "name": "Rock_Basalt_Brick",
      "rotation": 2
    },
    {
      "x": -26,
      "y": 5,
      "z": 4,
      "name": "Rock_Basalt_Brick",
      "rotation": 2
    },
    {
      "x": -26,
      "y": 6,
      "z": 4,
      "name": "Rock_Basalt_Brick",
      "rotation": 2
    },
    {
      "x": -26,
      "y": 0,
      "z": 5,
      "name": "Rock_Basalt_Brick",
      "rotation": 2
    },
    {
      "x": -26,
      "y": 1,
      "z": 5,
      "name": "Rock_Basalt_Brick",
      "rotation": 2
    },
    {
      "x": -26,
      "y": 2,
      "z": 5,
      "name": "Rock_Basalt_Brick",
      "rotation": 2
    },
    {
      "x": -26,
      "y": 3,
      "z": 5,
      "name": "Rock_Basalt_Brick",
      "rotation": 2
    },
    {
      "x": -26,
      "y": 4,
      "z": 5,
      "name": "Rock_Basalt_Brick",
      "rotation": 2
    },
    {
      "x": -26,
      "y": 5,
      "z": 5,
      "name": "Rock_Basalt_Brick",
      "rotation": 2
    },
    {
      "x": -26,
      "y": 6,
      "z": 5,
      "name": "Rock_Basalt_Brick",
      "rotation": 2
    },
    {
      "x": -26,
      "y": 0,
      "z": 6,
      "name": "Rock_Basalt_Brick",
      "rotation": 2
    },
    {
      "x": -26,
      "y": 1,
      "z": 6,
      "name": "Rock_Basalt_Brick",
      "rotation": 2
    },
    {
      "x": -26,
      "y": 2,
      "z": 6,
      "name": "Rock_Basalt_Brick",
      "rotation": 2
    },
    {
      "x": -26,
      "y": 3,
      "z": 6,
      "name": "Rock_Basalt_Brick",
      "rotation": 2
    },
    {
      "x": -26,
      "y": 4,
      "z": 6,
      "name": "Rock_Basalt_Brick",
      "rotation": 2
    },
    {
      "x": -26,
      "y": 5,
      "z": 6,
      "name": "Rock_Basalt_Brick",
      "rotation": 2
    },
    {
      "x": -26,
      "y": 6,
      "z": 6,
      "name": "Rock_Basalt_Brick",
      "rotation": 2
    },
    {
      "x": -26,
      "y": 0,
      "z": 7,
      "name": "Rock_Basalt_Brick",
      "rotation": 2
    },
    {
      "x": -26,
      "y": 1,
      "z": 7,
      "name": "Rock_Basalt_Brick",
      "rotation": 2
    },
    {
      "x": -26,
      "y": 2,
      "z": 7,
      "name": "Rock_Basalt_Brick",
      "rotation": 2
    },
    {
      "x": -26,
      "y": 3,
      "z": 7,
      "name": "Rock_Basalt_Brick",
      "rotation": 2
    },
    {
      "x": -26,
      "y": 4,
      "z": 7,
      "name": "Rock_Basalt_Brick",
      "rotation": 2
    },
    {
      "x": -26,
      "y": 5,
      "z": 7,
      "name": "Rock_Basalt_Brick",
      "rotation": 2
    },
    {
      "x": -26,
      "y": 6,
      "z": 7,
      "name": "Rock_Basalt_Brick",
      "rotation": 2
    },
    {
      "x": -26,
      "y": 0,
      "z": 8,
      "name": "Rock_Basalt_Brick",
      "rotation": 2
    },
    {
      "x": -26,
      "y": 1,
      "z": 8,
      "name": "Rock_Basalt_Brick",
      "rotation": 2
    },
    {
      "x": -26,
      "y": 2,
      "z": 8,
      "name": "Rock_Basalt_Brick",
      "rotation": 2
    },
    {
      "x": -26,
      "y": 3,
      "z": 8,
      "name": "Rock_Basalt_Brick",
      "rotation": 2
    },
    {
      "x": -26,
      "y": 4,
      "z": 8,
      "name": "Rock_Basalt_Brick",
      "rotation": 2
    },
    {
      "x": -26,
      "y": 5,
      "z": 8,
      "name": "Rock_Basalt_Brick",
      "rotation": 2
    },
    {
      "x": -26,
      "y": 6,
      "z": 8,
      "name": "Rock_Basalt_Brick",
      "rotation": 2
    },
    {
      "x": -26,
      "y": 0,
      "z": 9,
      "name": "Rock_Basalt_Brick",
      "rotation": 2
    },
    {
      "x": -26,
      "y": 1,
      "z": 9,
      "name": "Rock_Basalt_Brick",
      "rotation": 2
    },
    {
      "x": -26,
      "y": 2,
      "z": 9,
      "name": "Rock_Basalt_Brick",
      "rotation": 2
    },
    {
      "x": -26,
      "y": 3,
      "z": 9,
      "name": "Rock_Basalt_Brick",
      "rotation": 2
    },
    {
      "x": -26,
      "y": 4,
      "z": 9,
      "name": "Rock_Basalt_Brick",
      "rotation": 2
    },
    {
      "x": -26,
      "y": 5,
      "z": 9,
      "name": "Rock_Basalt_Brick",
      "rotation": 2
    },
    {
      "x": -26,
      "y": 6,
      "z": 9,
      "name": "Rock_Basalt_Brick",
      "rotation": 2
    },
    {
      "x": -26,
      "y": 0,
      "z": 10,
      "name": "Rock_Basalt_Brick",
      "rotation": 2
    },
    {
      "x": -26,
      "y": 1,
      "z": 10,
      "name": "Rock_Basalt_Brick",
      "rotation": 2
    },
    {
      "x": -26,
      "y": 2,
      "z": 10,
      "name": "Rock_Basalt_Brick",
      "rotation": 2
    },
    {
      "x": -26,
      "y": 3,
      "z": 10,
      "name": "Rock_Basalt_Brick",
      "rotation": 2
    },
    {
      "x": -26,
      "y": 4,
      "z": 10,
      "name": "Rock_Basalt_Brick",
      "rotation": 2
    },
    {
      "x": -26,
      "y": 5,
      "z": 10,
      "name": "Rock_Basalt_Brick",
      "rotation": 2
    },
    {
      "x": -26,
      "y": 6,
      "z": 10,
      "name": "Rock_Basalt_Brick",
      "rotation": 2
    },
    {
      "x": -26,
      "y": 0,
      "z": 11,
      "name": "Rock_Basalt_Brick",
      "rotation": 2
    },
    {
      "x": -26,
      "y": 1,
      "z": 11,
      "name": "Rock_Basalt_Brick",
      "rotation": 2
    },
    {
      "x": -26,
      "y": 2,
      "z": 11,
      "name": "Rock_Basalt_Brick",
      "rotation": 2
    },
    {
      "x": -26,
      "y": 3,
      "z": 11,
      "name": "Rock_Basalt_Brick",
      "rotation": 2
    },
    {
      "x": -26,
      "y": 4,
      "z": 11,
      "name": "Rock_Basalt_Brick",
      "rotation": 2
    },
    {
      "x": -26,
      "y": 5,
      "z": 11,
      "name": "Rock_Basalt_Brick",
      "rotation": 2
    },
    {
      "x": -26,
      "y": 6,
      "z": 11,
      "name": "Rock_Basalt_Brick",
      "rotation": 2
    },
    {
      "x": -26,
      "y": 0,
      "z": 12,
      "name": "Rock_Basalt_Brick",
      "rotation": 2
    },
    {
      "x": -26,
      "y": 1,
      "z": 12,
      "name": "Rock_Basalt_Brick",
      "rotation": 2
    },
    {
      "x": -26,
      "y": 2,
      "z": 12,
      "name": "Rock_Basalt_Brick",
      "rotation": 2
    },
    {
      "x": -26,
      "y": 3,
      "z": 12,
      "name": "Rock_Basalt_Brick",
      "rotation": 2
    },
    {
      "x": -26,
      "y": 4,
      "z": 12,
      "name": "Rock_Basalt_Brick",
      "rotation": 2
    },
    {
      "x": -26,
      "y": 5,
      "z": 12,
      "name": "Rock_Basalt_Brick",
      "rotation": 2
    },
    {
      "x": -26,
      "y": 6,
      "z": 12,
      "name": "Rock_Basalt_Brick",
      "rotation": 2
    },
    {
      "x": -26,
      "y": 0,
      "z": 13,
      "name": "Rock_Basalt_Brick",
      "rotation": 2
    },
    {
      "x": -26,
      "y": 1,
      "z": 13,
      "name": "Rock_Basalt_Brick",
      "rotation": 2
    },
    {
      "x": -26,
      "y": 2,
      "z": 13,
      "name": "Rock_Basalt_Brick",
      "rotation": 2
    },
    {
      "x": -26,
      "y": 3,
      "z": 13,
      "name": "Rock_Basalt_Brick",
      "rotation": 2
    },
    {
      "x": -26,
      "y": 4,
      "z": 13,
      "name": "Rock_Basalt_Brick",
      "rotation": 2
    },
    {
      "x": -26,
      "y": 5,
      "z": 13,
      "name": "Rock_Basalt_Brick",
      "rotation": 2
    },
    {
      "x": -26,
      "y": 6,
      "z": 13,
      "name": "Rock_Basalt_Brick",
      "rotation": 2
    },
    {
      "x": -26,
      "y": 0,
      "z": 14,
      "name": "Rock_Basalt_Brick",
      "rotation": 2
    },
    {
      "x": -26,
      "y": 1,
      "z": 14,
      "name": "Rock_Basalt_Brick",
      "rotation": 2
    },
    {
      "x": -26,
      "y": 2,
      "z": 14,
      "name": "Rock_Basalt_Brick",
      "rotation": 2
    },
    {
      "x": -26,
      "y": 3,
      "z": 14,
      "name": "Rock_Basalt_Brick",
      "rotation": 2
    },
    {
      "x": -26,
      "y": 4,
      "z": 14,
      "name": "Rock_Basalt_Brick",
      "rotation": 2
    },
    {
      "x": -26,
      "y": 5,
      "z": 14,
      "name": "Rock_Basalt_Brick",
      "rotation": 2
    },
    {
      "x": -26,
      "y": 6,
      "z": 14,
      "name": "Rock_Basalt_Brick",
      "rotation": 2
    },
    {
      "x": -26,
      "y": 0,
      "z": 15,
      "name": "Rock_Basalt_Brick",
      "rotation": 2
    },
    {
      "x": -26,
      "y": 1,
      "z": 15,
      "name": "Rock_Basalt_Brick",
      "rotation": 2
    },
    {
      "x": -26,
      "y": 2,
      "z": 15,
      "name": "Rock_Basalt_Brick",
      "rotation": 2
    },
    {
      "x": -26,
      "y": 3,
      "z": 15,
      "name": "Rock_Basalt_Brick",
      "rotation": 2
    },
    {
      "x": -26,
      "y": 4,
      "z": 15,
      "name": "Rock_Basalt_Brick",
      "rotation": 2
    },
    {
      "x": -26,
      "y": 5,
      "z": 15,
      "name": "Rock_Basalt_Brick",
      "rotation": 2
    },
    {
      "x": -26,
      "y": 6,
      "z": 15,
      "name": "Rock_Basalt_Brick",
      "rotation": 2
    },
    {
      "x": -26,
      "y": 0,
      "z": 16,
      "name": "Rock_Basalt_Brick",
      "rotation": 2
    },
    {
      "x": -26,
      "y": 1,
      "z": 16,
      "name": "Rock_Basalt_Brick",
      "rotation": 2
    },
    {
      "x": -26,
      "y": 2,
      "z": 16,
      "name": "Rock_Basalt_Brick",
      "rotation": 2
    },
    {
      "x": -26,
      "y": 3,
      "z": 16,
      "name": "Rock_Basalt_Brick",
      "rotation": 2
    },
    {
      "x": -26,
      "y": 4,
      "z": 16,
      "name": "Rock_Basalt_Brick",
      "rotation": 2
    },
    {
      "x": -26,
      "y": 5,
      "z": 16,
      "name": "Rock_Basalt_Brick",
      "rotation": 2
    },
    {
      "x": -26,
      "y": 6,
      "z": 16,
      "name": "Rock_Basalt_Brick",
      "rotation": 2
    },
    {
      "x": -26,
      "y": 0,
      "z": 17,
      "name": "Rock_Basalt_Brick",
      "rotation": 2
    },
    {
      "x": -26,
      "y": 1,
      "z": 17,
      "name": "Rock_Basalt_Brick",
      "rotation": 2
    },
    {
      "x": -26,
      "y": 2,
      "z": 17,
      "name": "Rock_Basalt_Brick",
      "rotation": 2
    },
    {
      "x": -26,
      "y": 3,
      "z": 17,
      "name": "Rock_Basalt_Brick",
      "rotation": 2
    },
    {
      "x": -26,
      "y": 4,
      "z": 17,
      "name": "Rock_Basalt_Brick",
      "rotation": 2
    },
    {
      "x": -26,
      "y": 5,
      "z": 17,
      "name": "Rock_Basalt_Brick",
      "rotation": 2
    },
    {
      "x": -26,
      "y": 6,
      "z": 17,
      "name": "Rock_Basalt_Brick",
      "rotation": 2
    },
    {
      "x": -26,
      "y": 0,
      "z": 18,
      "name": "Rock_Basalt_Brick",
      "rotation": 2
    },
    {
      "x": -26,
      "y": 1,
      "z": 18,
      "name": "Rock_Basalt_Brick",
      "rotation": 2
    },
    {
      "x": -26,
      "y": 2,
      "z": 18,
      "name": "Rock_Basalt_Brick",
      "rotation": 2
    },
    {
      "x": -26,
      "y": 3,
      "z": 18,
      "name": "Rock_Basalt_Brick",
      "rotation": 2
    },
    {
      "x": -26,
      "y": 4,
      "z": 18,
      "name": "Rock_Basalt_Brick",
      "rotation": 2
    },
    {
      "x": -26,
      "y": 5,
      "z": 18,
      "name": "Rock_Basalt_Brick",
      "rotation": 2
    },
    {
      "x": -26,
      "y": 6,
      "z": 18,
      "name": "Rock_Basalt_Brick",
      "rotation": 2
    },
    {
      "x": -26,
      "y": 0,
      "z": 19,
      "name": "Rock_Basalt_Brick",
      "rotation": 2
    },
    {
      "x": -26,
      "y": 1,
      "z": 19,
      "name": "Rock_Basalt_Brick",
      "rotation": 2
    },
    {
      "x": -26,
      "y": 2,
      "z": 19,
      "name": "Rock_Basalt_Brick",
      "rotation": 2
    },
    {
      "x": -26,
      "y": 3,
      "z": 19,
      "name": "Rock_Basalt_Brick",
      "rotation": 2
    },
    {
      "x": -26,
      "y": 4,
      "z": 19,
      "name": "Rock_Basalt_Brick",
      "rotation": 2
    },
    {
      "x": -26,
      "y": 5,
      "z": 19,
      "name": "Rock_Basalt_Brick",
      "rotation": 2
    },
    {
      "x": -26,
      "y": 6,
      "z": 19,
      "name": "Rock_Basalt_Brick",
      "rotation": 2
    },
    {
      "x": -26,
      "y": 0,
      "z": 20,
      "name": "Rock_Basalt_Brick",
      "rotation": 2
    },
    {
      "x": -26,
      "y": 1,
      "z": 20,
      "name": "Rock_Basalt_Brick",
      "rotation": 2
    },
    {
      "x": -26,
      "y": 2,
      "z": 20,
      "name": "Rock_Basalt_Brick",
      "rotation": 2
    },
    {
      "x": -26,
      "y": 3,
      "z": 20,
      "name": "Rock_Basalt_Brick",
      "rotation": 2
    },
    {
      "x": -26,
      "y": 4,
      "z": 20,
      "name": "Rock_Basalt_Brick",
      "rotation": 2
    },
    {
      "x": -26,
      "y": 5,
      "z": 20,
      "name": "Rock_Basalt_Brick",
      "rotation": 2
    },
    {
      "x": -26,
      "y": 6,
      "z": 20,
      "name": "Rock_Basalt_Brick",
      "rotation": 2
    },
    {
      "x": -26,
      "y": 0,
      "z": 21,
      "name": "Rock_Basalt_Brick",
      "rotation": 2
    },
    {
      "x": -26,
      "y": 1,
      "z": 21,
      "name": "Rock_Basalt_Brick",
      "rotation": 2
    },
    {
      "x": -26,
      "y": 2,
      "z": 21,
      "name": "Rock_Basalt_Brick",
      "rotation": 2
    },
    {
      "x": -26,
      "y": 3,
      "z": 21,
      "name": "Rock_Basalt_Brick",
      "rotation": 2
    },
    {
      "x": -26,
      "y": 4,
      "z": 21,
      "name": "Rock_Basalt_Brick",
      "rotation": 2
    },
    {
      "x": -26,
      "y": 5,
      "z": 21,
      "name": "Rock_Basalt_Brick",
      "rotation": 2
    },
    {
      "x": -26,
      "y": 6,
      "z": 21,
      "name": "Rock_Basalt_Brick",
      "rotation": 2
    },
    {
      "x": -26,
      "y": 0,
      "z": 22,
      "name": "Rock_Basalt_Brick",
      "rotation": 2
    },
    {
      "x": -26,
      "y": 1,
      "z": 22,
      "name": "Rock_Basalt_Brick",
      "rotation": 2
    },
    {
      "x": -26,
      "y": 2,
      "z": 22,
      "name": "Rock_Basalt_Brick",
      "rotation": 2
    },
    {
      "x": -26,
      "y": 3,
      "z": 22,
      "name": "Rock_Basalt_Brick",
      "rotation": 2
    },
    {
      "x": -26,
      "y": 4,
      "z": 22,
      "name": "Rock_Basalt_Brick",
      "rotation": 2
    },
    {
      "x": -26,
      "y": 5,
      "z": 22,
      "name": "Rock_Basalt_Brick",
      "rotation": 2
    },
    {
      "x": -26,
      "y": 6,
      "z": 22,
      "name": "Rock_Basalt_Brick",
      "rotation": 2
    },
    {
      "x": -26,
      "y": 0,
      "z": 23,
      "name": "Rock_Basalt_Brick",
      "rotation": 2
    },
    {
      "x": -26,
      "y": 1,
      "z": 23,
      "name": "Rock_Basalt_Brick",
      "rotation": 2
    },
    {
      "x": -26,
      "y": 2,
      "z": 23,
      "name": "Rock_Basalt_Brick",
      "rotation": 2
    },
    {
      "x": -26,
      "y": 3,
      "z": 23,
      "name": "Rock_Basalt_Brick",
      "rotation": 2
    },
    {
      "x": -26,
      "y": 4,
      "z": 23,
      "name": "Rock_Basalt_Brick",
      "rotation": 2
    },
    {
      "x": -26,
      "y": 5,
      "z": 23,
      "name": "Rock_Basalt_Brick",
      "rotation": 2
    },
    {
      "x": -26,
      "y": 6,
      "z": 23,
      "name": "Rock_Basalt_Brick",
      "rotation": 2
    },
    {
      "x": -26,
      "y": 0,
      "z": 24,
      "name": "Rock_Basalt_Brick",
      "rotation": 2
    },
    {
      "x": -26,
      "y": 1,
      "z": 24,
      "name": "Rock_Basalt_Brick",
      "rotation": 2
    },
    {
      "x": -26,
      "y": 2,
      "z": 24,
      "name": "Rock_Basalt_Brick",
      "rotation": 2
    },
    {
      "x": -26,
      "y": 3,
      "z": 24,
      "name": "Rock_Basalt_Brick",
      "rotation": 2
    },
    {
      "x": -26,
      "y": 4,
      "z": 24,
      "name": "Rock_Basalt_Brick",
      "rotation": 2
    },
    {
      "x": -26,
      "y": 5,
      "z": 24,
      "name": "Rock_Basalt_Brick",
      "rotation": 2
    },
    {
      "x": -26,
      "y": 6,
      "z": 24,
      "name": "Rock_Basalt_Brick",
      "rotation": 2
    },
    {
      "x": -26,
      "y": 0,
      "z": 25,
      "name": "Rock_Basalt_Brick",
      "rotation": 2
    },
    {
      "x": -26,
      "y": 1,
      "z": 25,
      "name": "Rock_Basalt_Brick",
      "rotation": 2
    },
    {
      "x": -26,
      "y": 2,
      "z": 25,
      "name": "Rock_Basalt_Brick",
      "rotation": 2
    },
    {
      "x": -26,
      "y": 3,
      "z": 25,
      "name": "Rock_Basalt_Brick",
      "rotation": 2
    },
    {
      "x": -26,
      "y": 4,
      "z": 25,
      "name": "Rock_Basalt_Brick",
      "rotation": 2
    },
    {
      "x": -26,
      "y": 5,
      "z": 25,
      "name": "Rock_Basalt_Brick_Roof",
      "rotation": 3
    },
    {
      "x": -26,
      "y": 6,
      "z": 25,
      "name": "Rock_Basalt_Brick",
      "rotation": 2
    },
    {
      "x": -26,
      "y": 0,
      "z": 26,
      "name": "Rock_Basalt_Brick_Smooth"
    },
    {
      "x": -26,
      "y": 1,
      "z": 26,
      "name": "Rock_Basalt_Brick_Smooth"
    },
    {
      "x": -26,
      "y": 2,
      "z": 26,
      "name": "Rock_Basalt_Brick_Smooth"
    },
    {
      "x": -26,
      "y": 3,
      "z": 26,
      "name": "Rock_Basalt_Brick_Smooth"
    },
    {
      "x": -26,
      "y": 4,
      "z": 26,
      "name": "Rock_Basalt_Brick_Decorative"
    },
    {
      "x": -26,
      "y": 5,
      "z": 26,
      "name": "*Rock_Basalt_Brick_Roof_State_Definitions_Corner_Left",
      "rotation": 3
    },
    {
      "x": -25,
      "y": 0,
      "z": -27,
      "name": "Rock_Basalt_Brick_Smooth"
    },
    {
      "x": -25,
      "y": 1,
      "z": -27,
      "name": "Rock_Basalt_Brick_Smooth"
    },
    {
      "x": -25,
      "y": 2,
      "z": -27,
      "name": "Rock_Basalt_Brick_Smooth"
    },
    {
      "x": -25,
      "y": 3,
      "z": -27,
      "name": "Rock_Basalt_Brick_Smooth"
    },
    {
      "x": -25,
      "y": 4,
      "z": -27,
      "name": "Rock_Basalt_Brick_Decorative"
    },
    {
      "x": -25,
      "y": 5,
      "z": -27,
      "name": "Rock_Basalt_Brick_Smooth"
    },
    {
      "x": -25,
      "y": 6,
      "z": -27,
      "name": "Rock_Basalt_Brick_Smooth"
    },
    {
      "x": -25,
      "y": 0,
      "z": -26,
      "name": "Rock_Basalt_Brick",
      "rotation": 2
    },
    {
      "x": -25,
      "y": 1,
      "z": -26,
      "name": "Rock_Basalt_Brick",
      "rotation": 2
    },
    {
      "x": -25,
      "y": 2,
      "z": -26,
      "name": "Rock_Basalt_Brick",
      "rotation": 2
    },
    {
      "x": -25,
      "y": 3,
      "z": -26,
      "name": "Rock_Basalt_Brick",
      "rotation": 2
    },
    {
      "x": -25,
      "y": 4,
      "z": -26,
      "name": "Rock_Basalt_Brick",
      "rotation": 2
    },
    {
      "x": -25,
      "y": 5,
      "z": -26,
      "name": "Rock_Basalt_Brick_Roof",
      "rotation": 2
    },
    {
      "x": -25,
      "y": 6,
      "z": -26,
      "name": "Rock_Basalt_Brick",
      "rotation": 2
    },
    {
      "x": -25,
      "y": 0,
      "z": -25,
      "name": "Rock_Basalt_Brick",
      "rotation": 2
    },
    {
      "x": -25,
      "y": 1,
      "z": -25,
      "name": "Rock_Basalt_Brick",
      "rotation": 2
    },
    {
      "x": -25,
      "y": 2,
      "z": -25,
      "name": "Rock_Basalt_Brick",
      "rotation": 2
    },
    {
      "x": -25,
      "y": 3,
      "z": -25,
      "name": "Rock_Basalt_Brick",
      "rotation": 2
    },
    {
      "x": -25,
      "y": 4,
      "z": -25,
      "name": "Rock_Basalt_Brick",
      "rotation": 2
    },
    {
      "x": -25,
      "y": 5,
      "z": -25,
      "name": "Rock_Basalt_Brick",
      "rotation": 2
    },
    {
      "x": -25,
      "y": 6,
      "z": -25,
      "name": "Rock_Basalt_Brick",
      "rotation": 2
    },
    {
      "x": -25,
      "y": 0,
      "z": -24,
      "name": "Rock_Basalt_Brick",
      "rotation": 2
    },
    {
      "x": -25,
      "y": 1,
      "z": -24,
      "name": "Rock_Basalt_Brick",
      "rotation": 2
    },
    {
      "x": -25,
      "y": 2,
      "z": -24,
      "name": "Rock_Basalt_Brick",
      "rotation": 2
    },
    {
      "x": -25,
      "y": 3,
      "z": -24,
      "name": "Rock_Basalt_Brick",
      "rotation": 2
    },
    {
      "x": -25,
      "y": 4,
      "z": -24,
      "name": "Rock_Basalt_Brick",
      "rotation": 2
    },
    {
      "x": -25,
      "y": 5,
      "z": -24,
      "name": "Rock_Basalt_Brick",
      "rotation": 2
    },
    {
      "x": -25,
      "y": 6,
      "z": -24,
      "name": "Rock_Basalt_Brick",
      "rotation": 2
    },
    {
      "x": -25,
      "y": 0,
      "z": -23,
      "name": "Rock_Basalt_Brick",
      "rotation": 2
    },
    {
      "x": -25,
      "y": 1,
      "z": -23,
      "name": "Rock_Basalt_Brick",
      "rotation": 2
    },
    {
      "x": -25,
      "y": 2,
      "z": -23,
      "name": "Rock_Basalt_Brick",
      "rotation": 2
    },
    {
      "x": -25,
      "y": 3,
      "z": -23,
      "name": "Rock_Basalt_Brick",
      "rotation": 2
    },
    {
      "x": -25,
      "y": 4,
      "z": -23,
      "name": "Rock_Basalt_Brick",
      "rotation": 2
    },
    {
      "x": -25,
      "y": 5,
      "z": -23,
      "name": "Rock_Basalt_Brick",
      "rotation": 2
    },
    {
      "x": -25,
      "y": 6,
      "z": -23,
      "name": "Rock_Basalt_Brick",
      "rotation": 2
    },
    {
      "x": -25,
      "y": 0,
      "z": -22,
      "name": "Rock_Basalt_Brick",
      "rotation": 2
    },
    {
      "x": -25,
      "y": 1,
      "z": -22,
      "name": "Rock_Basalt_Brick",
      "rotation": 2
    },
    {
      "x": -25,
      "y": 2,
      "z": -22,
      "name": "Rock_Basalt_Brick",
      "rotation": 2
    },
    {
      "x": -25,
      "y": 3,
      "z": -22,
      "name": "Rock_Basalt_Brick",
      "rotation": 2
    },
    {
      "x": -25,
      "y": 4,
      "z": -22,
      "name": "Rock_Basalt_Brick",
      "rotation": 2
    },
    {
      "x": -25,
      "y": 5,
      "z": -22,
      "name": "Rock_Basalt_Brick",
      "rotation": 2
    },
    {
      "x": -25,
      "y": 6,
      "z": -22,
      "name": "Rock_Basalt_Brick",
      "rotation": 2
    },
    {
      "x": -25,
      "y": 0,
      "z": -21,
      "name": "Rock_Basalt_Brick",
      "rotation": 2
    },
    {
      "x": -25,
      "y": 1,
      "z": -21,
      "name": "Rock_Basalt_Brick",
      "rotation": 2
    },
    {
      "x": -25,
      "y": 2,
      "z": -21,
      "name": "Rock_Basalt_Brick",
      "rotation": 2
    },
    {
      "x": -25,
      "y": 3,
      "z": -21,
      "name": "Rock_Basalt_Brick",
      "rotation": 2
    },
    {
      "x": -25,
      "y": 4,
      "z": -21,
      "name": "Rock_Basalt_Brick",
      "rotation": 2
    },
    {
      "x": -25,
      "y": 5,
      "z": -21,
      "name": "Rock_Basalt_Brick",
      "rotation": 2
    },
    {
      "x": -25,
      "y": 6,
      "z": -21,
      "name": "Rock_Basalt_Brick",
      "rotation": 2
    },
    {
      "x": -25,
      "y": 0,
      "z": -20,
      "name": "Rock_Basalt_Brick",
      "rotation": 2
    },
    {
      "x": -25,
      "y": 1,
      "z": -20,
      "name": "Rock_Basalt_Brick",
      "rotation": 2
    },
    {
      "x": -25,
      "y": 2,
      "z": -20,
      "name": "Rock_Basalt_Brick",
      "rotation": 2
    },
    {
      "x": -25,
      "y": 3,
      "z": -20,
      "name": "Rock_Basalt_Brick",
      "rotation": 2
    },
    {
      "x": -25,
      "y": 4,
      "z": -20,
      "name": "Rock_Basalt_Brick",
      "rotation": 2
    },
    {
      "x": -25,
      "y": 5,
      "z": -20,
      "name": "Rock_Basalt_Brick",
      "rotation": 2
    },
    {
      "x": -25,
      "y": 6,
      "z": -20,
      "name": "Rock_Basalt_Brick",
      "rotation": 2
    },
    {
      "x": -25,
      "y": 0,
      "z": -19,
      "name": "Rock_Basalt_Brick",
      "rotation": 2
    },
    {
      "x": -25,
      "y": 1,
      "z": -19,
      "name": "Rock_Basalt_Brick",
      "rotation": 2
    },
    {
      "x": -25,
      "y": 2,
      "z": -19,
      "name": "Rock_Basalt_Brick",
      "rotation": 2
    },
    {
      "x": -25,
      "y": 3,
      "z": -19,
      "name": "Rock_Basalt_Brick",
      "rotation": 2
    },
    {
      "x": -25,
      "y": 4,
      "z": -19,
      "name": "Rock_Basalt_Brick",
      "rotation": 2
    },
    {
      "x": -25,
      "y": 5,
      "z": -19,
      "name": "Rock_Basalt_Brick",
      "rotation": 2
    },
    {
      "x": -25,
      "y": 6,
      "z": -19,
      "name": "Rock_Basalt_Brick",
      "rotation": 2
    },
    {
      "x": -25,
      "y": 0,
      "z": -18,
      "name": "Rock_Basalt_Brick",
      "rotation": 2
    },
    {
      "x": -25,
      "y": 1,
      "z": -18,
      "name": "Rock_Basalt_Brick",
      "rotation": 2
    },
    {
      "x": -25,
      "y": 2,
      "z": -18,
      "name": "Rock_Basalt_Brick",
      "rotation": 2
    },
    {
      "x": -25,
      "y": 3,
      "z": -18,
      "name": "Rock_Basalt_Brick",
      "rotation": 2
    },
    {
      "x": -25,
      "y": 4,
      "z": -18,
      "name": "Rock_Basalt_Brick",
      "rotation": 2
    },
    {
      "x": -25,
      "y": 5,
      "z": -18,
      "name": "Rock_Basalt_Brick",
      "rotation": 2
    },
    {
      "x": -25,
      "y": 6,
      "z": -18,
      "name": "Rock_Basalt_Brick",
      "rotation": 2
    },
    {
      "x": -25,
      "y": 0,
      "z": -17,
      "name": "Rock_Basalt_Brick",
      "rotation": 2
    },
    {
      "x": -25,
      "y": 1,
      "z": -17,
      "name": "Rock_Basalt_Brick",
      "rotation": 2
    },
    {
      "x": -25,
      "y": 2,
      "z": -17,
      "name": "Rock_Basalt_Brick",
      "rotation": 2
    },
    {
      "x": -25,
      "y": 3,
      "z": -17,
      "name": "Rock_Basalt_Brick",
      "rotation": 2
    },
    {
      "x": -25,
      "y": 4,
      "z": -17,
      "name": "Rock_Basalt_Brick",
      "rotation": 2
    },
    {
      "x": -25,
      "y": 5,
      "z": -17,
      "name": "Rock_Basalt_Brick",
      "rotation": 2
    },
    {
      "x": -25,
      "y": 6,
      "z": -17,
      "name": "Rock_Basalt_Brick",
      "rotation": 2
    },
    {
      "x": -25,
      "y": 0,
      "z": -16,
      "name": "Rock_Basalt_Brick",
      "rotation": 2
    },
    {
      "x": -25,
      "y": 1,
      "z": -16,
      "name": "Rock_Basalt_Brick",
      "rotation": 2
    },
    {
      "x": -25,
      "y": 2,
      "z": -16,
      "name": "Rock_Basalt_Brick",
      "rotation": 2
    },
    {
      "x": -25,
      "y": 3,
      "z": -16,
      "name": "Rock_Basalt_Brick",
      "rotation": 2
    },
    {
      "x": -25,
      "y": 4,
      "z": -16,
      "name": "Rock_Basalt_Brick",
      "rotation": 2
    },
    {
      "x": -25,
      "y": 5,
      "z": -16,
      "name": "Rock_Basalt_Brick",
      "rotation": 2
    },
    {
      "x": -25,
      "y": 6,
      "z": -16,
      "name": "Rock_Basalt_Brick",
      "rotation": 2
    },
    {
      "x": -25,
      "y": 0,
      "z": -15,
      "name": "Rock_Basalt_Brick",
      "rotation": 2
    },
    {
      "x": -25,
      "y": 1,
      "z": -15,
      "name": "Rock_Basalt_Brick",
      "rotation": 2
    },
    {
      "x": -25,
      "y": 2,
      "z": -15,
      "name": "Rock_Basalt_Brick",
      "rotation": 2
    },
    {
      "x": -25,
      "y": 3,
      "z": -15,
      "name": "Rock_Basalt_Brick",
      "rotation": 2
    },
    {
      "x": -25,
      "y": 4,
      "z": -15,
      "name": "Rock_Basalt_Brick",
      "rotation": 2
    },
    {
      "x": -25,
      "y": 5,
      "z": -15,
      "name": "Rock_Basalt_Brick",
      "rotation": 2
    },
    {
      "x": -25,
      "y": 6,
      "z": -15,
      "name": "Rock_Basalt_Brick",
      "rotation": 2
    },
    {
      "x": -25,
      "y": 0,
      "z": -14,
      "name": "Rock_Basalt_Brick",
      "rotation": 2
    },
    {
      "x": -25,
      "y": 1,
      "z": -14,
      "name": "Rock_Basalt_Brick",
      "rotation": 2
    },
    {
      "x": -25,
      "y": 2,
      "z": -14,
      "name": "Rock_Basalt_Brick",
      "rotation": 2
    },
    {
      "x": -25,
      "y": 3,
      "z": -14,
      "name": "Rock_Basalt_Brick",
      "rotation": 2
    },
    {
      "x": -25,
      "y": 4,
      "z": -14,
      "name": "Rock_Basalt_Brick",
      "rotation": 2
    },
    {
      "x": -25,
      "y": 5,
      "z": -14,
      "name": "Rock_Basalt_Brick",
      "rotation": 2
    },
    {
      "x": -25,
      "y": 6,
      "z": -14,
      "name": "Rock_Basalt_Brick",
      "rotation": 2
    },
    {
      "x": -25,
      "y": 0,
      "z": -13,
      "name": "Rock_Basalt_Brick",
      "rotation": 2
    },
    {
      "x": -25,
      "y": 1,
      "z": -13,
      "name": "Rock_Basalt_Brick",
      "rotation": 2
    },
    {
      "x": -25,
      "y": 2,
      "z": -13,
      "name": "Rock_Basalt_Brick",
      "rotation": 2
    },
    {
      "x": -25,
      "y": 3,
      "z": -13,
      "name": "Rock_Basalt_Brick",
      "rotation": 2
    },
    {
      "x": -25,
      "y": 4,
      "z": -13,
      "name": "Rock_Basalt_Brick",
      "rotation": 2
    },
    {
      "x": -25,
      "y": 5,
      "z": -13,
      "name": "Rock_Basalt_Brick",
      "rotation": 2
    },
    {
      "x": -25,
      "y": 6,
      "z": -13,
      "name": "Rock_Basalt_Brick",
      "rotation": 2
    },
    {
      "x": -25,
      "y": 0,
      "z": -12,
      "name": "Rock_Basalt_Brick",
      "rotation": 2
    },
    {
      "x": -25,
      "y": 1,
      "z": -12,
      "name": "Rock_Basalt_Brick",
      "rotation": 2
    },
    {
      "x": -25,
      "y": 2,
      "z": -12,
      "name": "Rock_Basalt_Brick",
      "rotation": 2
    },
    {
      "x": -25,
      "y": 3,
      "z": -12,
      "name": "Rock_Basalt_Brick",
      "rotation": 2
    },
    {
      "x": -25,
      "y": 4,
      "z": -12,
      "name": "Rock_Basalt_Brick",
      "rotation": 2
    },
    {
      "x": -25,
      "y": 5,
      "z": -12,
      "name": "Rock_Basalt_Brick",
      "rotation": 2
    },
    {
      "x": -25,
      "y": 6,
      "z": -12,
      "name": "Rock_Basalt_Brick",
      "rotation": 2
    },
    {
      "x": -25,
      "y": 0,
      "z": -11,
      "name": "Rock_Basalt_Brick",
      "rotation": 2
    },
    {
      "x": -25,
      "y": 1,
      "z": -11,
      "name": "Rock_Basalt_Brick",
      "rotation": 2
    },
    {
      "x": -25,
      "y": 2,
      "z": -11,
      "name": "Rock_Basalt_Brick",
      "rotation": 2
    },
    {
      "x": -25,
      "y": 3,
      "z": -11,
      "name": "Rock_Basalt_Brick",
      "rotation": 2
    },
    {
      "x": -25,
      "y": 4,
      "z": -11,
      "name": "Rock_Basalt_Brick",
      "rotation": 2
    },
    {
      "x": -25,
      "y": 5,
      "z": -11,
      "name": "Rock_Basalt_Brick",
      "rotation": 2
    },
    {
      "x": -25,
      "y": 6,
      "z": -11,
      "name": "Rock_Basalt_Brick",
      "rotation": 2
    },
    {
      "x": -25,
      "y": 0,
      "z": -10,
      "name": "Rock_Basalt_Brick",
      "rotation": 2
    },
    {
      "x": -25,
      "y": 1,
      "z": -10,
      "name": "Rock_Basalt_Brick",
      "rotation": 2
    },
    {
      "x": -25,
      "y": 2,
      "z": -10,
      "name": "Rock_Basalt_Brick",
      "rotation": 2
    },
    {
      "x": -25,
      "y": 3,
      "z": -10,
      "name": "Rock_Basalt_Brick",
      "rotation": 2
    },
    {
      "x": -25,
      "y": 4,
      "z": -10,
      "name": "Rock_Basalt_Brick",
      "rotation": 2
    },
    {
      "x": -25,
      "y": 5,
      "z": -10,
      "name": "Rock_Basalt_Brick",
      "rotation": 2
    },
    {
      "x": -25,
      "y": 6,
      "z": -10,
      "name": "Rock_Basalt_Brick",
      "rotation": 2
    },
    {
      "x": -25,
      "y": 0,
      "z": -9,
      "name": "Rock_Basalt_Brick",
      "rotation": 2
    },
    {
      "x": -25,
      "y": 1,
      "z": -9,
      "name": "Rock_Basalt_Brick",
      "rotation": 2
    },
    {
      "x": -25,
      "y": 2,
      "z": -9,
      "name": "Rock_Basalt_Brick",
      "rotation": 2
    },
    {
      "x": -25,
      "y": 3,
      "z": -9,
      "name": "Rock_Basalt_Brick",
      "rotation": 2
    },
    {
      "x": -25,
      "y": 4,
      "z": -9,
      "name": "Rock_Basalt_Brick",
      "rotation": 2
    },
    {
      "x": -25,
      "y": 5,
      "z": -9,
      "name": "Rock_Basalt_Brick",
      "rotation": 2
    },
    {
      "x": -25,
      "y": 6,
      "z": -9,
      "name": "Rock_Basalt_Brick",
      "rotation": 2
    },
    {
      "x": -25,
      "y": 0,
      "z": -8,
      "name": "Rock_Basalt_Brick",
      "rotation": 2
    },
    {
      "x": -25,
      "y": 1,
      "z": -8,
      "name": "Rock_Basalt_Brick",
      "rotation": 2
    },
    {
      "x": -25,
      "y": 2,
      "z": -8,
      "name": "Rock_Basalt_Brick",
      "rotation": 2
    },
    {
      "x": -25,
      "y": 3,
      "z": -8,
      "name": "Rock_Basalt_Brick",
      "rotation": 2
    },
    {
      "x": -25,
      "y": 4,
      "z": -8,
      "name": "Rock_Basalt_Brick",
      "rotation": 2
    },
    {
      "x": -25,
      "y": 5,
      "z": -8,
      "name": "Rock_Basalt_Brick",
      "rotation": 2
    },
    {
      "x": -25,
      "y": 6,
      "z": -8,
      "name": "Rock_Basalt_Brick",
      "rotation": 2
    },
    {
      "x": -25,
      "y": 0,
      "z": -7,
      "name": "Rock_Basalt_Brick",
      "rotation": 2
    },
    {
      "x": -25,
      "y": 1,
      "z": -7,
      "name": "Rock_Basalt_Brick",
      "rotation": 2
    },
    {
      "x": -25,
      "y": 2,
      "z": -7,
      "name": "Rock_Basalt_Brick",
      "rotation": 2
    },
    {
      "x": -25,
      "y": 3,
      "z": -7,
      "name": "Rock_Basalt_Brick",
      "rotation": 2
    },
    {
      "x": -25,
      "y": 4,
      "z": -7,
      "name": "Rock_Basalt_Brick",
      "rotation": 2
    },
    {
      "x": -25,
      "y": 5,
      "z": -7,
      "name": "Rock_Basalt_Brick",
      "rotation": 2
    },
    {
      "x": -25,
      "y": 6,
      "z": -7,
      "name": "Rock_Basalt_Brick",
      "rotation": 2
    },
    {
      "x": -25,
      "y": 0,
      "z": -6,
      "name": "Rock_Basalt_Brick",
      "rotation": 2
    },
    {
      "x": -25,
      "y": 1,
      "z": -6,
      "name": "Rock_Basalt_Brick",
      "rotation": 2
    },
    {
      "x": -25,
      "y": 2,
      "z": -6,
      "name": "Rock_Basalt_Brick",
      "rotation": 2
    },
    {
      "x": -25,
      "y": 3,
      "z": -6,
      "name": "Rock_Basalt_Brick",
      "rotation": 2
    },
    {
      "x": -25,
      "y": 4,
      "z": -6,
      "name": "Rock_Basalt_Brick",
      "rotation": 2
    },
    {
      "x": -25,
      "y": 5,
      "z": -6,
      "name": "Rock_Basalt_Brick",
      "rotation": 2
    },
    {
      "x": -25,
      "y": 6,
      "z": -6,
      "name": "Rock_Basalt_Brick",
      "rotation": 2
    },
    {
      "x": -25,
      "y": 0,
      "z": -5,
      "name": "Rock_Basalt_Brick",
      "rotation": 2
    },
    {
      "x": -25,
      "y": 1,
      "z": -5,
      "name": "Rock_Basalt_Brick",
      "rotation": 2
    },
    {
      "x": -25,
      "y": 2,
      "z": -5,
      "name": "Rock_Basalt_Brick",
      "rotation": 2
    },
    {
      "x": -25,
      "y": 3,
      "z": -5,
      "name": "Rock_Basalt_Brick",
      "rotation": 2
    },
    {
      "x": -25,
      "y": 4,
      "z": -5,
      "name": "Rock_Basalt_Brick",
      "rotation": 2
    },
    {
      "x": -25,
      "y": 5,
      "z": -5,
      "name": "Rock_Basalt_Brick",
      "rotation": 2
    },
    {
      "x": -25,
      "y": 6,
      "z": -5,
      "name": "Rock_Basalt_Brick",
      "rotation": 2
    },
    {
      "x": -25,
      "y": 0,
      "z": -4,
      "name": "Rock_Basalt_Brick",
      "rotation": 2
    },
    {
      "x": -25,
      "y": 1,
      "z": -4,
      "name": "Rock_Basalt_Brick",
      "rotation": 2
    },
    {
      "x": -25,
      "y": 2,
      "z": -4,
      "name": "Rock_Basalt_Brick",
      "rotation": 2
    },
    {
      "x": -25,
      "y": 3,
      "z": -4,
      "name": "Rock_Basalt_Brick",
      "rotation": 2
    },
    {
      "x": -25,
      "y": 4,
      "z": -4,
      "name": "Rock_Basalt_Brick",
      "rotation": 2
    },
    {
      "x": -25,
      "y": 5,
      "z": -4,
      "name": "Rock_Basalt_Brick",
      "rotation": 2
    },
    {
      "x": -25,
      "y": 6,
      "z": -4,
      "name": "Rock_Basalt_Brick",
      "rotation": 2
    },
    {
      "x": -25,
      "y": 0,
      "z": -3,
      "name": "Rock_Basalt_Brick",
      "rotation": 2
    },
    {
      "x": -25,
      "y": 1,
      "z": -3,
      "name": "Rock_Basalt_Brick",
      "rotation": 2
    },
    {
      "x": -25,
      "y": 2,
      "z": -3,
      "name": "Rock_Basalt_Brick",
      "rotation": 2
    },
    {
      "x": -25,
      "y": 3,
      "z": -3,
      "name": "Rock_Basalt_Brick",
      "rotation": 2
    },
    {
      "x": -25,
      "y": 4,
      "z": -3,
      "name": "Rock_Basalt_Brick",
      "rotation": 2
    },
    {
      "x": -25,
      "y": 5,
      "z": -3,
      "name": "Rock_Basalt_Brick",
      "rotation": 2
    },
    {
      "x": -25,
      "y": 6,
      "z": -3,
      "name": "Rock_Basalt_Brick",
      "rotation": 2
    },
    {
      "x": -25,
      "y": 0,
      "z": -2,
      "name": "Rock_Basalt_Brick",
      "rotation": 2
    },
    {
      "x": -25,
      "y": 1,
      "z": -2,
      "name": "Rock_Basalt_Brick",
      "rotation": 2
    },
    {
      "x": -25,
      "y": 2,
      "z": -2,
      "name": "Rock_Basalt_Brick",
      "rotation": 2
    },
    {
      "x": -25,
      "y": 3,
      "z": -2,
      "name": "Rock_Basalt_Brick",
      "rotation": 2
    },
    {
      "x": -25,
      "y": 4,
      "z": -2,
      "name": "Rock_Basalt_Brick",
      "rotation": 2
    },
    {
      "x": -25,
      "y": 5,
      "z": -2,
      "name": "Rock_Basalt_Brick",
      "rotation": 2
    },
    {
      "x": -25,
      "y": 6,
      "z": -2,
      "name": "Rock_Basalt_Brick",
      "rotation": 2
    },
    {
      "x": -25,
      "y": 0,
      "z": -1,
      "name": "Rock_Basalt_Brick",
      "rotation": 2
    },
    {
      "x": -25,
      "y": 1,
      "z": -1,
      "name": "Rock_Basalt_Brick",
      "rotation": 2
    },
    {
      "x": -25,
      "y": 2,
      "z": -1,
      "name": "Rock_Basalt_Brick",
      "rotation": 2
    },
    {
      "x": -25,
      "y": 3,
      "z": -1,
      "name": "Rock_Basalt_Brick",
      "rotation": 2
    },
    {
      "x": -25,
      "y": 4,
      "z": -1,
      "name": "Rock_Basalt_Brick",
      "rotation": 2
    },
    {
      "x": -25,
      "y": 5,
      "z": -1,
      "name": "Rock_Basalt_Brick",
      "rotation": 2
    },
    {
      "x": -25,
      "y": 6,
      "z": -1,
      "name": "Rock_Basalt_Brick",
      "rotation": 2
    },
    {
      "x": -25,
      "y": 0,
      "z": 0,
      "name": "Rock_Basalt_Brick",
      "rotation": 2
    },
    {
      "x": -25,
      "y": 1,
      "z": 0,
      "name": "Rock_Basalt_Brick",
      "rotation": 2
    },
    {
      "x": -25,
      "y": 2,
      "z": 0,
      "name": "Rock_Basalt_Brick",
      "rotation": 2
    },
    {
      "x": -25,
      "y": 3,
      "z": 0,
      "name": "Rock_Basalt_Brick",
      "rotation": 2
    },
    {
      "x": -25,
      "y": 4,
      "z": 0,
      "name": "Rock_Basalt_Brick",
      "rotation": 2
    },
    {
      "x": -25,
      "y": 5,
      "z": 0,
      "name": "Rock_Basalt_Brick",
      "rotation": 2
    },
    {
      "x": -25,
      "y": 6,
      "z": 0,
      "name": "Rock_Basalt_Brick",
      "rotation": 2
    },
    {
      "x": -25,
      "y": 0,
      "z": 1,
      "name": "Rock_Basalt_Brick",
      "rotation": 2
    },
    {
      "x": -25,
      "y": 1,
      "z": 1,
      "name": "Rock_Basalt_Brick",
      "rotation": 2
    },
    {
      "x": -25,
      "y": 2,
      "z": 1,
      "name": "Rock_Basalt_Brick",
      "rotation": 2
    },
    {
      "x": -25,
      "y": 3,
      "z": 1,
      "name": "Rock_Basalt_Brick",
      "rotation": 2
    },
    {
      "x": -25,
      "y": 4,
      "z": 1,
      "name": "Rock_Basalt_Brick",
      "rotation": 2
    },
    {
      "x": -25,
      "y": 5,
      "z": 1,
      "name": "Rock_Basalt_Brick",
      "rotation": 2
    },
    {
      "x": -25,
      "y": 6,
      "z": 1,
      "name": "Rock_Basalt_Brick",
      "rotation": 2
    },
    {
      "x": -25,
      "y": 0,
      "z": 2,
      "name": "Rock_Basalt_Brick",
      "rotation": 2
    },
    {
      "x": -25,
      "y": 1,
      "z": 2,
      "name": "Rock_Basalt_Brick",
      "rotation": 2
    },
    {
      "x": -25,
      "y": 2,
      "z": 2,
      "name": "Rock_Basalt_Brick",
      "rotation": 2
    },
    {
      "x": -25,
      "y": 3,
      "z": 2,
      "name": "Rock_Basalt_Brick",
      "rotation": 2
    },
    {
      "x": -25,
      "y": 4,
      "z": 2,
      "name": "Rock_Basalt_Brick",
      "rotation": 2
    },
    {
      "x": -25,
      "y": 5,
      "z": 2,
      "name": "Rock_Basalt_Brick",
      "rotation": 2
    },
    {
      "x": -25,
      "y": 6,
      "z": 2,
      "name": "Rock_Basalt_Brick",
      "rotation": 2
    },
    {
      "x": -25,
      "y": 0,
      "z": 3,
      "name": "Rock_Basalt_Brick",
      "rotation": 2
    },
    {
      "x": -25,
      "y": 1,
      "z": 3,
      "name": "Rock_Basalt_Brick",
      "rotation": 2
    },
    {
      "x": -25,
      "y": 2,
      "z": 3,
      "name": "Rock_Basalt_Brick",
      "rotation": 2
    },
    {
      "x": -25,
      "y": 3,
      "z": 3,
      "name": "Rock_Basalt_Brick",
      "rotation": 2
    },
    {
      "x": -25,
      "y": 4,
      "z": 3,
      "name": "Rock_Basalt_Brick",
      "rotation": 2
    },
    {
      "x": -25,
      "y": 5,
      "z": 3,
      "name": "Rock_Basalt_Brick",
      "rotation": 2
    },
    {
      "x": -25,
      "y": 6,
      "z": 3,
      "name": "Rock_Basalt_Brick",
      "rotation": 2
    },
    {
      "x": -25,
      "y": 0,
      "z": 4,
      "name": "Rock_Basalt_Brick",
      "rotation": 2
    },
    {
      "x": -25,
      "y": 1,
      "z": 4,
      "name": "Rock_Basalt_Brick",
      "rotation": 2
    },
    {
      "x": -25,
      "y": 2,
      "z": 4,
      "name": "Rock_Basalt_Brick",
      "rotation": 2
    },
    {
      "x": -25,
      "y": 3,
      "z": 4,
      "name": "Rock_Basalt_Brick",
      "rotation": 2
    },
    {
      "x": -25,
      "y": 4,
      "z": 4,
      "name": "Rock_Basalt_Brick",
      "rotation": 2
    },
    {
      "x": -25,
      "y": 5,
      "z": 4,
      "name": "Rock_Basalt_Brick",
      "rotation": 2
    },
    {
      "x": -25,
      "y": 6,
      "z": 4,
      "name": "Rock_Basalt_Brick",
      "rotation": 2
    },
    {
      "x": -25,
      "y": 0,
      "z": 5,
      "name": "Rock_Basalt_Brick",
      "rotation": 2
    },
    {
      "x": -25,
      "y": 1,
      "z": 5,
      "name": "Rock_Basalt_Brick",
      "rotation": 2
    },
    {
      "x": -25,
      "y": 2,
      "z": 5,
      "name": "Rock_Basalt_Brick",
      "rotation": 2
    },
    {
      "x": -25,
      "y": 3,
      "z": 5,
      "name": "Rock_Basalt_Brick",
      "rotation": 2
    },
    {
      "x": -25,
      "y": 4,
      "z": 5,
      "name": "Rock_Basalt_Brick",
      "rotation": 2
    },
    {
      "x": -25,
      "y": 5,
      "z": 5,
      "name": "Rock_Basalt_Brick",
      "rotation": 2
    },
    {
      "x": -25,
      "y": 6,
      "z": 5,
      "name": "Rock_Basalt_Brick",
      "rotation": 2
    },
    {
      "x": -25,
      "y": 0,
      "z": 6,
      "name": "Rock_Basalt_Brick",
      "rotation": 2
    },
    {
      "x": -25,
      "y": 1,
      "z": 6,
      "name": "Rock_Basalt_Brick",
      "rotation": 2
    },
    {
      "x": -25,
      "y": 2,
      "z": 6,
      "name": "Rock_Basalt_Brick",
      "rotation": 2
    },
    {
      "x": -25,
      "y": 3,
      "z": 6,
      "name": "Rock_Basalt_Brick",
      "rotation": 2
    },
    {
      "x": -25,
      "y": 4,
      "z": 6,
      "name": "Rock_Basalt_Brick",
      "rotation": 2
    },
    {
      "x": -25,
      "y": 5,
      "z": 6,
      "name": "Rock_Basalt_Brick",
      "rotation": 2
    },
    {
      "x": -25,
      "y": 6,
      "z": 6,
      "name": "Rock_Basalt_Brick",
      "rotation": 2
    },
    {
      "x": -25,
      "y": 0,
      "z": 7,
      "name": "Rock_Basalt_Brick",
      "rotation": 2
    },
    {
      "x": -25,
      "y": 1,
      "z": 7,
      "name": "Rock_Basalt_Brick",
      "rotation": 2
    },
    {
      "x": -25,
      "y": 2,
      "z": 7,
      "name": "Rock_Basalt_Brick",
      "rotation": 2
    },
    {
      "x": -25,
      "y": 3,
      "z": 7,
      "name": "Rock_Basalt_Brick",
      "rotation": 2
    },
    {
      "x": -25,
      "y": 4,
      "z": 7,
      "name": "Rock_Basalt_Brick",
      "rotation": 2
    },
    {
      "x": -25,
      "y": 5,
      "z": 7,
      "name": "Rock_Basalt_Brick",
      "rotation": 2
    },
    {
      "x": -25,
      "y": 6,
      "z": 7,
      "name": "Rock_Basalt_Brick",
      "rotation": 2
    },
    {
      "x": -25,
      "y": 0,
      "z": 8,
      "name": "Rock_Basalt_Brick",
      "rotation": 2
    },
    {
      "x": -25,
      "y": 1,
      "z": 8,
      "name": "Rock_Basalt_Brick",
      "rotation": 2
    },
    {
      "x": -25,
      "y": 2,
      "z": 8,
      "name": "Rock_Basalt_Brick",
      "rotation": 2
    },
    {
      "x": -25,
      "y": 3,
      "z": 8,
      "name": "Rock_Basalt_Brick",
      "rotation": 2
    },
    {
      "x": -25,
      "y": 4,
      "z": 8,
      "name": "Rock_Basalt_Brick",
      "rotation": 2
    },
    {
      "x": -25,
      "y": 5,
      "z": 8,
      "name": "Rock_Basalt_Brick",
      "rotation": 2
    },
    {
      "x": -25,
      "y": 6,
      "z": 8,
      "name": "Rock_Basalt_Brick",
      "rotation": 2
    },
    {
      "x": -25,
      "y": 0,
      "z": 9,
      "name": "Rock_Basalt_Brick",
      "rotation": 2
    },
    {
      "x": -25,
      "y": 1,
      "z": 9,
      "name": "Rock_Basalt_Brick",
      "rotation": 2
    },
    {
      "x": -25,
      "y": 2,
      "z": 9,
      "name": "Rock_Basalt_Brick",
      "rotation": 2
    },
    {
      "x": -25,
      "y": 3,
      "z": 9,
      "name": "Rock_Basalt_Brick",
      "rotation": 2
    },
    {
      "x": -25,
      "y": 4,
      "z": 9,
      "name": "Rock_Basalt_Brick",
      "rotation": 2
    },
    {
      "x": -25,
      "y": 5,
      "z": 9,
      "name": "Rock_Basalt_Brick",
      "rotation": 2
    },
    {
      "x": -25,
      "y": 6,
      "z": 9,
      "name": "Rock_Basalt_Brick",
      "rotation": 2
    },
    {
      "x": -25,
      "y": 0,
      "z": 10,
      "name": "Rock_Basalt_Brick",
      "rotation": 2
    },
    {
      "x": -25,
      "y": 1,
      "z": 10,
      "name": "Rock_Basalt_Brick",
      "rotation": 2
    },
    {
      "x": -25,
      "y": 2,
      "z": 10,
      "name": "Rock_Basalt_Brick",
      "rotation": 2
    },
    {
      "x": -25,
      "y": 3,
      "z": 10,
      "name": "Rock_Basalt_Brick",
      "rotation": 2
    },
    {
      "x": -25,
      "y": 4,
      "z": 10,
      "name": "Rock_Basalt_Brick",
      "rotation": 2
    },
    {
      "x": -25,
      "y": 5,
      "z": 10,
      "name": "Rock_Basalt_Brick",
      "rotation": 2
    },
    {
      "x": -25,
      "y": 6,
      "z": 10,
      "name": "Rock_Basalt_Brick",
      "rotation": 2
    },
    {
      "x": -25,
      "y": 0,
      "z": 11,
      "name": "Rock_Basalt_Brick",
      "rotation": 2
    },
    {
      "x": -25,
      "y": 1,
      "z": 11,
      "name": "Rock_Basalt_Brick",
      "rotation": 2
    },
    {
      "x": -25,
      "y": 2,
      "z": 11,
      "name": "Rock_Basalt_Brick",
      "rotation": 2
    },
    {
      "x": -25,
      "y": 3,
      "z": 11,
      "name": "Rock_Basalt_Brick",
      "rotation": 2
    },
    {
      "x": -25,
      "y": 4,
      "z": 11,
      "name": "Rock_Basalt_Brick",
      "rotation": 2
    },
    {
      "x": -25,
      "y": 5,
      "z": 11,
      "name": "Rock_Basalt_Brick",
      "rotation": 2
    },
    {
      "x": -25,
      "y": 6,
      "z": 11,
      "name": "Rock_Basalt_Brick",
      "rotation": 2
    },
    {
      "x": -25,
      "y": 0,
      "z": 12,
      "name": "Rock_Basalt_Brick",
      "rotation": 2
    },
    {
      "x": -25,
      "y": 1,
      "z": 12,
      "name": "Rock_Basalt_Brick",
      "rotation": 2
    },
    {
      "x": -25,
      "y": 2,
      "z": 12,
      "name": "Rock_Basalt_Brick",
      "rotation": 2
    },
    {
      "x": -25,
      "y": 3,
      "z": 12,
      "name": "Rock_Basalt_Brick",
      "rotation": 2
    },
    {
      "x": -25,
      "y": 4,
      "z": 12,
      "name": "Rock_Basalt_Brick",
      "rotation": 2
    },
    {
      "x": -25,
      "y": 5,
      "z": 12,
      "name": "Rock_Basalt_Brick",
      "rotation": 2
    },
    {
      "x": -25,
      "y": 6,
      "z": 12,
      "name": "Rock_Basalt_Brick",
      "rotation": 2
    },
    {
      "x": -25,
      "y": 0,
      "z": 13,
      "name": "Rock_Basalt_Brick",
      "rotation": 2
    },
    {
      "x": -25,
      "y": 1,
      "z": 13,
      "name": "Rock_Basalt_Brick",
      "rotation": 2
    },
    {
      "x": -25,
      "y": 2,
      "z": 13,
      "name": "Rock_Basalt_Brick",
      "rotation": 2
    },
    {
      "x": -25,
      "y": 3,
      "z": 13,
      "name": "Rock_Basalt_Brick",
      "rotation": 2
    },
    {
      "x": -25,
      "y": 4,
      "z": 13,
      "name": "Rock_Basalt_Brick",
      "rotation": 2
    },
    {
      "x": -25,
      "y": 5,
      "z": 13,
      "name": "Rock_Basalt_Brick",
      "rotation": 2
    },
    {
      "x": -25,
      "y": 6,
      "z": 13,
      "name": "Rock_Basalt_Brick",
      "rotation": 2
    },
    {
      "x": -25,
      "y": 0,
      "z": 14,
      "name": "Rock_Basalt_Brick",
      "rotation": 2
    },
    {
      "x": -25,
      "y": 1,
      "z": 14,
      "name": "Rock_Basalt_Brick",
      "rotation": 2
    },
    {
      "x": -25,
      "y": 2,
      "z": 14,
      "name": "Rock_Basalt_Brick",
      "rotation": 2
    },
    {
      "x": -25,
      "y": 3,
      "z": 14,
      "name": "Rock_Basalt_Brick",
      "rotation": 2
    },
    {
      "x": -25,
      "y": 4,
      "z": 14,
      "name": "Rock_Basalt_Brick",
      "rotation": 2
    },
    {
      "x": -25,
      "y": 5,
      "z": 14,
      "name": "Rock_Basalt_Brick",
      "rotation": 2
    },
    {
      "x": -25,
      "y": 6,
      "z": 14,
      "name": "Rock_Basalt_Brick",
      "rotation": 2
    },
    {
      "x": -25,
      "y": 0,
      "z": 15,
      "name": "Rock_Basalt_Brick",
      "rotation": 2
    },
    {
      "x": -25,
      "y": 1,
      "z": 15,
      "name": "Rock_Basalt_Brick",
      "rotation": 2
    },
    {
      "x": -25,
      "y": 2,
      "z": 15,
      "name": "Rock_Basalt_Brick",
      "rotation": 2
    },
    {
      "x": -25,
      "y": 3,
      "z": 15,
      "name": "Rock_Basalt_Brick",
      "rotation": 2
    },
    {
      "x": -25,
      "y": 4,
      "z": 15,
      "name": "Rock_Basalt_Brick",
      "rotation": 2
    },
    {
      "x": -25,
      "y": 5,
      "z": 15,
      "name": "Rock_Basalt_Brick",
      "rotation": 2
    },
    {
      "x": -25,
      "y": 6,
      "z": 15,
      "name": "Rock_Basalt_Brick",
      "rotation": 2
    },
    {
      "x": -25,
      "y": 0,
      "z": 16,
      "name": "Rock_Basalt_Brick",
      "rotation": 2
    },
    {
      "x": -25,
      "y": 1,
      "z": 16,
      "name": "Rock_Basalt_Brick",
      "rotation": 2
    },
    {
      "x": -25,
      "y": 2,
      "z": 16,
      "name": "Rock_Basalt_Brick",
      "rotation": 2
    },
    {
      "x": -25,
      "y": 3,
      "z": 16,
      "name": "Rock_Basalt_Brick",
      "rotation": 2
    },
    {
      "x": -25,
      "y": 4,
      "z": 16,
      "name": "Rock_Basalt_Brick",
      "rotation": 2
    },
    {
      "x": -25,
      "y": 5,
      "z": 16,
      "name": "Rock_Basalt_Brick",
      "rotation": 2
    },
    {
      "x": -25,
      "y": 6,
      "z": 16,
      "name": "Rock_Basalt_Brick",
      "rotation": 2
    },
    {
      "x": -25,
      "y": 0,
      "z": 17,
      "name": "Rock_Basalt_Brick",
      "rotation": 2
    },
    {
      "x": -25,
      "y": 1,
      "z": 17,
      "name": "Rock_Basalt_Brick",
      "rotation": 2
    },
    {
      "x": -25,
      "y": 2,
      "z": 17,
      "name": "Rock_Basalt_Brick",
      "rotation": 2
    },
    {
      "x": -25,
      "y": 3,
      "z": 17,
      "name": "Rock_Basalt_Brick",
      "rotation": 2
    },
    {
      "x": -25,
      "y": 4,
      "z": 17,
      "name": "Rock_Basalt_Brick",
      "rotation": 2
    },
    {
      "x": -25,
      "y": 5,
      "z": 17,
      "name": "Rock_Basalt_Brick",
      "rotation": 2
    },
    {
      "x": -25,
      "y": 6,
      "z": 17,
      "name": "Rock_Basalt_Brick",
      "rotation": 2
    },
    {
      "x": -25,
      "y": 0,
      "z": 18,
      "name": "Rock_Basalt_Brick",
      "rotation": 2
    },
    {
      "x": -25,
      "y": 1,
      "z": 18,
      "name": "Rock_Basalt_Brick",
      "rotation": 2
    },
    {
      "x": -25,
      "y": 2,
      "z": 18,
      "name": "Rock_Basalt_Brick",
      "rotation": 2
    },
    {
      "x": -25,
      "y": 3,
      "z": 18,
      "name": "Rock_Basalt_Brick",
      "rotation": 2
    },
    {
      "x": -25,
      "y": 4,
      "z": 18,
      "name": "Rock_Basalt_Brick",
      "rotation": 2
    },
    {
      "x": -25,
      "y": 5,
      "z": 18,
      "name": "Rock_Basalt_Brick",
      "rotation": 2
    },
    {
      "x": -25,
      "y": 6,
      "z": 18,
      "name": "Rock_Basalt_Brick",
      "rotation": 2
    },
    {
      "x": -25,
      "y": 0,
      "z": 19,
      "name": "Rock_Basalt_Brick",
      "rotation": 2
    },
    {
      "x": -25,
      "y": 1,
      "z": 19,
      "name": "Rock_Basalt_Brick",
      "rotation": 2
    },
    {
      "x": -25,
      "y": 2,
      "z": 19,
      "name": "Rock_Basalt_Brick",
      "rotation": 2
    },
    {
      "x": -25,
      "y": 3,
      "z": 19,
      "name": "Rock_Basalt_Brick",
      "rotation": 2
    },
    {
      "x": -25,
      "y": 4,
      "z": 19,
      "name": "Rock_Basalt_Brick",
      "rotation": 2
    },
    {
      "x": -25,
      "y": 5,
      "z": 19,
      "name": "Rock_Basalt_Brick",
      "rotation": 2
    },
    {
      "x": -25,
      "y": 6,
      "z": 19,
      "name": "Rock_Basalt_Brick",
      "rotation": 2
    },
    {
      "x": -25,
      "y": 0,
      "z": 20,
      "name": "Rock_Basalt_Brick",
      "rotation": 2
    },
    {
      "x": -25,
      "y": 1,
      "z": 20,
      "name": "Rock_Basalt_Brick",
      "rotation": 2
    },
    {
      "x": -25,
      "y": 2,
      "z": 20,
      "name": "Rock_Basalt_Brick",
      "rotation": 2
    },
    {
      "x": -25,
      "y": 3,
      "z": 20,
      "name": "Rock_Basalt_Brick",
      "rotation": 2
    },
    {
      "x": -25,
      "y": 4,
      "z": 20,
      "name": "Rock_Basalt_Brick",
      "rotation": 2
    },
    {
      "x": -25,
      "y": 5,
      "z": 20,
      "name": "Rock_Basalt_Brick",
      "rotation": 2
    },
    {
      "x": -25,
      "y": 6,
      "z": 20,
      "name": "Rock_Basalt_Brick",
      "rotation": 2
    },
    {
      "x": -25,
      "y": 0,
      "z": 21,
      "name": "Rock_Basalt_Brick",
      "rotation": 2
    },
    {
      "x": -25,
      "y": 1,
      "z": 21,
      "name": "Rock_Basalt_Brick",
      "rotation": 2
    },
    {
      "x": -25,
      "y": 2,
      "z": 21,
      "name": "Rock_Basalt_Brick",
      "rotation": 2
    },
    {
      "x": -25,
      "y": 3,
      "z": 21,
      "name": "Rock_Basalt_Brick",
      "rotation": 2
    },
    {
      "x": -25,
      "y": 4,
      "z": 21,
      "name": "Rock_Basalt_Brick",
      "rotation": 2
    },
    {
      "x": -25,
      "y": 5,
      "z": 21,
      "name": "Rock_Basalt_Brick",
      "rotation": 2
    },
    {
      "x": -25,
      "y": 6,
      "z": 21,
      "name": "Rock_Basalt_Brick",
      "rotation": 2
    },
    {
      "x": -25,
      "y": 0,
      "z": 22,
      "name": "Rock_Basalt_Brick",
      "rotation": 2
    },
    {
      "x": -25,
      "y": 1,
      "z": 22,
      "name": "Rock_Basalt_Brick",
      "rotation": 2
    },
    {
      "x": -25,
      "y": 2,
      "z": 22,
      "name": "Rock_Basalt_Brick",
      "rotation": 2
    },
    {
      "x": -25,
      "y": 3,
      "z": 22,
      "name": "Rock_Basalt_Brick",
      "rotation": 2
    },
    {
      "x": -25,
      "y": 4,
      "z": 22,
      "name": "Rock_Basalt_Brick",
      "rotation": 2
    },
    {
      "x": -25,
      "y": 5,
      "z": 22,
      "name": "Rock_Basalt_Brick",
      "rotation": 2
    },
    {
      "x": -25,
      "y": 6,
      "z": 22,
      "name": "Rock_Basalt_Brick",
      "rotation": 2
    },
    {
      "x": -25,
      "y": 0,
      "z": 23,
      "name": "Rock_Basalt_Brick",
      "rotation": 2
    },
    {
      "x": -25,
      "y": 1,
      "z": 23,
      "name": "Rock_Basalt_Brick",
      "rotation": 2
    },
    {
      "x": -25,
      "y": 2,
      "z": 23,
      "name": "Rock_Basalt_Brick",
      "rotation": 2
    },
    {
      "x": -25,
      "y": 3,
      "z": 23,
      "name": "Rock_Basalt_Brick",
      "rotation": 2
    },
    {
      "x": -25,
      "y": 4,
      "z": 23,
      "name": "Rock_Basalt_Brick",
      "rotation": 2
    },
    {
      "x": -25,
      "y": 5,
      "z": 23,
      "name": "Rock_Basalt_Brick",
      "rotation": 2
    },
    {
      "x": -25,
      "y": 6,
      "z": 23,
      "name": "Rock_Basalt_Brick",
      "rotation": 2
    },
    {
      "x": -25,
      "y": 0,
      "z": 24,
      "name": "Rock_Basalt_Brick",
      "rotation": 2
    },
    {
      "x": -25,
      "y": 1,
      "z": 24,
      "name": "Rock_Basalt_Brick",
      "rotation": 2
    },
    {
      "x": -25,
      "y": 2,
      "z": 24,
      "name": "Rock_Basalt_Brick",
      "rotation": 2
    },
    {
      "x": -25,
      "y": 3,
      "z": 24,
      "name": "Rock_Basalt_Brick",
      "rotation": 2
    },
    {
      "x": -25,
      "y": 4,
      "z": 24,
      "name": "Rock_Basalt_Brick",
      "rotation": 2
    },
    {
      "x": -25,
      "y": 5,
      "z": 24,
      "name": "Rock_Basalt_Brick",
      "rotation": 2
    },
    {
      "x": -25,
      "y": 6,
      "z": 24,
      "name": "Rock_Basalt_Brick",
      "rotation": 2
    },
    {
      "x": -25,
      "y": 0,
      "z": 25,
      "name": "Rock_Basalt_Brick",
      "rotation": 2
    },
    {
      "x": -25,
      "y": 1,
      "z": 25,
      "name": "Rock_Basalt_Brick",
      "rotation": 2
    },
    {
      "x": -25,
      "y": 2,
      "z": 25,
      "name": "Rock_Basalt_Brick",
      "rotation": 2
    },
    {
      "x": -25,
      "y": 3,
      "z": 25,
      "name": "Rock_Basalt_Brick",
      "rotation": 2
    },
    {
      "x": -25,
      "y": 4,
      "z": 25,
      "name": "Rock_Basalt_Brick",
      "rotation": 2
    },
    {
      "x": -25,
      "y": 5,
      "z": 25,
      "name": "Rock_Basalt_Brick",
      "rotation": 2
    },
    {
      "x": -25,
      "y": 6,
      "z": 25,
      "name": "Rock_Basalt_Brick",
      "rotation": 2
    },
    {
      "x": -25,
      "y": 0,
      "z": 26,
      "name": "Rock_Basalt_Brick",
      "rotation": 2
    },
    {
      "x": -25,
      "y": 1,
      "z": 26,
      "name": "Rock_Basalt_Brick",
      "rotation": 2
    },
    {
      "x": -25,
      "y": 2,
      "z": 26,
      "name": "Rock_Basalt_Brick",
      "rotation": 2
    },
    {
      "x": -25,
      "y": 3,
      "z": 26,
      "name": "Rock_Basalt_Brick",
      "rotation": 2
    },
    {
      "x": -25,
      "y": 4,
      "z": 26,
      "name": "Rock_Basalt_Brick",
      "rotation": 2
    },
    {
      "x": -25,
      "y": 5,
      "z": 26,
      "name": "Rock_Basalt_Brick_Roof"
    },
    {
      "x": -25,
      "y": 6,
      "z": 26,
      "name": "Rock_Basalt_Brick",
      "rotation": 2
    },
    {
      "x": -25,
      "y": 0,
      "z": 27,
      "name": "Rock_Basalt_Brick_Smooth"
    },
    {
      "x": -25,
      "y": 1,
      "z": 27,
      "name": "Rock_Basalt_Brick_Smooth"
    },
    {
      "x": -25,
      "y": 2,
      "z": 27,
      "name": "Rock_Basalt_Brick_Smooth"
    },
    {
      "x": -25,
      "y": 3,
      "z": 27,
      "name": "Rock_Basalt_Brick_Smooth"
    },
    {
      "x": -25,
      "y": 4,
      "z": 27,
      "name": "Rock_Basalt_Brick_Decorative"
    },
    {
      "x": -25,
      "y": 5,
      "z": 27,
      "name": "Rock_Basalt_Brick_Smooth"
    },
    {
      "x": -25,
      "y": 6,
      "z": 27,
      "name": "Rock_Basalt_Brick_Smooth"
    },
    {
      "x": -24,
      "y": 0,
      "z": -27,
      "name": "Rock_Basalt_Brick_Smooth"
    },
    {
      "x": -24,
      "y": 1,
      "z": -27,
      "name": "Rock_Basalt_Brick_Smooth"
    },
    {
      "x": -24,
      "y": 2,
      "z": -27,
      "name": "Rock_Basalt_Brick_Smooth"
    },
    {
      "x": -24,
      "y": 3,
      "z": -27,
      "name": "Rock_Basalt_Brick_Smooth"
    },
    {
      "x": -24,
      "y": 4,
      "z": -27,
      "name": "Rock_Basalt_Brick_Ornate"
    },
    {
      "x": -24,
      "y": 5,
      "z": -27,
      "name": "Rock_Basalt_Brick_Smooth"
    },
    {
      "x": -24,
      "y": 6,
      "z": -27,
      "name": "Rock_Basalt_Brick_Smooth"
    },
    {
      "x": -24,
      "y": 0,
      "z": -26,
      "name": "Rock_Basalt_Brick",
      "rotation": 2
    },
    {
      "x": -24,
      "y": 1,
      "z": -26,
      "name": "Rock_Basalt_Brick",
      "rotation": 2
    },
    {
      "x": -24,
      "y": 2,
      "z": -26,
      "name": "Rock_Basalt_Brick",
      "rotation": 2
    },
    {
      "x": -24,
      "y": 3,
      "z": -26,
      "name": "Rock_Basalt_Brick",
      "rotation": 2
    },
    {
      "x": -24,
      "y": 4,
      "z": -26,
      "name": "Rock_Basalt_Brick",
      "rotation": 2
    },
    {
      "x": -24,
      "y": 5,
      "z": -26,
      "name": "Rock_Basalt_Brick",
      "rotation": 2
    },
    {
      "x": -24,
      "y": 6,
      "z": -26,
      "name": "Rock_Basalt_Brick",
      "rotation": 2
    },
    {
      "x": -24,
      "y": 0,
      "z": -25,
      "name": "Rock_Basalt_Brick",
      "rotation": 2
    },
    {
      "x": -24,
      "y": 1,
      "z": -25,
      "name": "Rock_Basalt_Brick",
      "rotation": 2
    },
    {
      "x": -24,
      "y": 2,
      "z": -25,
      "name": "Rock_Basalt_Brick",
      "rotation": 2
    },
    {
      "x": -24,
      "y": 3,
      "z": -25,
      "name": "Rock_Basalt_Brick",
      "rotation": 2
    },
    {
      "x": -24,
      "y": 4,
      "z": -25,
      "name": "Rock_Basalt_Brick",
      "rotation": 2
    },
    {
      "x": -24,
      "y": 5,
      "z": -25,
      "name": "Rock_Basalt_Brick",
      "rotation": 2
    },
    {
      "x": -24,
      "y": 6,
      "z": -25,
      "name": "Rock_Basalt_Brick",
      "rotation": 2
    },
    {
      "x": -24,
      "y": 0,
      "z": -24,
      "name": "Wood_Deadwood_Planks",
      "rotation": 2
    },
    {
      "x": -24,
      "y": 1,
      "z": -24,
      "name": "Wood_Deadwood_Planks",
      "rotation": 2
    },
    {
      "x": -24,
      "y": 2,
      "z": -24,
      "name": "Wood_Deadwood_Planks",
      "rotation": 2
    },
    {
      "x": -24,
      "y": 3,
      "z": -24,
      "name": "Wood_Deadwood_Planks",
      "rotation": 2
    },
    {
      "x": -24,
      "y": 4,
      "z": -24,
      "name": "Wood_Deadwood_Planks",
      "rotation": 2
    },
    {
      "x": -24,
      "y": 5,
      "z": -24,
      "name": "Wood_Deadwood_Planks",
      "rotation": 2
    },
    {
      "x": -24,
      "y": 6,
      "z": -24,
      "name": "Wood_Deadwood_Planks",
      "rotation": 2
    },
    {
      "x": -24,
      "y": 0,
      "z": -23,
      "name": "Wood_Deadwood_Planks",
      "rotation": 2
    },
    {
      "x": -24,
      "y": 1,
      "z": -23,
      "name": "Wood_Deadwood_Planks",
      "rotation": 2
    },
    {
      "x": -24,
      "y": 2,
      "z": -23,
      "name": "Wood_Deadwood_Planks",
      "rotation": 2
    },
    {
      "x": -24,
      "y": 3,
      "z": -23,
      "name": "Wood_Deadwood_Planks",
      "rotation": 2
    },
    {
      "x": -24,
      "y": 4,
      "z": -23,
      "name": "Wood_Deadwood_Planks",
      "rotation": 2
    },
    {
      "x": -24,
      "y": 5,
      "z": -23,
      "name": "Wood_Deadwood_Planks",
      "rotation": 2
    },
    {
      "x": -24,
      "y": 6,
      "z": -23,
      "name": "Wood_Deadwood_Planks",
      "rotation": 2
    },
    {
      "x": -24,
      "y": 0,
      "z": -22,
      "name": "Wood_Deadwood_Planks"
    },
    {
      "x": -24,
      "y": 1,
      "z": -22,
      "name": "Wood_Deadwood_Planks"
    },
    {
      "x": -24,
      "y": 2,
      "z": -22,
      "name": "Wood_Deadwood_Planks"
    },
    {
      "x": -24,
      "y": 3,
      "z": -22,
      "name": "Wood_Deadwood_Planks"
    },
    {
      "x": -24,
      "y": 4,
      "z": -22,
      "name": "Wood_Deadwood_Planks"
    },
    {
      "x": -24,
      "y": 5,
      "z": -22,
      "name": "Wood_Deadwood_Planks"
    },
    {
      "x": -24,
      "y": 6,
      "z": -22,
      "name": "Wood_Deadwood_Planks"
    },
    {
      "x": -24,
      "y": 0,
      "z": -21,
      "name": "Wood_Deadwood_Planks"
    },
    {
      "x": -24,
      "y": 1,
      "z": -21,
      "name": "Wood_Deadwood_Planks"
    },
    {
      "x": -24,
      "y": 2,
      "z": -21,
      "name": "Wood_Deadwood_Planks"
    },
    {
      "x": -24,
      "y": 3,
      "z": -21,
      "name": "Wood_Deadwood_Planks"
    },
    {
      "x": -24,
      "y": 4,
      "z": -21,
      "name": "Wood_Deadwood_Planks"
    },
    {
      "x": -24,
      "y": 5,
      "z": -21,
      "name": "Wood_Deadwood_Planks"
    },
    {
      "x": -24,
      "y": 6,
      "z": -21,
      "name": "Wood_Deadwood_Planks"
    },
    {
      "x": -24,
      "y": 0,
      "z": -20,
      "name": "Wood_Deadwood_Planks"
    },
    {
      "x": -24,
      "y": 1,
      "z": -20,
      "name": "Wood_Deadwood_Planks"
    },
    {
      "x": -24,
      "y": 2,
      "z": -20,
      "name": "Wood_Deadwood_Planks"
    },
    {
      "x": -24,
      "y": 3,
      "z": -20,
      "name": "Wood_Deadwood_Planks"
    },
    {
      "x": -24,
      "y": 4,
      "z": -20,
      "name": "Wood_Deadwood_Planks"
    },
    {
      "x": -24,
      "y": 5,
      "z": -20,
      "name": "Wood_Deadwood_Planks"
    },
    {
      "x": -24,
      "y": 6,
      "z": -20,
      "name": "Wood_Deadwood_Planks"
    },
    {
      "x": -24,
      "y": 0,
      "z": -19,
      "name": "Wood_Deadwood_Planks"
    },
    {
      "x": -24,
      "y": 1,
      "z": -19,
      "name": "Wood_Deadwood_Planks"
    },
    {
      "x": -24,
      "y": 2,
      "z": -19,
      "name": "Wood_Deadwood_Planks"
    },
    {
      "x": -24,
      "y": 3,
      "z": -19,
      "name": "Wood_Deadwood_Planks"
    },
    {
      "x": -24,
      "y": 4,
      "z": -19,
      "name": "Wood_Deadwood_Planks"
    },
    {
      "x": -24,
      "y": 5,
      "z": -19,
